Workbook

Sheet COMPARISON
B2: OASIS AT SAN MARCO
B3: CBRE UNDERWRITING AND HISTORICAL OVERVIEW - COMPARISON
D5: OCTOBER | G5: NOVEMBER | J5: VARIANCE
D6: Amount | E6: Per Unit | G6: Amount | H6: Per Unit | J6: Amount | K6: Per Unit | N6: Underwriting Notes
B7: Economic Occupancy (Vacancy Loss only) | D7: 0.94775996 | G7: =+PROFORMA!S7 -> 0.95 | J7: =+G7-D7 -> 0.0022400421
B8: Physical Occupancy | D8: 0.95275591 | G8: =+PROFORMA!S8 -> 0.96062992 | J8: =+G8-D8 -> 0.0078740157 | M8: Growth Factor
B10: REVENUE
A11: 1 | B11: Gross Potential Rent (net of LTL) | D11: 1666308 | E11: =+D11/$D$77 -> 13120.535 | G11: =+PROFORMA!S11 -> 1655436 | H11: =+G11/$D$77 -> 13034.929 | J11: =+G11-D11 -> -10872 | K11: =+J11/$D$77 -> -85.606299 | N11: OCT = 11/4/25 RR, NOV = 12/16/25 RR
A12: 2 | B12: Vacancy Loss | D12: -87048 | E12: =+D12/$D$77 -> -685.41732 | G12: =+PROFORMA!S12 -> -82771.8 | H12: =+G12/$D$77 -> -651.74646 | J12: =+G12-D12 -> 4276.2 | K12: =+J12/$D$77 -> 33.670866 | N12: OCT = 11/4/25 RR, NOV = 5%
A13: 3 | B13: Concessions | D13: 0 | E13: =+D13/$D$77 -> 0 | G13: =+PROFORMA!S13 -> 0 | H13: =+G13/$D$77 -> 0 | J13: =+G13-D13 -> 0 | K13: =+J13/$D$77 -> 0 | N13: 0
A14: 4 | B14: Delinquency/Bad Debt | D14: -49989.24 | E14: =+D14/$D$77 -> -393.61606 | G14: =+PROFORMA!S14 -> -49663.08 | H14: =+G14/$D$77 -> -391.04787 | J14: =+G14-D14 -> 326.16 | K14: =+J14/$D$77 -> 2.568189 | N14: 0.03
A15: 5 | B15: Model/Down Units | D15: 0 | E15: =+D15/$D$77 -> 0 | G15: =+PROFORMA!S15 -> 0 | H15: =+G15/$D$77 -> 0 | J15: =+G15-D15 -> 0 | K15: =+J15/$D$77 -> 0 | N15: T12
B16: Total Rental Income | D16: 1529260 | E16: =+D16/$D$77 -> 12041.417 | G16: =+PROFORMA!S16 -> 1523001.1 | H16: =+G16/$D$77 -> 11992.135 | J16: =+G16-D16 -> -6258.88 | K16: =+J16/$D$77 -> -49.28252
A17: 6 | B17: Utility Reimbursements | D17: 85773.847 | E17: =+D17/$D$77 -> 675.38463 | G17: =+PROFORMA!S17 -> 87122.56 | H17: =+G17/$D$77 -> 686.00441 | J17: =+G17-D17 -> 1348.7129 | K17: =+J17/$D$77 -> 10.619787 | M17: 0.03 | N17: T12
A18: 7 | B18: Miscellaneous Income | D18: 133870.98 | E18: =+D18/$D$77 -> 1054.1022 | G18: =+PROFORMA!S18 -> 124901.74 | H18: =+G18/$D$77 -> 983.47831 | J18: =+G18-D18 -> -8969.24 | K18: =+J18/$D$77 -> -70.623937 | M18: 0.03 | N18: T12
B19: Effective Gross Income | D19: 1748904.8 | E19: =+D19/$D$77 -> 13770.904 | G19: =+PROFORMA!S19 -> 1735025.4 | H19: =+G19/$D$77 -> 13661.618 | J19: =+G19-D19 -> -13879.407 | K19: =+J19/$D$77 -> -109.28667
B21: EXPENSES
A22: 8 | B22: Payroll | D22: 88011.461 | E22: =+D22/$D$77 -> 693.00363 | G22: =+PROFORMA!S22 -> 103654.23 | H22: =+G22/$D$77 -> 816.175 | J22: =+G22-D22 -> 15642.765 | K22: =+J22/$D$77 -> 123.17137 | M22: 0.03 | N22: T12
A23: 9 | B23: General & Administrative | D23: 61873.872 | E23: =+D23/$D$77 -> 487.19584 | G23: =+PROFORMA!S23 -> 59070.706 | H23: =+G23/$D$77 -> 465.12367 | J23: =+G23-D23 -> -2803.1656 | K23: =+J23/$D$77 -> -22.07217 | M23: 0.03 | N23: T12
A24: 10 | B24: Advertising | D24: 29015.285 | E24: =+D24/$D$77 -> 228.46681 | G24: =+PROFORMA!S24 -> 32334.502 | H24: =+G24/$D$77 -> 254.60237 | J24: =+G24-D24 -> 3319.2162 | K24: =+J24/$D$77 -> 26.135561 | M24: 0.03 | N24: T12
A25: 11 | B25: Repairs & Maintenance | D25: 66435.082 | E25: =+D25/$D$77 -> 523.11089 | G25: =+PROFORMA!S25 -> 64927.42 | H25: =+G25/$D$77 -> 511.23953 | J25: =+G25-D25 -> -1507.6625 | K25: =+J25/$D$77 -> -11.871358 | M25: 0.03 | N25: T12
A26: 12 | B26: Contract Services | D26: 68126.373 | E26: =+D26/$D$77 -> 536.42814 | G26: =+PROFORMA!S26 -> 66526.639 | H26: =+G26/$D$77 -> 523.8318 | J26: =+G26-D26 -> -1599.7342 | K26: =+J26/$D$77 -> -12.596332 | M26: 0.03 | N26: T12
A27: 13 | B27: Turnover/Cleaning | D27: 51694.691 | E27: =+D27/$D$77 -> 407.04481 | G27: =+PROFORMA!S27 -> 47022.981 | H27: =+G27/$D$77 -> 370.2597 | J27: =+G27-D27 -> -4671.7092 | K27: =+J27/$D$77 -> -36.785112 | M27: 0.03 | N27: T12
A28: 14 | B28: Utilities | D28: 78048.487 | E28: =+D28/$D$77 -> 614.55501 | G28: =+PROFORMA!S28 -> 77975.563 | H28: =+G28/$D$77 -> 613.98081 | J28: =+G28-D28 -> -72.924 | K28: =+J28/$D$77 -> -0.57420472 | M28: 0.03 | N28: T12
A29: 15 | B29: Property Taxes | D29: 163732.42 | E29: =+D29/$D$77 -> 1289.2316 | G29: =+PROFORMA!S29 -> 163732.42 | H29: =+G29/$D$77 -> 1289.2316 | J29: =+G29-D29 -> 0 | K29: =+J29/$D$77 -> 0 | M29: 0.03 | N29: 2025 Bill
A30: 16 | B30: Property Insurance | D30: 160000 | E30: =+D30/$D$77 -> 1259.8425 | G30: =+PROFORMA!S30 -> 160000 | H30: =+G30/$D$77 -> 1259.8425 | J30: =+G30-D30 -> 0 | K30: =+J30/$D$77 -> 0 | N30: Insurance Renewal
A31: 17 | B31: Management Fee | D31: 61211.669 | E31: =+D31/$D$77 -> 481.98165 | G31: =+PROFORMA!S31 -> 60725.89 | H31: =+G31/$D$77 -> 478.15661 | J31: =+G31-D31 -> -485.77925 | K31: =+J31/$D$77 -> -3.8250335 | N31: 0.035
B32: Reserves | D32: 38100 | E32: =+D32/$D$77 -> 300 | G32: =+PROFORMA!S32 -> 38100 | H32: =+G32/$D$77 -> 300 | J32: =+G32-D32 -> 0 | K32: =+J32/$D$77 -> 0 | N32: 300
B33: Total Operating Expenses | D33: 866249.34 | E33: =+D33/$D$77 -> 6820.8609 | G33: =+PROFORMA!S33 -> 874070.34 | H33: =+G33/$D$77 -> 6882.4436 | J33: =+G33-D33 -> 7821.006 | K33: =+J33/$D$77 -> 61.582724
B34: Expense Ratio | D34: 0.49530959 | G34: =+PROFORMA!S34 -> 0.50377956 | J34: =+G34-D34 -> 0.0084699678
B36: NET OPERATING INCOME | D36: 882655.5 | E36: =+D36/$D$77 -> 6950.0433 | G36: =+PROFORMA!S36 -> 860955.08 | H36: =+G36/$D$77 -> 6779.1739 | J36: =+G36-D36 -> -21700.413 | K36: =+J36/$D$77 -> -170.86939
B38: Footnotes: | P38: PROPERTY TAX CALC | W38: 2026 | AA38: 2025 | AE38: 2024 | AI38: 2023 | AM38: 2022
R39: Re-Assessed Value | U39: Taxable Values
P40: Market Value | R40: 11000000 | U40: Non-School | W40: =+(1+AVERAGE(AA44:AE44))*AA40 -> 9442061 | AA40: 9143000 | AE40: 8958200 | AI40: 8574168 | AM40: 7794699
P41: Taxable Value | Q41: 0.8 | R41: =+Q41*R40 -> 8800000 | U41: School | W41: =+(1+$AA45)*AA41 -> 9331612.3 | AA41: 9143000 | AE41: 8958200 | AI41: 9103200 | AM41: 8947800
P42: Millage Rate | Q42: =+$X$59 -> 17.7412 | R42: =+(Q42/1000)*R41 -> 156122.56
B43: LOAN METRICS | P43: Non-Ad Valorem | R43: =+Y64 -> 3379.2 | U43: YoY Increases
E44: Per Unit | H44: Per Unit | K44: Per Unit | P44: Taxes | R44: =+SUM(R42:R43) -> 159501.76 | U44: Non-School | W44: =+W40/AA40-1 -> 0.032709281 | AA44: =+AA40/AE40-1 -> 0.020629144 | AE44: =+AE40/AI40-1 -> 0.044789419 | AI44: =+AI40/AM40-1 -> 0.099999885
B45: Value at | C45: 0.0575 | D45: =+ROUND(D36/$C45,-4) -> 15350000 | E45: =+ROUND(D45/$G$77,-3) -> 121000 | G45: =+ROUND(G36/$C45,-4) -> 14970000 | H45: =+ROUND(G45/$G$77,-3) -> 118000 | J45: =+G45-D45 -> -380000 | K45: =+ROUND(J45/$G$77,-3) -> -3000 | P45: Prepay | Q45: -0.04 | R45: =+Q45*R44 -> -6380.0704 | U45: School | W45: =+W41/AA41-1 -> 0.020629144 | AA45: =+AA41/AE41-1 -> 0.020629144 | AE45: =+AE41/AI41-1 -> -0.015928465 | AI45: =+AI41/AM41-1 -> 0.017367398
B46: Loan Size | D46: 10500000 | E46: =+ROUND(D46/$G$77,-3) -> 83000 | G46: 10500000 | H46: =+ROUND(G46/$G$77,-3) -> 83000 | J46: =+G46-D46 -> 0 | K46: =+ROUND(J46/$G$77,-3) -> 0 | P46: Taxes net of Prepay | R46: =+SUM(R44:R45) -> 153121.69
...

Sheet PROFORMA
B2: OASIS AT SAN MARCO
B3: CBRE UNDERWRITING AND HISTORICAL OVERVIEW
D5: 2022 | G5: 2023 | J5: 2024 | M5: T12 | N5: T6 | O5: T3 | P5: T2 | Q5: T1 | S5: PROFORMA
D6: Amount | E6: Per Unit | G6: Amount | H6: Per Unit | J6: Amount | K6: Per Unit | S6: Amount | T6: Per Unit | W6: Underwriting Notes
B7: Economic Occupancy (Vacancy Loss only) | D7: =IFERROR(1-(-D12/D11),"NA") -> NA | G7: =IFERROR(1-(-G12/G11),"NA") -> NA | J7: =IFERROR(1-(-J12/J11),"NA") -> NA | M7: =IFERROR(1-(-M12/M11),"NA") -> 0.82460883 | N7: =IFERROR(1-(-N12/N11),"NA") -> 0.83204828 | O7: =IFERROR(1-(-O12/O11),"NA") -> 0.91508542 | P7: =IFERROR(1-(-P12/P11),"NA") -> 0.94388776 | Q7: =IFERROR(1-(-Q12/Q11),"NA") -> 0.93297484 | S7: =IFERROR(1-(-S12/S11),"NA") -> 0.95
B8: Physical Occupancy | S8: =+'RR 12-16-25'!$H$150 -> 0.96062992 | V8: Growth Factor
B10: REVENUE
A11: 1 | B11: Gross Potential Rent (net of LTL) | D11: =+SUMIFS('IS 2022'!$V:$V,'IS 2022'!$A:$A,$A11) -> 0 | E11: =+D11/'RR 11-4-25'!$G$152 -> 0 | G11: =+SUMIFS('IS 2023'!$V:$V,'IS 2023'!$A:$A,$A11) -> 0 | H11: =+G11/'RR 11-4-25'!$G$152 -> 0 | J11: =+SUMIFS('IS 2024'!$V:$V,'IS 2024'!$A:$A,$A11) -> 0 | K11: =+J11/'RR 11-4-25'!$G$152 -> 0 | M11: =+SUMIFS('TTM Nov-25'!U:U,'TTM Nov-25'!$A:$A,$A11) -> 1617029 | N11: =+SUMIFS('TTM Nov-25'!T:T,'TTM Nov-25'!$A:$A,$A11) -> 1584657.8 | O11: =+SUMIFS('TTM Nov-25'!S:S,'TTM Nov-25'!$A:$A,$A11) -> 1481992.8 | P11: =+SUMIFS('TTM Nov-25'!R:R,'TTM Nov-25'!$A:$A,$A11) -> 1502837.9 | Q11: =+SUMIFS('TTM Nov-25'!Q:Q,'TTM Nov-25'!$A:$A,$A11) -> 1560859.3 | S11: =+'RR 12-16-25'!$K$152*12 -> 1655436 | T11: =+S11/'RR 11-4-25'!$G$152 -> 13034.929 | W11: Rent Roll as of 11/4/2025
A12: 2 | B12: Vacancy Loss | D12: =+SUMIFS('IS 2022'!$V:$V,'IS 2022'!$A:$A,$A12) -> 0 | E12: =+D12/'RR 11-4-25'!$G$152 -> 0 | G12: =+SUMIFS('IS 2023'!$V:$V,'IS 2023'!$A:$A,$A12) -> 0 | H12: =+G12/'RR 11-4-25'!$G$152 -> 0 | J12: =+SUMIFS('IS 2024'!$V:$V,'IS 2024'!$A:$A,$A12) -> 0 | K12: =+J12/'RR 11-4-25'!$G$152 -> 0 | M12: =+SUMIFS('TTM Nov-25'!U:U,'TTM Nov-25'!$A:$A,$A12) -> -283612.62 | N12: =+SUMIFS('TTM Nov-25'!T:T,'TTM Nov-25'!$A:$A,$A12) -> -266146 | O12: =+SUMIFS('TTM Nov-25'!S:S,'TTM Nov-25'!$A:$A,$A12) -> -125842.8 | P12: =+SUMIFS('TTM Nov-25'!R:R,'TTM Nov-25'!$A:$A,$A12) -> -84327.6 | Q12: =+SUMIFS('TTM Nov-25'!Q:Q,'TTM Nov-25'!$A:$A,$A12) -> -104616.84 | S12: =+-W12*S11 -> -82771.8 | T12: =+S12/'RR 11-4-25'!$G$152 -> -651.74646 | W12: 0.05
A13: 3 | B13: Concessions | D13: =+SUMIFS('IS 2022'!$V:$V,'IS 2022'!$A:$A,$A13) -> 0 | E13: =+D13/'RR 11-4-25'!$G$152 -> 0 | G13: =+SUMIFS('IS 2023'!$V:$V,'IS 2023'!$A:$A,$A13) -> 0 | H13: =+G13/'RR 11-4-25'!$G$152 -> 0 | J13: =+SUMIFS('IS 2024'!$V:$V,'IS 2024'!$A:$A,$A13) -> 0 | K13: =+J13/'RR 11-4-25'!$G$152 -> 0 | M13: =+SUMIFS('TTM Nov-25'!U:U,'TTM Nov-25'!$A:$A,$A13) -> -1730 | N13: =+SUMIFS('TTM Nov-25'!T:T,'TTM Nov-25'!$A:$A,$A13) -> -3460 | O13: =+SUMIFS('TTM Nov-25'!S:S,'TTM Nov-25'!$A:$A,$A13) -> -4520 | P13: =+SUMIFS('TTM Nov-25'!R:R,'TTM Nov-25'!$A:$A,$A13) -> -4320 | Q13: =+SUMIFS('TTM Nov-25'!Q:Q,'TTM Nov-25'!$A:$A,$A13) -> -3720 | S13: =+-W13*S10 -> 0 | T13: =+S13/'RR 11-4-25'!$G$152 -> 0 | W13: 0
A14: 4 | B14: Delinquency/Bad Debt | D14: =+SUMIFS('IS 2022'!$V:$V,'IS 2022'!$A:$A,$A14) -> 0 | E14: =+D14/'RR 11-4-25'!$G$152 -> 0 | G14: =+SUMIFS('IS 2023'!$V:$V,'IS 2023'!$A:$A,$A14) -> 0 | H14: =+G14/'RR 11-4-25'!$G$152 -> 0 | J14: =+SUMIFS('IS 2024'!$V:$V,'IS 2024'!$A:$A,$A14) -> 0 | K14: =+J14/'RR 11-4-25'!$G$152 -> 0 | M14: =+SUMIFS('TTM Nov-25'!U:U,'TTM Nov-25'!$A:$A,$A14) -> -103089.13 | N14: =+SUMIFS('TTM Nov-25'!T:T,'TTM Nov-25'!$A:$A,$A14) -> -64606.52 | O14: =+SUMIFS('TTM Nov-25'!S:S,'TTM Nov-25'!$A:$A,$A14) -> -113341.04 | P14: =+SUMIFS('TTM Nov-25'!R:R,'TTM Nov-25'!$A:$A,$A14) -> -70044.42 | Q14: =+SUMIFS('TTM Nov-25'!Q:Q,'TTM Nov-25'!$A:$A,$A14) -> 0 | S14: =+-W14*S11 -> -49663.08 | T14: =+S14/'RR 11-4-25'!$G$152 -> -391.04787 | W14: 0.03
A15: 5 | B15: Model/Down Units | D15: =+SUMIFS('IS 2022'!$V:$V,'IS 2022'!$A:$A,$A15) -> 0 | E15: =+D15/'RR 11-4-25'!$G$152 -> 0 | G15: =+SUMIFS('IS 2023'!$V:$V,'IS 2023'!$A:$A,$A15) -> 0 | H15: =+G15/'RR 11-4-25'!$G$152 -> 0 | J15: =+SUMIFS('IS 2024'!$V:$V,'IS 2024'!$A:$A,$A15) -> 0 | K15: =+J15/'RR 11-4-25'!$G$152 -> 0 | M15: =+SUMIFS('TTM Nov-25'!U:U,'TTM Nov-25'!$A:$A,$A15) -> 0 | N15: =+SUMIFS('TTM Nov-25'!T:T,'TTM Nov-25'!$A:$A,$A15) -> 0 | O15: =+SUMIFS('TTM Nov-25'!S:S,'TTM Nov-25'!$A:$A,$A15) -> 0 | P15: =+SUMIFS('TTM Nov-25'!R:R,'TTM Nov-25'!$A:$A,$A15) -> 0 | Q15: =+SUMIFS('TTM Nov-25'!Q:Q,'TTM Nov-25'!$A:$A,$A15) -> 0 | S15: =+SUMIFS($M15:$Q15,$M$5:$Q$5,$W15)*(1+$V15) -> 0 | T15: =+S15/'RR 11-4-25'!$G$152 -> 0 | W15: T12
B16: Total Rental Income | D16: =+SUM(D11:D15) -> 0 | E16: =+D16/'RR 11-4-25'!$G$152 -> 0 | G16: =+SUM(G11:G15) -> 0 | H16: =+G16/'RR 11-4-25'!$G$152 -> 0 | J16: =+SUM(J11:J15) -> 0 | K16: =+J16/'RR 11-4-25'!$G$152 -> 0 | M16: =+SUM(M11:M15) -> 1228597.3 | N16: =+SUM(N11:N15) -> 1250445.3 | O16: =+SUM(O11:O15) -> 1238289 | P16: =+SUM(P11:P15) -> 1344145.9 | Q16: =+SUM(Q11:Q15) -> 1452522.5 | S16: =+SUM(S11:S15) -> 1523001.1 | T16: =+S16/'RR 11-4-25'!$G$152 -> 11992.135
A17: 6 | B17: Utility Reimbursements | D17: =+SUMIFS('IS 2022'!$V:$V,'IS 2022'!$A:$A,$A17) -> 0 | E17: =+D17/'RR 11-4-25'!$G$152 -> 0 | G17: =+SUMIFS('IS 2023'!$V:$V,'IS 2023'!$A:$A,$A17) -> 0 | H17: =+G17/'RR 11-4-25'!$G$152 -> 0 | J17: =+SUMIFS('IS 2024'!$V:$V,'IS 2024'!$A:$A,$A17) -> 0 | K17: =+J17/'RR 11-4-25'!$G$152 -> 0 | M17: =+SUMIFS('TTM Nov-25'!U:U,'TTM Nov-25'!$A:$A,$A17) -> 84585.01 | N17: =+SUMIFS('TTM Nov-25'!T:T,'TTM Nov-25'!$A:$A,$A17) -> 82450.02 | O17: =+SUMIFS('TTM Nov-25'!S:S,'TTM Nov-25'!$A:$A,$A17) -> 90137.28 | P17: =+SUMIFS('TTM Nov-25'!R:R,'TTM Nov-25'!$A:$A,$A17) -> 93177.96 | Q17: =+SUMIFS('TTM Nov-25'!Q:Q,'TTM Nov-25'!$A:$A,$A17) -> 93227.52 | S17: =+SUMIFS($M17:$Q17,$M$5:$Q$5,$W17)*(1+$V17) -> 87122.56 | T17: =+S17/'RR 11-4-25'!$G$152 -> 686.00441 | V17: 0.03 | W17: T12
A18: 7 | B18: Miscellaneous Income | D18: =+SUMIFS('IS 2022'!$V:$V,'IS 2022'!$A:$A,$A18) -> 0 | E18: =+D18/'RR 11-4-25'!$G$152 -> 0 | G18: =+SUMIFS('IS 2023'!$V:$V,'IS 2023'!$A:$A,$A18) -> 0 | H18: =+G18/'RR 11-4-25'!$G$152 -> 0 | J18: =+SUMIFS('IS 2024'!$V:$V,'IS 2024'!$A:$A,$A18) -> 0 | K18: =+J18/'RR 11-4-25'!$G$152 -> 0 | M18: =+SUMIFS('TTM Nov-25'!U:U,'TTM Nov-25'!$A:$A,$A18) -> 121263.83 | N18: =+SUMIFS('TTM Nov-25'!T:T,'TTM Nov-25'!$A:$A,$A18) -> 91409.54 | O18: =+SUMIFS('TTM Nov-25'!S:S,'TTM Nov-25'!$A:$A,$A18) -> 88093.56 | P18: =+SUMIFS('TTM Nov-25'!R:R,'TTM Nov-25'!$A:$A,$A18) -> 95491.5 | Q18: =+SUMIFS('TTM Nov-25'!Q:Q,'TTM Nov-25'!$A:$A,$A18) -> 116246.76 | S18: =+SUMIFS($M18:$Q18,$M$5:$Q$5,$W18)*(1+$V18) -> 124901.74 | T18: =+S18/'RR 11-4-25'!$G$152 -> 983.47831 | V18: 0.03 | W18: T12
B19: Effective Gross Income | D19: =+SUM(D16:D18) -> 0 | E19: =+D19/'RR 11-4-25'!$G$152 -> 0 | G19: =+SUM(G16:G18) -> 0 | H19: =+G19/'RR 11-4-25'!$G$152 -> 0 | J19: =+SUM(J16:J18) -> 0 | K19: =+J19/'RR 11-4-25'!$G$152 -> 0 | M19: =+SUM(M16:M18) -> 1434446.1 | N19: =+SUM(N16:N18) -> 1424304.9 | O19: =+SUM(O16:O18) -> 1416519.8 | P19: =+SUM(P16:P18) -> 1532815.4 | Q19: =+SUM(Q16:Q18) -> 1661996.8 | S19: =+SUM(S16:S18) -> 1735025.4 | T19: =+S19/'RR 11-4-25'!$G$152 -> 13661.618
B21: EXPENSES
A22: 8 | B22: Payroll | D22: =+SUMIFS('IS 2022'!$V:$V,'IS 2022'!$A:$A,$A22) -> 0 | E22: =+D22/'RR 11-4-25'!$G$152 -> 0 | G22: =+SUMIFS('IS 2023'!$V:$V,'IS 2023'!$A:$A,$A22) -> 0 | H22: =+G22/'RR 11-4-25'!$G$152 -> 0 | J22: =+SUMIFS('IS 2024'!$V:$V,'IS 2024'!$A:$A,$A22) -> 0 | K22: =+J22/'RR 11-4-25'!$G$152 -> 0 | M22: =+SUMIFS('TTM Nov-25'!U:U,'TTM Nov-25'!$A:$A,$A22) -> 100635.17 | N22: =+SUMIFS('TTM Nov-25'!T:T,'TTM Nov-25'!$A:$A,$A22) -> 186164.24 | O22: =+SUMIFS('TTM Nov-25'!S:S,'TTM Nov-25'!$A:$A,$A22) -> 158930.56 | P22: =+SUMIFS('TTM Nov-25'!R:R,'TTM Nov-25'!$A:$A,$A22) -> 163955.64 | Q22: =+SUMIFS('TTM Nov-25'!Q:Q,'TTM Nov-25'!$A:$A,$A22) -> 146188.08 | S22: =+SUMIFS($M22:$Q22,$M$5:$Q$5,$W22)*(1+$V22) -> 103654.23 | T22: =+S22/'RR 11-4-25'!$G$152 -> 816.175 | V22: 0.03 | W22: T12
A23: 9 | B23: General & Administrative | D23: =+SUMIFS('IS 2022'!$V:$V,'IS 2022'!$A:$A,$A23) -> 0 | E23: =+D23/'RR 11-4-25'!$G$152 -> 0 | G23: =+SUMIFS('IS 2023'!$V:$V,'IS 2023'!$A:$A,$A23) -> 0 | H23: =+G23/'RR 11-4-25'!$G$152 -> 0 | J23: =+SUMIFS('IS 2024'!$V:$V,'IS 2024'!$A:$A,$A23) -> 0 | K23: =+J23/'RR 11-4-25'!$G$152 -> 0 | M23: =+SUMIFS('TTM Nov-25'!U:U,'TTM Nov-25'!$A:$A,$A23) -> 57350.2 | N23: =+SUMIFS('TTM Nov-25'!T:T,'TTM Nov-25'!$A:$A,$A23) -> 42387.04 | O23: =+SUMIFS('TTM Nov-25'!S:S,'TTM Nov-25'!$A:$A,$A23) -> 25765.2 | P23: =+SUMIFS('TTM Nov-25'!R:R,'TTM Nov-25'!$A:$A,$A23) -> 27994.2 | Q23: =+SUMIFS('TTM Nov-25'!Q:Q,'TTM Nov-25'!$A:$A,$A23) -> 21189.12 | S23: =+SUMIFS($M23:$Q23,$M$5:$Q$5,$W23)*(1+$V23) -> 59070.706 | T23: =+S23/'RR 11-4-25'!$G$152 -> 465.12367 | V23: 0.03 | W23: T12
A24: 10 | B24: Advertising | D24: =+SUMIFS('IS 2022'!$V:$V,'IS 2022'!$A:$A,$A24) -> 0 | E24: =+D24/'RR 11-4-25'!$G$152 -> 0 | G24: =+SUMIFS('IS 2023'!$V:$V,'IS 2023'!$A:$A,$A24) -> 0 | H24: =+G24/'RR 11-4-25'!$G$152 -> 0 | J24: =+SUMIFS('IS 2024'!$V:$V,'IS 2024'!$A:$A,$A24) -> 0 | K24: =+J24/'RR 11-4-25'!$G$152 -> 0 | M24: =+SUMIFS('TTM Nov-25'!U:U,'TTM Nov-25'!$A:$A,$A24) -> 31392.72 | N24: =+SUMIFS('TTM Nov-25'!T:T,'TTM Nov-25'!$A:$A,$A24) -> 51515.14 | O24: =+SUMIFS('TTM Nov-25'!S:S,'TTM Nov-25'!$A:$A,$A24) -> 47359.68 | P24: =+SUMIFS('TTM Nov-25'!R:R,'TTM Nov-25'!$A:$A,$A24) -> 44658 | Q24: =+SUMIFS('TTM Nov-25'!Q:Q,'TTM Nov-25'!$A:$A,$A24) -> 45744 | S24: =+SUMIFS($M24:$Q24,$M$5:$Q$5,$W24)*(1+$V24) -> 32334.502 | T24: =+S24/'RR 11-4-25'!$G$152 -> 254.60237 | V24: 0.03 | W24: T12
A25: 11 | B25: Repairs & Maintenance | D25: =+SUMIFS('IS 2022'!$V:$V,'IS 2022'!$A:$A,$A25) -> 0 | E25: =+D25/'RR 11-4-25'!$G$152 -> 0 | G25: =+SUMIFS('IS 2023'!$V:$V,'IS 2023'!$A:$A,$A25) -> 0 | H25: =+G25/'RR 11-4-25'!$G$152 -> 0 | J25: =+SUMIFS('IS 2024'!$V:$V,'IS 2024'!$A:$A,$A25) -> 0 | K25: =+J25/'RR 11-4-25'!$G$152 -> 0 | M25: =+SUMIFS('TTM Nov-25'!U:U,'TTM Nov-25'!$A:$A,$A25) -> 63036.33 | N25: =+SUMIFS('TTM Nov-25'!T:T,'TTM Nov-25'!$A:$A,$A25) -> 57352.92 | O25: =+SUMIFS('TTM Nov-25'!S:S,'TTM Nov-25'!$A:$A,$A25) -> 68108.68 | P25: =+SUMIFS('TTM Nov-25'!R:R,'TTM Nov-25'!$A:$A,$A25) -> 70273.2 | Q25: =+SUMIFS('TTM Nov-25'!Q:Q,'TTM Nov-25'!$A:$A,$A25) -> 80229.6 | S25: =+SUMIFS($M25:$Q25,$M$5:$Q$5,$W25)*(1+$V25) -> 64927.42 | T25: =+S25/'RR 11-4-25'!$G$152 -> 511.23953 | V25: 0.03 | W25: T12
A26: 12 | B26: Contract Services | D26: =+SUMIFS('IS 2022'!$V:$V,'IS 2022'!$A:$A,$A26) -> 0 | E26: =+D26/'RR 11-4-25'!$G$152 -> 0 | G26: =+SUMIFS('IS 2023'!$V:$V,'IS 2023'!$A:$A,$A26) -> 0 | H26: =+G26/'RR 11-4-25'!$G$152 -> 0 | J26: =+SUMIFS('IS 2024'!$V:$V,'IS 2024'!$A:$A,$A26) -> 0 | K26: =+J26/'RR 11-4-25'!$G$152 -> 0 | M26: =+SUMIFS('TTM Nov-25'!U:U,'TTM Nov-25'!$A:$A,$A26) -> 64588.97 | N26: =+SUMIFS('TTM Nov-25'!T:T,'TTM Nov-25'!$A:$A,$A26) -> 64074.82 | O26: =+SUMIFS('TTM Nov-25'!S:S,'TTM Nov-25'!$A:$A,$A26) -> 70707.72 | P26: =+SUMIFS('TTM Nov-25'!R:R,'TTM Nov-25'!$A:$A,$A26) -> 76203.42 | Q26: =+SUMIFS('TTM Nov-25'!Q:Q,'TTM Nov-25'!$A:$A,$A26) -> 88183.2 | S26: =+SUMIFS($M26:$Q26,$M$5:$Q$5,$W26)*(1+$V26) -> 66526.639 | T26: =+S26/'RR 11-4-25'!$G$152 -> 523.8318 | V26: 0.03 | W26: T12
A27: 13 | B27: Turnover/Cleaning | D27: =+SUMIFS('IS 2022'!$V:$V,'IS 2022'!$A:$A,$A27) -> 0 | E27: =+D27/'RR 11-4-25'!$G$152 -> 0 | G27: =+SUMIFS('IS 2023'!$V:$V,'IS 2023'!$A:$A,$A27) -> 0 | H27: =+G27/'RR 11-4-25'!$G$152 -> 0 | J27: =+SUMIFS('IS 2024'!$V:$V,'IS 2024'!$A:$A,$A27) -> 0 | K27: =+J27/'RR 11-4-25'!$G$152 -> 0 | M27: =+SUMIFS('TTM Nov-25'!U:U,'TTM Nov-25'!$A:$A,$A27) -> 45653.38 | N27: =+SUMIFS('TTM Nov-25'!T:T,'TTM Nov-25'!$A:$A,$A27) -> 32028.48 | O27: =+SUMIFS('TTM Nov-25'!S:S,'TTM Nov-25'!$A:$A,$A27) -> 50841.76 | P27: =+SUMIFS('TTM Nov-25'!R:R,'TTM Nov-25'!$A:$A,$A27) -> 24147.96 | Q27: =+SUMIFS('TTM Nov-25'!Q:Q,'TTM Nov-25'!$A:$A,$A27) -> 15101.52 | S27: =+SUMIFS($M27:$Q27,$M$5:$Q$5,$W27)*(1+$V27) -> 47022.981 | T27: =+S27/'RR 11-4-25'!$G$152 -> 370.2597 | V27: 0.03 | W27: T12
A28: 14 | B28: Utilities | D28: =+SUMIFS('IS 2022'!$V:$V,'IS 2022'!$A:$A,$A28) -> 0 | E28: =+D28/'RR 11-4-25'!$G$152 -> 0 | G28: =+SUMIFS('IS 2023'!$V:$V,'IS 2023'!$A:$A,$A28) -> 0 | H28: =+G28/'RR 11-4-25'!$G$152 -> 0 | J28: =+SUMIFS('IS 2024'!$V:$V,'IS 2024'!$A:$A,$A28) -> 0 | K28: =+J28/'RR 11-4-25'!$G$152 -> 0 | M28: =+SUMIFS('TTM Nov-25'!U:U,'TTM Nov-25'!$A:$A,$A28) -> 75704.43 | N28: =+SUMIFS('TTM Nov-25'!T:T,'TTM Nov-25'!$A:$A,$A28) -> 79541.56 | O28: =+SUMIFS('TTM Nov-25'!S:S,'TTM Nov-25'!$A:$A,$A28) -> 76849.04 | P28: =+SUMIFS('TTM Nov-25'!R:R,'TTM Nov-25'!$A:$A,$A28) -> 73728 | Q28: =+SUMIFS('TTM Nov-25'!Q:Q,'TTM Nov-25'!$A:$A,$A28) -> 75841.44 | S28: =+SUMIFS($M28:$Q28,$M$5:$Q$5,$W28)*(1+$V28) -> 77975.563 | T28: =+S28/'RR 11-4-25'!$G$152 -> 613.98081 | V28: 0.03 | W28: T12
A29: 15 | B29: Property Taxes | D29: =+SUMIFS('IS 2022'!$V:$V,'IS 2022'!$A:$A,$A29) -> 0 | E29: =+D29/'RR 11-4-25'!$G$152 -> 0 | G29: =+SUMIFS('IS 2023'!$V:$V,'IS 2023'!$A:$A,$A29) -> 0 | H29: =+G29/'RR 11-4-25'!$G$152 -> 0 | J29: =+SUMIFS('IS 2024'!$V:$V,'IS 2024'!$A:$A,$A29) -> 0 | K29: =+J29/'RR 11-4-25'!$G$152 -> 0 | M29: =+SUMIFS('TTM Nov-25'!U:U,'TTM Nov-25'!$A:$A,$A29) -> 164042.76 | N29: =+SUMIFS('TTM Nov-25'!T:T,'TTM Nov-25'!$A:$A,$A29) -> 165073.2 | O29: =+SUMIFS('TTM Nov-25'!S:S,'TTM Nov-25'!$A:$A,$A29) -> 158173.16 | P29: =+SUMIFS('TTM Nov-25'!R:R,'TTM Nov-25'!$A:$A,$A29) -> 143126.88 | Q29: =+SUMIFS('TTM Nov-25'!Q:Q,'TTM Nov-25'!$A:$A,$A29) -> 97988.04 | S29: =+IF($W29=AA$39,$AA$46,(1+$V29)*$AL$69) -> 163732.42 | T29: =+S29/'RR 11-4-25'!$G$152 -> 1289.2316 | V29: 0.03 | W29: 2025 Bill
A30: 16 | B30: Property Insurance | D30: =+SUMIFS('IS 2022'!$V:$V,'IS 2022'!$A:$A,$A30) -> 0 | E30: =+D30/'RR 11-4-25'!$G$152 -> 0 | G30: =+SUMIFS('IS 2023'!$V:$V,'IS 2023'!$A:$A,$A30) -> 0 | H30: =+G30/'RR 11-4-25'!$G$152 -> 0 | J30: =+SUMIFS('IS 2024'!$V:$V,'IS 2024'!$A:$A,$A30) -> 0 | K30: =+J30/'RR 11-4-25'!$G$152 -> 0 | M30: =+SUMIFS('TTM Nov-25'!U:U,'TTM Nov-25'!$A:$A,$A30) -> 206902.04 | N30: =+SUMIFS('TTM Nov-25'!T:T,'TTM Nov-25'!$A:$A,$A30) -> 228812.92 | O30: =+SUMIFS('TTM Nov-25'!S:S,'TTM Nov-25'!$A:$A,$A30) -> 244238.28 | P30: =+SUMIFS('TTM Nov-25'!R:R,'TTM Nov-25'!$A:$A,$A30) -> 244238.28 | Q30: =+SUMIFS('TTM Nov-25'!Q:Q,'TTM Nov-25'!$A:$A,$A30) -> 244238.28 | S30: 160000 | T30: =+S30/'RR 11-4-25'!$G$152 -> 1259.8425 | W30: Insurance Renewal
A31: 17 | B31: Management Fee | D31: =+SUMIFS('IS 2022'!$V:$V,'IS 2022'!$A:$A,$A31) -> 0 | E31: =+D31/'RR 11-4-25'!$G$152 -> 0 | G31: =+SUMIFS('IS 2023'!$V:$V,'IS 2023'!$A:$A,$A31) -> 0 | H31: =+G31/'RR 11-4-25'!$G$152 -> 0 | J31: =+SUMIFS('IS 2024'!$V:$V,'IS 2024'!$A:$A,$A31) -> 0 | K31: =+J31/'RR 11-4-25'!$G$152 -> 0 | M31: =+SUMIFS('TTM Nov-25'!U:U,'TTM Nov-25'!$A:$A,$A31) -> 121532.18 | N31: =+SUMIFS('TTM Nov-25'!T:T,'TTM Nov-25'!$A:$A,$A31) -> 54000 | O31: =+SUMIFS('TTM Nov-25'!S:S,'TTM Nov-25'!$A:$A,$A31) -> 54000 | P31: =+SUMIFS('TTM Nov-25'!R:R,'TTM Nov-25'!$A:$A,$A31) -> 54000 | Q31: =+SUMIFS('TTM Nov-25'!Q:Q,'TTM Nov-25'!$A:$A,$A31) -> 54000 | S31: =+W31*S19 -> 60725.89 | T31: =+S31/'RR 11-4-25'!$G$152 -> 478.15661 | W31: 0.035
B32: Reserves | D32: =+SUMIFS('IS 2022'!$V:$V,'IS 2022'!$A:$A,$A32) -> 0 | E32: =+D32/'RR 11-4-25'!$G$152 -> 0 | G32: =+SUMIFS('IS 2023'!$V:$V,'IS 2023'!$A:$A,$A32) -> 0 | H32: =+G32/'RR 11-4-25'!$G$152 -> 0 | J32: =+SUMIFS('IS 2024'!$V:$V,'IS 2024'!$A:$A,$A32) -> 0 | K32: =+J32/'RR 11-4-25'!$G$152 -> 0 | S32: =+$W32*'RR 11-4-25'!$G$152 -> 38100 | T32: =+S32/'RR 11-4-25'!$G$152 -> 300 | W32: 300
B33: Total Operating Expenses | D33: =+SUM(D22:D32) -> 0 | E33: =+D33/'RR 11-4-25'!$G$152 -> 0 | G33: =+SUM(G22:G32) -> 0 | H33: =+G33/'RR 11-4-25'!$G$152 -> 0 | J33: =+SUM(J22:J32) -> 0 | K33: =+J33/'RR 11-4-25'!$G$152 -> 0 | M33: =+SUM(M22:M32) -> 930838.18 | N33: =+SUM(N22:N32) -> 960950.32 | O33: =+SUM(O22:O32) -> 954974.08 | P33: =+SUM(P22:P32) -> 922325.58 | Q33: =+SUM(Q22:Q32) -> 868703.28 | S33: =+SUM(S22:S32) -> 874070.34 | T33: =+S33/'RR 11-4-25'!$G$152 -> 6882.4436
B34: Expense Ratio | D34: =+IFERROR(D33/D19,"NA") -> NA | G34: =+IFERROR(G33/G19,"NA") -> NA | J34: =+IFERROR(J33/J19,"NA") -> NA | S34: =+S33/S19 -> 0.50377956
B36: NET OPERATING INCOME | D36: =+D19-D33 -> 0 | E36: =+E19-E33 -> 0 | G36: =+G19-G33 -> 0 | H36: =+H19-H33 -> 0 | J36: =+J19-J33 -> 0 | K36: =+K19-K33 -> 0 | M36: =+M19-M33 -> 503607.95 | N36: =+N19-N33 -> 463354.54 | O36: =+O19-O33 -> 461545.76 | P36: =+P19-P33 -> 610489.8 | Q36: =+Q19-Q33 -> 793293.48 | S36: =+S19-S33 -> 860955.08 | T36: =+T19-T33 -> 6779.1739
B38: Footnotes: | Y38: PROPERTY TAX CALC | AF38: 2026 | AJ38: 2025 | AN38: 2024 | AR38: 2023 | AV38: 2022
AA39: Re-Assessed Value | AD39: Taxable Values
Y40: Market Value | AA40: 11000000 | AD40: Non-School | AF40: =+(1+AVERAGE(AJ44:AN44))*AJ40 -> 9442061 | AJ40: 9143000 | AN40: 8958200 | AR40: 8574168 | AV40: 7794699
Y41: Taxable Value | Z41: 0.8 | AA41: =+Z41*AA40 -> 8800000 | AD41: School | AF41: =+(1+$AJ45)*AJ41 -> 9331612.3 | AJ41: 9143000 | AN41: 8958200 | AR41: 9103200 | AV41: 8947800
Y42: Millage Rate | Z42: =+$AG$57 -> 17.7412 | AA42: =+(Z42/1000)*AA41 -> 156122.56
P43: LOAN METRICS | Y43: Non-Ad Valorem | AA43: =+AH62 -> 3379.2 | AD43: YoY Increases
T44: Per Unit | Y44: Taxes | AA44: =+SUM(AA42:AA43) -> 159501.76 | AD44: Non-School | AF44: =+AF40/AJ40-1 -> 0.032709281 | AJ44: =+AJ40/AN40-1 -> 0.020629144 | AN44: =+AN40/AR40-1 -> 0.044789419 | AR44: =+AR40/AV40-1 -> 0.099999885
P45: Cap Rate | Q45: 0.0575 | S45: =+ROUND(S36/Q45,-4) -> 14970000 | T45: =+ROUND(S45/'RR 11-4-25'!$G$152,-3) -> 118000 | Y45: Prepay | Z45: -0.04 | AA45: =+Z45*AA44 -> -6380.0704 | AD45: School | AF45: =+AF41/AJ41-1 -> 0.020629144 | AJ45: =+AJ41/AN41-1 -> 0.020629144 | AN45: =+AN41/AR41-1 -> -0.015928465 | AR45: =+AR41/AV41-1 -> 0.017367398
P46: LTV | Q46: =+S46/S45 -> 0.70140281 | S46: 10500000 | T46: =+ROUND(S46/'RR 11-4-25'!$G$152,-3) -> 83000 | Y46: Taxes net of Prepay | AA46: =+SUM(AA44:AA45) -> 153121.69
...

Sheet Sources & Uses
B2: OASIS AT SAN MARCO
B3: LOAN REQUEST AND SOURCES & USES
B6: Loan Sizing | F6: Sources and Uses
B10: On Cost | D10: Per Unit | F10: SOURCES
B11: =+"Value at "&TEXT(PROFORMA!$Q$45,"#.0%")&" cap rate on Proforma NOI" -> Value at 5.8% cap rate on Proforma NOI | C11: =+PROFORMA!$S$45 -> 14970000 | D11: =+ROUND(C11/'RR 11-4-25'!$G$152,-3) -> 118000 | F11: Debt | H11: =+C12 -> 10500000 | I11: =+H11/$H$12 -> 1
B12: Loan Size | C12: =+PROFORMA!$S$46 -> 10500000 | D12: =+ROUND(C12/'RR 11-4-25'!$G$152,-3) -> 83000 | F12: TOTAL SOURCES | H12: =+H11 -> 10500000 | I12: =+H12/$H$12 -> 1
B13: Loan to Value | C13: =+C12/C11 -> 0.70140281
F14: USES
B15: On Proforma | F15: Payoff Existing Loan | H15: 10300000 | I15: =+H15/$H$19 -> 0.98095238
B16: Market Cap Rate | C16: =+PROFORMA!$Q$45 -> 0.0575 | F16: Recoup Previously Expended Capital (see schedule page 6) | I16: =+H16/$H$19 -> 0
B17: Proforma NOI (CBRE UW) | C17: =+PROFORMA!$S$36 -> 860955.08 | F17: Closing Costs | H17: =+$I$61 -> 224675 | I17: 0.02
B18: Index | C18: =+PROFORMA!$S$48 -> 3-YR UST | F18: Equity Recapture | H18: =+H19-SUM(H15:H17) -> -24675 | I18: =+H18/$H$19 -> -0.00235
B19: =+PROFORMA!$P$49 -> Index Rate as of 11/11/2025 | C19: =+PROFORMA!S49 -> 0.0355 | F19: TOTAL USES | H19: =+H12 -> 10500000 | I19: =+H19/$H$19 -> 1
B20: Spread | C20: =+PROFORMA!S50 -> 0.02
B21: =+PROFORMA!$P$51 -> Face Rate as of 11/11/2025 | C21: =+SUM(C19:C20) -> 0.0555 | F21: BASIS
B22: IO DSCR at current Face Rate | C22: =+C17/(C21*C12) -> 1.4774004 | F22: Purchase Price (1/22/2024) | H22: 11370000 | I22: =+H22/$H$25 -> 0.98039216 | K22: =+H22/'RR 11-4-25'!$G$152 -> 89527.559
B23: 25-Year Amortizing DSCR at current Face Rate | C23: =+PROFORMA!S56 -> 1.1124347 | F23: Closing Costs & Due Diligence | H23: =2%*H22 -> 227400 | I23: =+H23/$H$25 -> 0.019607843 | K23: =+H23/'RR 11-4-25'!$G$152 -> 1790.5512
B24: 30-Year Amortizing DSCR at current Face Rate | C24: =+PROFORMA!S57 -> 1.2023504 | F24: Additional Capital Expenditures (see schedule page 6) | I24: =+H24/$H$25 -> 0 | K24: =+H24/'RR 11-4-25'!$G$152 -> 0
B25: Stabilized Yield on Cost | C25: =+C17/C12 -> 0.081995722 | F25: TOTAL BASIS | H25: =+SUM(H22:H24) -> 11597400 | I25: =+H25/$H$25 -> 1 | K25: =+C11/H25-1 -> 0.29080656
F28: Loan Closing Costs
F32: Loan Request | I32: =+H11 -> 10500000
F37: Origination Fees
F38: Lender Fee | H38: 0.0025 | I38: =+H38*$I$32 -> 26250
F39: CBRE Fee | H39: 0.01 | I39: =+H39*$I$32 -> 105000
H40: =+SUBTOTAL(9,H38:H39) -> 0.0125 | I40: =+SUBTOTAL(9,I38:I39) -> 131250
F41: Legal Fees
F42: Lender Legal | H42: =+I42/$I$32 -> 0.0019047619 | I42: 20000
F43: Borrower Legal | H43: =+I43/$I$32 -> 0.0019047619 | I43: 20000
H44: =+SUBTOTAL(9,H42:H43) -> 0.0038095238 | I44: =+SUBTOTAL(9,I42:I43) -> 40000
F45: Taxes / Government Fees
F46: FL Documentary Stamp Tax | G46: 0.35 | H46: =+I46/$I$32 -> 6.6666667e-05 | I46: =+G46*(($I$32-$H$15)/100) -> 700 | L46: Title Insurance Sizer | N46: =+SUM(N47:N51) -> 27325
F47: FL Intangible Tax | G47: 2 | H47: =+I47/$I$32 -> 3.8095238e-05 | I47: =+G47*(($I$32-$H$15)/1000) -> 400 | L47: 100000 | M47: 0.00575 | N47: =+M47*L47 -> 575
F48: Recording and Filing Fees | H48: =+I48/$I$32 -> 0.00047619048 | I48: 5000 | L48: 1000000 | M48: 0.005 | N48: =+M48*(L48-L47) -> 4500
H49: =+SUBTOTAL(9,H46:H48) -> 0.00058095238 | I49: =+SUBTOTAL(9,I46:I48) -> 6100 | L49: 5000000 | M49: 0.0025 | N49: =+M49*(L49-L48) -> 10000
L50: 10000000 | M50: 0.00225 | N50: =+M50*(L50-L49) -> 11250
F51: Title Insurance Policy | H51: =+I51/$I$32 -> 0.002602381 | I51: =+N46 -> 27325 | L51: =+H11 -> 10500000 | M51: 0.002 | N51: =+M51*(L51-L50) -> 1000
F53: Due Diligence / Third Party Reports
F54: Survey | H54: =+I54/$I$32 -> 0.00052380952 | I54: 5500
F55: ESA | H55: =+I55/$I$32 -> 0.00033333333 | I55: 3500
F56: PCA | H56: =+I56/$I$32 -> 0.00038095238 | I56: 4000
...

Sheet CapEx
B2: TOPAZ VILLAGE
B3: HISTORICAL CAPITAL EXPENDITURES UNDER CURRENT OWNERSHIP
B5: CapEx Schedule | D5: 2018 | E5: 2019 | F5: 2020 | G5: 2021 | H5: 2022 | I5: 2023 | J5: 2024 | K5: YTD thru 7/31/25 | L5: Total
B9: COMMON ITEMS
B10: Water Heaters | D10: 5977 | E10: 8712 | F10: 5624 | G10: 5519 | H10: 2514 | I10: 4370 | J10: 1964 | K10: 4218 | L10: =+SUM(D10:K10) -> 38898
B11: Plumbing | D11: 111 | E11: 23463 | F11: 2132 | G11: 14401 | H11: 1100 | I11: 16645 | J11: 12500 | K11: 5275 | L11: =+SUM(D11:K11) -> 75627
B12: Electrical | D12: 5757 | E12: 5696 | F12: 4378 | G12: 1716 | H12: 1686 | I12: 2241 | J12: 3406 | K12: 0 | L12: =+SUM(D12:K12) -> 24880
D13: =+SUBTOTAL(9,D10:D12) -> 11845 | E13: =+SUBTOTAL(9,E10:E12) -> 37871 | F13: =+SUBTOTAL(9,F10:F12) -> 12134 | G13: =+SUBTOTAL(9,G10:G12) -> 21636 | H13: =+SUBTOTAL(9,H10:H12) -> 5300 | I13: =+SUBTOTAL(9,I10:I12) -> 23256 | J13: =+SUBTOTAL(9,J10:J12) -> 17870 | K13: =+SUBTOTAL(9,K10:K12) -> 9493 | L13: =+SUBTOTAL(9,L10:L12) -> 139405
B15: COMMON AREA ITEMS
B16: Common Area Improvements | D16: 35465 | E16: 43825 | F16: 5919 | G16: 12525 | H16: 27267 | I16: 37031 | J16: 22923 | K16: 9453 | L16: =+SUM(D16:K16) -> 194408
B17: Trees and Landscaping | D17: 28754 | E17: 10350 | F17: 0 | G17: 4700 | H17: 16055 | I17: 19255 | J17: 5845 | K17: 0 | L17: =+SUM(D17:K17) -> 84959
B18: Asphalt | D18: 0 | E18: 41820 | F18: 0 | G18: 0 | H18: 0 | I18: 2296 | J18: 0 | K18: 8750 | L18: =+SUM(D18:K18) -> 52866
B19: Approved Capital Projects | D19: 4906 | E19: 19041 | F19: 0 | G19: 1772 | H19: 0 | I19: 0 | J19: 0 | K19: 0 | L19: =+SUM(D19:K19) -> 25719
B20: Laundry Room Equipment | D20: 0 | E20: 29000 | F20: 0 | G20: 0 | H20: 0 | I20: 0 | J20: 0 | K20: 0 | L20: =+SUM(D20:K20) -> 29000
B21: Fitness Room | D21: 0 | E21: 0 | F21: 13881 | G21: 0 | H21: 0 | I21: 0 | J21: 0 | K21: 0 | L21: =+SUM(D21:K21) -> 13881
B22: Amenities | D22: 0 | E22: 0 | F22: 0 | G22: 0 | H22: 2308 | I22: 4850 | J22: 1666 | K22: 0 | L22: =+SUM(D22:K22) -> 8824
B23: Clubhouse Renovation | D23: 11833 | E23: 0 | F23: 0 | G23: 0 | H23: 6589 | I23: 0 | J23: 0 | K23: 0 | L23: =+SUM(D23:K23) -> 18422
D24: =+SUBTOTAL(9,D16:D23) -> 80958 | E24: =+SUBTOTAL(9,E16:E23) -> 144036 | F24: =+SUBTOTAL(9,F16:F23) -> 19800 | G24: =+SUBTOTAL(9,G16:G23) -> 18997 | H24: =+SUBTOTAL(9,H16:H23) -> 52219 | I24: =+SUBTOTAL(9,I16:I23) -> 63432 | J24: =+SUBTOTAL(9,J16:J23) -> 30434 | K24: =+SUBTOTAL(9,K16:K23) -> 18203 | L24: =+SUBTOTAL(9,L16:L23) -> 428079
B26: BIG TICKET ITEMS
B27: HVAC Replacement | D27: 51911 | E27: 19582 | F27: 44356 | G27: 24958 | H27: 43503 | I27: 59832 | J27: 67875 | K27: 23721 | L27: =+SUM(D27:K27) -> 335738
B28: Roof Replacement | D28: 0 | E28: 0 | F28: 0 | G28: 0 | H28: 7100 | I28: 6000 | J28: 18361 | K28: 5000 | L28: =+SUM(D28:K28) -> 36461
D29: =+SUBTOTAL(9,D27:D28) -> 51911 | E29: =+SUBTOTAL(9,E27:E28) -> 19582 | F29: =+SUBTOTAL(9,F27:F28) -> 44356 | G29: =+SUBTOTAL(9,G27:G28) -> 24958 | H29: =+SUBTOTAL(9,H27:H28) -> 50603 | I29: =+SUBTOTAL(9,I27:I28) -> 65832 | J29: =+SUBTOTAL(9,J27:J28) -> 86236 | K29: =+SUBTOTAL(9,K27:K28) -> 28721 | L29: =+SUBTOTAL(9,L27:L28) -> 372199
B31: UNIT RENOVATIONS AND UPGRADES
B32: Unit Upgrade Capital - Appliances | D32: 22002 | E32: 47467 | F32: 34343 | G32: 24175 | H32: 35747 | I32: 31534 | J32: 16390 | K32: 19354 | L32: =+SUM(D32:K32) -> 231012
B33: Unit Upgrade Capital - General | D33: 75191 | E33: 434939 | F33: 127351 | G33: 3523 | H33: 4394 | I33: 1061 | J33: 3166 | K33: 9488 | L33: =+SUM(D33:K33) -> 659113
B34: Unit Upgrade Capital - Flooring | D34: 98983 | E34: 260132 | F34: 105365 | G34: 57498 | H34: 29279 | I34: 38116 | J34: 23809 | K34: 48748 | L34: =+SUM(D34:K34) -> 661930
D35: =+SUBTOTAL(9,D32:D34) -> 196176 | E35: =+SUBTOTAL(9,E32:E34) -> 742538 | F35: =+SUBTOTAL(9,F32:F34) -> 267059 | G35: =+SUBTOTAL(9,G32:G34) -> 85196 | H35: =+SUBTOTAL(9,H32:H34) -> 69420 | I35: =+SUBTOTAL(9,I32:I34) -> 70711 | J35: =+SUBTOTAL(9,J32:J34) -> 43365 | K35: =+SUBTOTAL(9,K32:K34) -> 77590 | L35: =+SUBTOTAL(9,L32:L34) -> 1552055
B37: Total | D37: =+SUBTOTAL(9,D10:D36) -> 340890 | E37: =+SUBTOTAL(9,E10:E36) -> 944027 | F37: =+SUBTOTAL(9,F10:F36) -> 343349 | G37: =+SUBTOTAL(9,G10:G36) -> 150787 | H37: =+SUBTOTAL(9,H10:H36) -> 177542 | I37: =+SUBTOTAL(9,I10:I36) -> 223231 | J37: =+SUBTOTAL(9,J10:J36) -> 177905 | K37: =+SUBTOTAL(9,K10:K36) -> 134007 | L37: =+SUBTOTAL(9,L10:L36) -> 2491738

Sheet Unit Mix
B3: Unit Mix
B8: Floorplan | C8: Average SQFT | D8: # Units | E8: # Occupied Units | F8: Occupancy % | G8: Average Market Rent | H8: Market Rent PSF | I8: Average In-Place Rent | J8: In-Place Rent PSF
B9: 1x1a | C9: 645 | D9: 62 | E9: 57 | F9: 0.9194 | G9: 1132.18 | H9: 1.76 | I9: 936.33 | J9: 1.45
B10: 1x1L | C10: 745 | D10: 44 | E10: 41 | F10: 0.9318 | G10: 1209.89 | H10: 1.62 | I10: 1016.39 | J10: 1.36
B11: 1x1L-C | C11: 745 | D11: 36 | E11: 33 | F11: 0.9167 | G11: 1222.08 | H11: 1.64 | I11: 1044.39 | J11: 1.4
B12: 2x1 | C12: 996 | D12: 2 | E12: 2 | F12: 1 | G12: 1335 | H12: 1.34 | I12: 1102.5 | J12: 1.11
B13: 2x1-C | C13: 996 | D13: 30 | E13: 30 | F13: 1 | G13: 1414 | H13: 1.42 | I13: 1197.37 | J13: 1.2
B14: 2x2 | C14: 1024 | D14: 1 | E14: 1 | F14: 1 | G14: 1440 | H14: 1.41 | I14: 1185 | J14: 1.16
B15: 2x2-C | C15: 1024 | D15: 51 | E15: 50 | F15: 0.9804 | G15: 1485.1 | H15: 1.45 | I15: 1242.56 | J15: 1.21
B16: 3x2 | C16: 1320 | D16: 32 | E16: 31 | F16: 0.9688 | G16: 1611.88 | H16: 1.22 | I16: 1422.77 | J16: 1.08
B17: Totals / Averages: | C17: 880 | D17: 258 | E17: 245 | F17: 0.9496 | G17: 1322.77 | H17: 1.5 | I17: 1122.67 | J17: 1.27

Sheet Sales Comps
C3: Sales Comps
I4: Transaction Details
C5: Property | D5: Address | E5: Distance to Subject (mi) | F5: Built/ Renovated | G5: Units | I5: Date | J5: Price | K5: Per Unit
C6: Lakewood Oaks | D6: 3534 Smithfield Rd | E6: 8.5 | F6: 1974 | G6: 138 | I6: 45323 | J6: 13370000 | K6: =+ROUND(J6/G6,-3) -> 97000
C7: Oasis Club | D7: 5800 University Blvd W | E7: 7.5 | F7: 1972/2000 | G7: 242 | I7: 45323 | J7: 26030000 | K7: =+ROUND(J7/G7,-3) -> 108000
C8: Magnolia Point | D8: 7507 Beach Blvd | E8: 6.37 | F8: 1973/1980 | G8: 227 | I8: 45323 | J8: 25830000 | K8: =+ROUND(J8/G8,-3) -> 114000
C9: Oakview Landing | D9: 7350 Blanding Blvd | E9: 13.95 | F9: 1974/2021 | G9: 216 | I9: 45658 | J9: 20300000 | K9: =+ROUND(J9/G9,-3) -> 94000
C10: Renaissance Strawberry Creek | D10: 7557 Arlington Expwy | E10: 3.76 | F10: 1969/2017 | G10: 195 | I10: 45778 | J10: 23358000 | K10: =+ROUND(J10/G10,-3) -> 120000
C11: Edenfield Shores | D11: 5885 Edenfield Rd | E11: 0.27 | F11: 1975/2017 | G11: 332 | I11: 45870 | J11: 37000000 | K11: =+ROUND(J11/G11,-3) -> 111000
C13: Total / Wtd Average | G13: =+SUM(G6:G12) -> 1350 | J13: =+SUM(J6:J12) -> 145888000 | K13: =+ROUND(J13/G13,-3) -> 108000
C15: SUBJECT* | D15: 5501 University Club Blvd N | E15: 0 | F15: 1975/2024 | G15: 258 | J15: =+'Sources & Uses'!C11 -> 14970000 | K15: =+ROUND(J15/G15,-3) -> 58000
C17: *Value based on proforma NOI using a market 6.2% cap rate

Sheet Rent Comps
C3: Rent Comps
C5: Property | D5: Address | E5: Distance to Subject (mi) | F5: Built/ Renovated | G5: Units | H5: Avg Unit Size (SF) | I5: Market Rent | J5: Market Rent PSF | K5: In-Place Rent | L5: In-Place Rent PSF | M5: Current Occupancy
C6: Townsend | D6: 3501 Townsend Blvd | E6: 2.03 | F6: 1970 | G6: 396 | H6: 1000 | I6: 1094 | J6: 1.09 | K6: 1094 | L6: 1.09 | M6: 0.91
C7: The Square at 59 Caroline | D7: 5959 Fort Caroline Rd | E7: =4791/5280 -> 0.90738636 | F7: 1972 | G7: 356 | H7: 960 | I7: 1107 | J7: 1.15 | K7: 1022 | L7: 1.06 | M7: 0.92
C8: Edenfield Shores | D8: 5885 Edenfield Rd | E8: 0.27 | F8: 1975/2017 | G8: 332 | H8: 983 | I8: 1233 | J8: 1.25 | K8: 1233 | L8: 1.25 | M8: 0.79
C9: Casa Bella | D9: 5791 University Club Blvd N | E9: =669/5280 -> 0.12670455 | F9: 1986 | G9: 168 | H9: 893 | I9: 1048 | J9: 1.17 | K9: 1048 | L9: 1.17 | M9: 0.99
C11: Total / Wtd Average | G11: =+SUM(G6:G10) -> 1252 | H11: =+SUMPRODUCT($G$6:$G$10,H$6:H$10)/$G11 -> 969.76038 | I11: =+SUMPRODUCT($G$6:$G$10,I$6:I$10)/$G11 -> 1128.3834 | J11: =+SUMPRODUCT($G$6:$G$10,J$6:J$10)/$G11 -> 1.1602236 | K11: =+SUMPRODUCT($G$6:$G$10,K$6:K$10)/$G11 -> 1104.2141 | L11: =+SUMPRODUCT($G$6:$G$10,L$6:L$10)/$G11 -> 1.1346326 | M11: =+SUMPRODUCT($G$6:$G$10,M$6:M$10)/$G11 -> 0.89175719
C13: SUBJECT | D13: 5501 University Club Blvd N | E13: 0 | F13: 1975/2024 | G13: 258 | H13: 880 | I13: 1323 | J13: 1.5 | K13: 1123 | L13: 1.27 | M13: 0.95

Sheet TTM Nov-25
B1: Income Statement - 12 Month
B2: Exported On: 12/10/2025 03:27 PM
B4: Atrium Management Company
B5: Properties: Oasis at San Marco - 4800 Atlantic Blvd Jacksonville, FL 32207
B6: Fund Type: All
B7: Period Range: Dec 2024 to Nov 2025 (Trailing 12 Months)
B8: Accounting Basis: Accrual
B9: GL Account Map: None - use master chart of accounts
B10: Level of Detail: Detail View
B11: Include Zero Balance GL Accounts: No
B13: Account Name | C13: Dec 2024 | D13: Jan 2025 | E13: Feb 2025 | F13: Mar 2025 | G13: Apr 2025 | H13: May 2025 | I13: Jun 2025 | J13: Jul 2025 | K13: Aug 2025 | L13: Sep 2025 | M13: Oct 2025 | N13: Nov 2025 | O13: Total | Q13: T1 | R13: T2 | S13: T3 | T13: T6 | U13: T12
B14: Operating Income & Expense
B15: Income
B16: Rental Income
A17: 1 | B17: Gross Potential Rent | C17: 144721.55 | D17: 146896.53 | E17: 147357.5 | F17: 147078 | G17: 147078 | H17: 147078 | I17: 154421 | J17: 155067.12 | K17: 142265.39 | L17: 136185.3 | M17: 139780.78 | N17: 143362 | O17: 1751291.2 | Q17: =+N17*12 -> 1720344 | R17: =+SUM(M17:N17)*6 -> 1698856.7 | S17: =+SUM(L17:N17)*4 -> 1677312.3 | T17: =+SUM(I17:N17)*2 -> 1742163.2 | U17: =+SUM(C17:N17) -> 1751291.2
A18: 1 | B18: Loss/Gain to Market | C18: -7553.26 | D18: -9302.88 | E18: -7219.92 | F18: -11409.39 | G18: -7196.23 | H18: -8458.77 | I18: -15965.57 | J18: -3498.54 | K18: -1535.7 | L18: 856.42 | M18: -158.9 | N18: -1700.4 | O18: -73143.14 | Q18: =+N18*12 -> -20404.8 | R18: =+SUM(M18:N18)*6 -> -11155.8 | S18: =+SUM(L18:N18)*4 -> -4011.52 | T18: =+SUM(I18:N18)*2 -> -44005.38 | U18: =+SUM(C18:N18) -> -73143.14
A19: 1 | B19: Concessions | C19: -100 | D19: -700 | E19: -1200 | F19: -320 | G19: -200 | H19: -1849 | I19: -1659 | J19: -1409 | K19: -5855 | L19: -17016.5 | M19: -19220.5 | N19: -11589.99 | O19: -61118.99 | Q19: =+N19*12 -> -139079.88 | R19: =+SUM(M19:N19)*6 -> -184862.94 | S19: =+SUM(L19:N19)*4 -> -191307.96 | T19: =+SUM(I19:N19)*2 -> -113499.98 | U19: =+SUM(C19:N19) -> -61118.99
A20: 3 | B20: Concessions - Recurring | C20: 0 | D20: 0 | E20: 0 | F20: 0 | G20: 0 | H20: 0 | I20: -200 | J20: -200 | K20: -200 | L20: -200 | M20: -200 | N20: -100 | O20: -1100 | Q20: =+N20*12 -> -1200 | R20: =+SUM(M20:N20)*6 -> -1800 | S20: =+SUM(L20:N20)*4 -> -2000 | T20: =+SUM(I20:N20)*2 -> -2200 | U20: =+SUM(C20:N20) -> -1100
A21: 3 | B21: Concessions - Employee Unit | C21: 0 | D21: 0 | E21: 0 | F21: 0 | G21: 0 | H21: 0 | I21: 0 | J21: 0 | K21: 0 | L21: -210 | M21: -210 | N21: -210 | O21: -630 | Q21: =+N21*12 -> -2520 | R21: =+SUM(M21:N21)*6 -> -2520 | S21: =+SUM(L21:N21)*4 -> -2520 | T21: =+SUM(I21:N21)*2 -> -1260 | U21: =+SUM(C21:N21) -> -630
A22: 2 | B22: Vacancy | C22: -29499.93 | D22: -25913.5 | E22: -24560.58 | F22: -19223.61 | G22: -25112.77 | H22: -26229.23 | I22: -29901.46 | J22: -37429.9 | K22: -34280.94 | L22: -17406.1 | M22: -5336.53 | N22: -8718.07 | O22: -283612.62 | Q22: =+N22*12 -> -104616.84 | R22: =+SUM(M22:N22)*6 -> -84327.6 | S22: =+SUM(L22:N22)*4 -> -125842.8 | T22: =+SUM(I22:N22)*2 -> -266146 | U22: =+SUM(C22:N22) -> -283612.62
A23: 4 | B23: Bad Debt - Contra | C23: -400 | D23: -22098.2 | E23: -1006 | F23: -20742.65 | G23: -26539.02 | H23: 0 | I23: 0 | J23: -3968 | K23: 0 | L23: -16661.19 | M23: -11674.07 | N23: 0 | O23: -103089.13 | Q23: =+N23*12 -> 0 | R23: =+SUM(M23:N23)*6 -> -70044.42 | S23: =+SUM(L23:N23)*4 -> -113341.04 | T23: =+SUM(I23:N23)*2 -> -64606.52 | U23: =+SUM(C23:N23) -> -103089.13
B24: Total Rental Income | C24: 107168.36 | D24: 88881.95 | E24: 113371 | F24: 95382.35 | G24: 88029.98 | H24: 110541 | I24: 106694.97 | J24: 108561.68 | K24: 100393.75 | L24: 85547.93 | M24: 102980.78 | N24: 121043.54 | O24: 1228597.3 | Q24: =+N24*12 -> 1452522.5 | R24: =+SUM(M24:N24)*6 -> 1344145.9 | S24: =+SUM(L24:N24)*4 -> 1238289 | T24: =+SUM(I24:N24)*2 -> 1250445.3 | U24: =+SUM(C24:N24) -> 1228597.3
B25: Other Income | Q25: =+N25*12 -> 0 | R25: =+SUM(M25:N25)*6 -> 0 | S25: =+SUM(L25:N25)*4 -> 0 | T25: =+SUM(I25:N25)*2 -> 0 | U25: =+SUM(C25:N25) -> 0
A26: 7 | B26: Lease Lock | C26: 1274 | D26: 1218 | E26: 0 | F26: 0 | G26: 0 | H26: 0 | I26: 0 | J26: 0 | K26: 0 | L26: 0 | M26: 0 | N26: 0 | O26: 2492 | Q26: =+N26*12 -> 0 | R26: =+SUM(M26:N26)*6 -> 0 | S26: =+SUM(L26:N26)*4 -> 0 | T26: =+SUM(I26:N26)*2 -> 0 | U26: =+SUM(C26:N26) -> 2492
A27: 7 | B27: NSF Fees Collected | C27: 0 | D27: 165 | E27: 275 | F27: 385 | G27: 55 | H27: 55 | I27: 0 | J27: 150 | K27: 0 | L27: -75 | M27: -75 | N27: 80 | O27: 1015 | Q27: =+N27*12 -> 960 | R27: =+SUM(M27:N27)*6 -> 30 | S27: =+SUM(L27:N27)*4 -> -280 | T27: =+SUM(I27:N27)*2 -> 160 | U27: =+SUM(C27:N27) -> 1015
A28: 7 | B28: Late Fee | C28: 2414.8 | D28: 2981 | E28: 3381.7 | F28: 3761.8 | G28: 3081.7 | H28: 3111.8 | I28: 4980.4 | J28: 250 | K28: 2429.16 | L28: 1850.19 | M28: 2271.56 | N28: 2299.95 | O28: 32814.06 | Q28: =+N28*12 -> 27599.4 | R28: =+SUM(M28:N28)*6 -> 27429.06 | S28: =+SUM(L28:N28)*4 -> 25686.8 | T28: =+SUM(I28:N28)*2 -> 28162.52 | U28: =+SUM(C28:N28) -> 32814.06
A29: 6 | B29: Utility Income | C29: 0 | D29: 0 | E29: 0 | F29: 0 | G29: 0 | H29: 0 | I29: 0 | J29: 0 | K29: 9.03 | L29: -9.03 | M29: 0 | N29: 0 | O29: 0 | Q29: =+N29*12 -> 0 | R29: =+SUM(M29:N29)*6 -> 0 | S29: =+SUM(L29:N29)*4 -> -36.12 | T29: =+SUM(I29:N29)*2 -> 0 | U29: =+SUM(C29:N29) -> 0
A30: 6 | B30: Electricity Income | C30: 95 | D30: 95 | E30: 95 | F30: 95 | G30: 95 | H30: 95 | I30: 0 | J30: 0 | K30: 0 | L30: 0 | M30: 0 | N30: 0 | O30: 570 | Q30: =+N30*12 -> 0 | R30: =+SUM(M30:N30)*6 -> 0 | S30: =+SUM(L30:N30)*4 -> 0 | T30: =+SUM(I30:N30)*2 -> 0 | U30: =+SUM(C30:N30) -> 570
A31: 6 | B31: Utility Reimbursements | C31: 6794 | D31: 7216 | E31: 7099 | F31: 7482 | G31: 7122 | H31: 7077 | I31: 6398.33 | J31: 6302.77 | K31: 5980.56 | L31: 7009.03 | M31: 7576.96 | N31: 7558.96 | O31: 83616.61 | Q31: =+N31*12 -> 90707.52 | R31: =+SUM(M31:N31)*6 -> 90815.52 | S31: =+SUM(L31:N31)*4 -> 88579.8 | T31: =+SUM(I31:N31)*2 -> 81653.22 | U31: =+SUM(C31:N31) -> 83616.61
A32: 7 | B32: Resident Liability & Contents Coverage | C32: 588 | D32: 661.5 | E32: 735 | F32: 756 | G32: 766.5 | H32: 724.5 | I32: -15.5 | J32: 258.5 | K32: 161 | L32: -107.92 | M32: -58.08 | N32: 263.22 | O32: 4732.72 | Q32: =+N32*12 -> 3158.64 | R32: =+SUM(M32:N32)*6 -> 1230.84 | S32: =+SUM(L32:N32)*4 -> 388.88 | T32: =+SUM(I32:N32)*2 -> 1002.44 | U32: =+SUM(C32:N32) -> 4732.72
A33: 7 | B33: 1st month - Resident Liability & Contents Coverage | C33: 0 | D33: 0 | E33: 0 | F33: 0 | G33: 0 | H33: 0 | I33: 26.52 | J33: -13.52 | K33: -13 | L33: -13 | M33: 0 | N33: 0 | O33: -13 | Q33: =+N33*12 -> 0 | R33: =+SUM(M33:N33)*6 -> 0 | S33: =+SUM(L33:N33)*4 -> -52 | T33: =+SUM(I33:N33)*2 -> -26 | U33: =+SUM(C33:N33) -> -13
A34: 7 | B34: AppFolio Insurance Admin Fee | C34: -382.5 | D34: -428 | E34: -505 | F34: -563 | G34: -581.5 | H34: -1366 | I34: 0 | J34: 0 | K34: 0 | L34: 0 | M34: 0 | N34: 0 | O34: -3826 | Q34: =+N34*12 -> 0 | R34: =+SUM(M34:N34)*6 -> 0 | S34: =+SUM(L34:N34)*4 -> 0 | T34: =+SUM(I34:N34)*2 -> 0 | U34: =+SUM(C34:N34) -> -3826
A35: 7 | B35: Pet Fee - Non Refundable | C35: 0 | D35: 0 | E35: 0 | F35: 0 | G35: 300 | H35: 0 | I35: 0 | J35: 0 | K35: 0 | L35: 0 | M35: 0 | N35: 0 | O35: 300 | Q35: =+N35*12 -> 0 | R35: =+SUM(M35:N35)*6 -> 0 | S35: =+SUM(L35:N35)*4 -> 0 | T35: =+SUM(I35:N35)*2 -> 0 | U35: =+SUM(C35:N35) -> 300
A36: 7 | B36: Bad Debt Recovery | C36: 0 | D36: 0 | E36: 0 | F36: 0 | G36: 162.71 | H36: 14.55 | I36: 0 | J36: 0 | K36: 0 | L36: 0 | M36: 0 | N36: 0 | O36: 177.26 | Q36: =+N36*12 -> 0 | R36: =+SUM(M36:N36)*6 -> 0 | S36: =+SUM(L36:N36)*4 -> 0 | T36: =+SUM(I36:N36)*2 -> 0 | U36: =+SUM(C36:N36) -> 177.26
A37: 7 | B37: Pet Application Fee | C37: 0 | D37: 0 | E37: 0 | F37: 0 | G37: 0 | H37: 222 | I37: 0 | J37: 0 | K37: 0 | L37: 0 | M37: 0 | N37: 0 | O37: 222 | Q37: =+N37*12 -> 0 | R37: =+SUM(M37:N37)*6 -> 0 | S37: =+SUM(L37:N37)*4 -> 0 | T37: =+SUM(I37:N37)*2 -> 0 | U37: =+SUM(C37:N37) -> 222
... A58: 7 | B58: Bad Debt - Contra Other Income | C58: 0 | D58: 0 | E58: 0 | F58: 0 | G58: 0 | H58: 0 | I58: 0 | J58: -727 | K58: 0 | L58: -2964 | M58: -3628 | N58: -6 | O58: -7325 | Q58: =+N58*12 -> -72 | R58: =+SUM(M58:N58)*6 -> -21804 | S58: =+SUM(L58:N58)*4 -> -26392 | T58: =+SUM(I58:N58)*2 -> -14650 | U58: =+SUM(C58:N58) -> -7325
B59: Total Other Income | C59: 17493.8 | D59: 19106.8 | E59: 15144.7 | F59: 21278.91 | G59: 27756.41 | H59: 18138.44 | I59: 16538.85 | J59: 11410.24 | K59: 14422.98 | L59: 13112.8 | M59: 13988.72 | N59: 17456.19 | O59: 205848.84 | Q59: =+N59*12 -> 209474.28 | R59: =+SUM(M59:N59)*6 -> 188669.46 | S59: =+SUM(L59:N59)*4 -> 178230.84 | T59: =+SUM(I59:N59)*2 -> 173859.56 | U59: =+SUM(C59:N59) -> 205848.84
B60: Total Operating Income | C60: 124662.16 | D60: 107988.75 | E60: 128515.7 | F60: 116661.26 | G60: 115786.39 | H60: 128679.44 | I60: 123233.82 | J60: 119971.92 | K60: 114816.73 | L60: 98660.73 | M60: 116969.5 | N60: 138499.73 | O60: 1434446.1 | Q60: =+N60*12 -> 1661996.8 | R60: =+SUM(M60:N60)*6 -> 1532815.4 | S60: =+SUM(L60:N60)*4 -> 1416519.8 | T60: =+SUM(I60:N60)*2 -> 1424304.9 | U60: =+SUM(C60:N60) -> 1434446.1
B61: Expense | Q61: =+N61*12 -> 0 | R61: =+SUM(M61:N61)*6 -> 0 | S61: =+SUM(L61:N61)*4 -> 0 | T61: =+SUM(I61:N61)*2 -> 0 | U61: =+SUM(C61:N61) -> 0
B62: Management Fee Expenses | Q62: =+N62*12 -> 0 | R62: =+SUM(M62:N62)*6 -> 0 | S62: =+SUM(L62:N62)*4 -> 0 | T62: =+SUM(I62:N62)*2 -> 0 | U62: =+SUM(C62:N62) -> 0
...

Sheet TTM Oct-25
B1: Income Statement - 12 Month
B2: Exported On: 11/03/2025 05:33 PM
B4: Atrium Management Company
B5: Properties: Active
B6: Fund Type: All
B7: Period Range: Nov 2024 to Oct 2025
B8: Accounting Basis: Accrual
B9: GL Account Map: None - use master chart of accounts
B10: Level of Detail: Detail View
B11: Include Zero Balance GL Accounts: No
B13: Account Name | C13: Nov 2024 | D13: Dec 2024 | E13: Jan 2025 | F13: Feb 2025 | G13: Mar 2025 | H13: Apr 2025 | I13: May 2025 | J13: Jun 2025 | K13: Jul 2025 | L13: Aug 2025 | M13: Sep 2025 | N13: Oct 2025 | O13: Total | Q13: T1 | R13: T2 | S13: T3 | T13: T6 | U13: T12
B14: Operating Income & Expense
B15: Income
B16: Rental Income
A17: 1 | B17: Rent | C17: 0 | D17: 0 | E17: 0 | F17: 0 | G17: 0 | H17: 0 | I17: 0 | J17: 0 | K17: 0 | L17: 0 | M17: 0 | N17: 132432.35 | O17: 132432.35 | Q17: =+N17*12 -> 1589188.2 | R17: =+SUM(M17:N17)*6 -> 794594.1 | S17: =+SUM(L17:N17)*4 -> 529729.4 | T17: =+SUM(I17:N17)*2 -> 264864.7 | U17: =+SUM(C17:N17) -> 132432.35
A18: 1 | B18: Section-8 Rent | C18: 0 | D18: 0 | E18: 0 | F18: 0 | G18: 0 | H18: 0 | I18: 0 | J18: 0 | K18: 0 | L18: 0 | M18: 0 | N18: 1853 | O18: 1853 | Q18: =+N18*12 -> 22236 | R18: =+SUM(M18:N18)*6 -> 11118 | S18: =+SUM(L18:N18)*4 -> 7412 | T18: =+SUM(I18:N18)*2 -> 3706 | U18: =+SUM(C18:N18) -> 1853
A19: 1 | B19: Gross Potential Rent | C19: 144311 | D19: 144721.55 | E19: 146896.53 | F19: 147357.5 | G19: 147078 | H19: 147078 | I19: 147078 | J19: 154421 | K19: 155067.12 | L19: 142265.39 | M19: 136185.3 | N19: 0 | O19: 1612459.4 | Q19: =+N19*12 -> 0 | R19: =+SUM(M19:N19)*6 -> 817111.8 | S19: =+SUM(L19:N19)*4 -> 1113802.8 | T19: =+SUM(I19:N19)*2 -> 1470033.6 | U19: =+SUM(C19:N19) -> 1612459.4
A20: 1 | B20: Loss/Gain to Market | C20: -5871.9 | D20: -7553.26 | E20: -9302.88 | F20: -7219.92 | G20: -11409.39 | H20: -7196.23 | I20: -8458.77 | J20: -15965.57 | K20: -3498.54 | L20: -1535.7 | M20: 856.42 | N20: 0 | O20: -77155.74 | Q20: =+N20*12 -> 0 | R20: =+SUM(M20:N20)*6 -> 5138.52 | S20: =+SUM(L20:N20)*4 -> -2717.12 | T20: =+SUM(I20:N20)*2 -> -57204.32 | U20: =+SUM(C20:N20) -> -77155.74
A21: 3 | B21: Concessions | C21: -800 | D21: -100 | E21: -700 | F21: -1200 | G21: -320 | H21: -200 | I21: -1849 | J21: -1659 | K21: -1409 | L21: -5855 | M21: -17016.5 | N21: -19220.5 | O21: -50329 | Q21: =+N21*12 -> -230646 | R21: =+SUM(M21:N21)*6 -> -217422 | S21: =+SUM(L21:N21)*4 -> -168368 | T21: =+SUM(I21:N21)*2 -> -94018 | U21: =+SUM(C21:N21) -> -50329
A22: 3 | B22: Concessions - Recurring | C22: 0 | D22: 0 | E22: 0 | F22: 0 | G22: 0 | H22: 0 | I22: 0 | J22: -200 | K22: -200 | L22: -200 | M22: -200 | N22: -200 | O22: -1000 | Q22: =+N22*12 -> -2400 | R22: =+SUM(M22:N22)*6 -> -2400 | S22: =+SUM(L22:N22)*4 -> -2400 | T22: =+SUM(I22:N22)*2 -> -2000 | U22: =+SUM(C22:N22) -> -1000
A23: 3 | B23: Concessions - Employee Unit | C23: 0 | D23: 0 | E23: 0 | F23: 0 | G23: 0 | H23: 0 | I23: 0 | J23: 0 | K23: 0 | L23: 0 | M23: -210 | N23: -210 | O23: -420 | Q23: =+N23*12 -> -2520 | R23: =+SUM(M23:N23)*6 -> -2520 | S23: =+SUM(L23:N23)*4 -> -1680 | T23: =+SUM(I23:N23)*2 -> -840 | U23: =+SUM(C23:N23) -> -420
A24: 2 | B24: Vacancy | C24: -33216.77 | D24: -29499.93 | E24: -25913.5 | F24: -24560.58 | G24: -19223.61 | H24: -25112.77 | I24: -26229.23 | J24: -29901.46 | K24: -37429.9 | L24: -34280.94 | M24: -17406.1 | N24: 0 | O24: -302774.79 | Q24: =+N24*12 -> 0 | R24: =+SUM(M24:N24)*6 -> -104436.6 | S24: =+SUM(L24:N24)*4 -> -206748.16 | T24: =+SUM(I24:N24)*2 -> -290495.26 | U24: =+SUM(C24:N24) -> -302774.79
A25: 4 | B25: Bad Debt - Contra | C25: -41256.8 | D25: -400 | E25: -22098.2 | F25: -1006 | G25: -20742.65 | H25: -26539.02 | I25: 0 | J25: 0 | K25: -3968 | L25: 0 | M25: -16661.19 | N25: 0 | O25: -132671.86 | Q25: =+N25*12 -> 0 | R25: =+SUM(M25:N25)*6 -> -99967.14 | S25: =+SUM(L25:N25)*4 -> -66644.76 | T25: =+SUM(I25:N25)*2 -> -41258.38 | U25: =+SUM(C25:N25) -> -132671.86
B26: Total Rental Income | C26: 63165.53 | D26: 107168.36 | E26: 88881.95 | F26: 113371 | G26: 95382.35 | H26: 88029.98 | I26: 110541 | J26: 106694.97 | K26: 108561.68 | L26: 100393.75 | M26: 85547.93 | N26: 114654.85 | O26: 1182393.4 | Q26: =+N26*12 -> 1375858.2 | R26: =+SUM(M26:N26)*6 -> 1201216.7 | S26: =+SUM(L26:N26)*4 -> 1202386.1 | T26: =+SUM(I26:N26)*2 -> 1252788.4 | U26: =+SUM(C26:N26) -> 1182393.4
B27: Other Income | Q27: =+N27*12 -> 0 | R27: =+SUM(M27:N27)*6 -> 0 | S27: =+SUM(L27:N27)*4 -> 0 | T27: =+SUM(I27:N27)*2 -> 0 | U27: =+SUM(C27:N27) -> 0
A28: 7 | B28: Lease Lock | C28: 1330 | D28: 1274 | E28: 1218 | F28: 0 | G28: 0 | H28: 0 | I28: 0 | J28: 0 | K28: 0 | L28: 0 | M28: 0 | N28: 0 | O28: 3822 | Q28: =+N28*12 -> 0 | R28: =+SUM(M28:N28)*6 -> 0 | S28: =+SUM(L28:N28)*4 -> 0 | T28: =+SUM(I28:N28)*2 -> 0 | U28: =+SUM(C28:N28) -> 3822
A29: 7 | B29: NSF Fees Collected | C29: 0 | D29: 0 | E29: 165 | F29: 275 | G29: 385 | H29: 55 | I29: 55 | J29: 0 | K29: 150 | L29: 0 | M29: -75 | N29: -75 | O29: 935 | Q29: =+N29*12 -> -900 | R29: =+SUM(M29:N29)*6 -> -900 | S29: =+SUM(L29:N29)*4 -> -600 | T29: =+SUM(I29:N29)*2 -> 110 | U29: =+SUM(C29:N29) -> 935
A30: 7 | B30: Late Fee | C30: 2246.5 | D30: 2414.8 | E30: 2981 | F30: 3381.7 | G30: 3761.8 | H30: 3081.7 | I30: 3111.8 | J30: 4980.4 | K30: 250 | L30: 2429.16 | M30: 1850.19 | N30: 2271.56 | O30: 32760.61 | Q30: =+N30*12 -> 27258.72 | R30: =+SUM(M30:N30)*6 -> 24730.5 | S30: =+SUM(L30:N30)*4 -> 26203.64 | T30: =+SUM(I30:N30)*2 -> 29786.22 | U30: =+SUM(C30:N30) -> 32760.61
A31: 6 | B31: Utility Income | C31: 0 | D31: 0 | E31: 0 | F31: 0 | G31: 0 | H31: 0 | I31: 0 | J31: 0 | K31: 0 | L31: 9.03 | M31: -9.03 | N31: 0 | O31: 0 | Q31: =+N31*12 -> 0 | R31: =+SUM(M31:N31)*6 -> -54.18 | S31: =+SUM(L31:N31)*4 -> 0 | T31: =+SUM(I31:N31)*2 -> 0 | U31: =+SUM(C31:N31) -> 0
A32: 6 | B32: Electricity Income | C32: 0 | D32: 95 | E32: 95 | F32: 95 | G32: 95 | H32: 95 | I32: 95 | J32: 0 | K32: 0 | L32: 0 | M32: 0 | N32: 0 | O32: 570 | Q32: =+N32*12 -> 0 | R32: =+SUM(M32:N32)*6 -> 0 | S32: =+SUM(L32:N32)*4 -> 0 | T32: =+SUM(I32:N32)*2 -> 190 | U32: =+SUM(C32:N32) -> 570
A33: 6 | B33: Utility Reimbursements | C33: 6459.53 | D33: 6794 | E33: 7216 | F33: 7099 | G33: 7482 | H33: 7122 | I33: 7077 | J33: 6398.33 | K33: 6302.77 | L33: 5980.56 | M33: 7009.03 | N33: 7576.96 | O33: 82517.18 | Q33: =+N33*12 -> 90923.52 | R33: =+SUM(M33:N33)*6 -> 87515.94 | S33: =+SUM(L33:N33)*4 -> 82266.2 | T33: =+SUM(I33:N33)*2 -> 80689.3 | U33: =+SUM(C33:N33) -> 82517.18
A34: 7 | B34: Resident Liability & Contents Coverage | C34: 493.5 | D34: 588 | E34: 661.5 | F34: 735 | G34: 756 | H34: 766.5 | I34: 724.5 | J34: -15.5 | K34: 258.5 | L34: 161 | M34: -107.92 | N34: 52.92 | O34: 5074 | Q34: =+N34*12 -> 635.04 | R34: =+SUM(M34:N34)*6 -> -330 | S34: =+SUM(L34:N34)*4 -> 424 | T34: =+SUM(I34:N34)*2 -> 2147 | U34: =+SUM(C34:N34) -> 5074
A35: 7 | B35: 1st month - Resident Liability & Contents Coverage | C35: 0 | D35: 0 | E35: 0 | F35: 0 | G35: 0 | H35: 0 | I35: 0 | J35: 26.52 | K35: -13.52 | L35: -13 | M35: -13 | N35: 0 | O35: -13 | Q35: =+N35*12 -> 0 | R35: =+SUM(M35:N35)*6 -> -78 | S35: =+SUM(L35:N35)*4 -> -104 | T35: =+SUM(I35:N35)*2 -> -26 | U35: =+SUM(C35:N35) -> -13
A36: 7 | B36: AppFolio Insurance Admin Fee | C36: -226.5 | D36: -382.5 | E36: -428 | F36: -505 | G36: -563 | H36: -581.5 | I36: -1366 | J36: 0 | K36: 0 | L36: 0 | M36: 0 | N36: 0 | O36: -4052.5 | Q36: =+N36*12 -> 0 | R36: =+SUM(M36:N36)*6 -> 0 | S36: =+SUM(L36:N36)*4 -> 0 | T36: =+SUM(I36:N36)*2 -> -2732 | U36: =+SUM(C36:N36) -> -4052.5
A37: 7 | B37: Pet Fee - Non Refundable | C37: 650 | D37: 0 | E37: 0 | F37: 0 | G37: 0 | H37: 300 | I37: 0 | J37: 0 | K37: 0 | L37: 0 | M37: 0 | N37: 0 | O37: 950 | Q37: =+N37*12 -> 0 | R37: =+SUM(M37:N37)*6 -> 0 | S37: =+SUM(L37:N37)*4 -> 0 | T37: =+SUM(I37:N37)*2 -> 0 | U37: =+SUM(C37:N37) -> 950
A38: 7 | B38: Bad Debt Recovery | C38: 871.84 | D38: 0 | E38: 0 | F38: 0 | G38: 0 | H38: 162.71 | I38: 14.55 | J38: 0 | K38: 0 | L38: 0 | M38: 0 | N38: 0 | O38: 1049.1 | Q38: =+N38*12 -> 0 | R38: =+SUM(M38:N38)*6 -> 0 | S38: =+SUM(L38:N38)*4 -> 0 | T38: =+SUM(I38:N38)*2 -> 29.1 | U38: =+SUM(C38:N38) -> 1049.1
A39: 7 | B39: Pet Application Fee | C39: 0 | D39: 0 | E39: 0 | F39: 0 | G39: 0 | H39: 0 | I39: 222 | J39: 0 | K39: 0 | L39: 0 | M39: 0 | N39: 0 | O39: 222 | Q39: =+N39*12 -> 0 | R39: =+SUM(M39:N39)*6 -> 0 | S39: =+SUM(L39:N39)*4 -> 0 | T39: =+SUM(I39:N39)*2 -> 444 | U39: =+SUM(C39:N39) -> 222
... A59: 7 | B59: Bad Debt - Contra Other Income | C59: 0 | D59: 0 | E59: 0 | F59: 0 | G59: 0 | H59: 0 | I59: 0 | J59: 0 | K59: -727 | L59: 0 | M59: -2964 | N59: 0 | O59: -3691 | Q59: =+N59*12 -> 0 | R59: =+SUM(M59:N59)*6 -> -17784 | S59: =+SUM(L59:N59)*4 -> -11856 | T59: =+SUM(I59:N59)*2 -> -7382 | U59: =+SUM(C59:N59) -> -3691
B60: Total Other Income | C60: 21565.76 | D60: 17493.8 | E60: 19106.8 | F60: 15144.7 | G60: 21278.91 | H60: 27756.41 | I60: 18138.44 | J60: 16538.85 | K60: 11410.24 | L60: 14422.98 | M60: 13112.8 | N60: 17277.72 | O60: 213247.41 | Q60: =+N60*12 -> 207332.64 | R60: =+SUM(M60:N60)*6 -> 182343.12 | S60: =+SUM(L60:N60)*4 -> 179254 | T60: =+SUM(I60:N60)*2 -> 181802.06 | U60: =+SUM(C60:N60) -> 213247.41
B61: Total Operating Income | C61: 84731.29 | D61: 124662.16 | E61: 107988.75 | F61: 128515.7 | G61: 116661.26 | H61: 115786.39 | I61: 128679.44 | J61: 123233.82 | K61: 119971.92 | L61: 114816.73 | M61: 98660.73 | N61: 131932.57 | O61: 1395640.8 | Q61: =+N61*12 -> 1583190.8 | R61: =+SUM(M61:N61)*6 -> 1383559.8 | S61: =+SUM(L61:N61)*4 -> 1381640.1 | T61: =+SUM(I61:N61)*2 -> 1434590.4 | U61: =+SUM(C61:N61) -> 1395640.8
...

Sheet IS 2024
B1: CLUB AT CHARTER POINTE
B2: Twelve Month Trailing Income Statement
B3: 45657
F4: 45322 | G4: 45351 | H4: 45382 | I4: 45412 | J4: 45443 | K4: 45473 | L4: 45504 | M4: 45535 | N4: 45565 | O4: 45596 | P4: 45626 | Q4: 45657 | R4: Total
F5: Actual | G5: Actual | H5: Actual | I5: Actual | J5: Actual | K5: Actual | L5: Actual | M5: Actual | N5: Actual | O5: Actual | P5: Actual | Q5: Actual | T5: T1 | U5: T3 | V5: T12
B6: Income:
B7: Rental Income
B8: 40000 | C8: Gross Potential
B9: 40091 | C9: Income for Renovated Units
B10: 41000 | C10: Rent Below Unit Schedules
B11: 41010 | C11: Rent Exceeding Unit Schedule
A12: 1 | B12: Net Effective Rent
B14: Vacancy , Losses and Concessions
A15: 7 | B15: 40020 | C15: Corporate Suite Income
A16: 7 | B16: 40025 | C16: Retail Income
A17: 7 | B17: 40027 | C17: CAM Income
A18: 2 | B18: 41020 | C18: Vacancies
A19: 5 | B19: 41030 | C19: Models
A20: 5 | B20: 41040 | C20: Rent Due to Down Units
A21: 3 | B21: 41050 | C21: Employee Concessions
A22: 3 | B22: 41070 | C22: Courtesy Officer Concession
A23: 3 | B23: 41080 | C23: New One Time Concessions
A24: 3 | B24: 41090 | C24: Concession Prorated Over Lease
A25: 3 | B25: 41091 | C25: Concession for Renovated Unit
A26: 4 | B26: 41095 | C26: Bad Debt Expense
... A28: 4 | B28: 41097 | C28: COVID-19 Bad Debt Expense
B29: Total Vacancy , Losses and Concessions
B31: Total Rental Income
B33: Other Income
A34: 7 | B34: 42000 | C34: Carport Income
A35: 7 | B35: 42010 | C35: Carport/Valet Concession
A36: 7 | B36: 42100 | C36: Garage/Reserved Income
A37: 7 | B37: 42150 | C37: Parking Permit Income
A38: 7 | B38: 42200 | C38: Valet Parking Income
A39: 7 | B39: 42500 | C39: Non-Refundable Pet Fees
A40: 7 | B40: 42505 | C40: Pet Monthly Rent
A41: 6 | B41: 42800 | C41: Utility Reimbursement Income
A42: 7 | B42: 42810 | C42: Master Meter Electric Reimbursement
A43: 7 | B43: 42900 | C43: Storage Income
A44: 7 | B44: 42905 | C44: Renters Insurance Income
...

Sheet IS 2023
B1: CLUB AT CHARTER POINTE
B2: Twelve Month Trailing Income Statement
B3: 45291
F4: 44957 | G4: 44985 | H4: 45016 | I4: 45046 | J4: 45077 | K4: 45107 | L4: 45138 | M4: 45169 | N4: 45199 | O4: 45230 | P4: 45260 | Q4: 45291 | R4: Total
F5: Actual | G5: Actual | H5: Actual | I5: Actual | J5: Actual | K5: Actual | L5: Actual | M5: Actual | N5: Actual | O5: Actual | P5: Actual | Q5: Actual | T5: T1 | U5: T3 | V5: T12
B6: Income:
B7: Rental Income
B8: 40000 | C8: Gross Potential
B9: 40091 | C9: Income for Renovated Units
B10: 41000 | C10: Rent Below Unit Schedules
B11: 41010 | C11: Rent Exceeding Unit Schedule
A12: 1 | B12: Net Effective Rent
B14: Vacancy , Losses and Concessions
A15: 7 | B15: 40020 | C15: Corporate Suite Income
A16: 7 | B16: 40025 | C16: Retail Income
A17: 7 | B17: 40027 | C17: CAM Income
A18: 2 | B18: 41020 | C18: Vacancies
A19: 5 | B19: 41030 | C19: Models
A20: 5 | B20: 41040 | C20: Rent Due to Down Units
A21: 3 | B21: 41050 | C21: Employee Concessions
A22: 3 | B22: 41070 | C22: Courtesy Officer Concession
A23: 3 | B23: 41080 | C23: New One Time Concessions
A24: 3 | B24: 41090 | C24: Concession Prorated Over Lease
A25: 3 | B25: 41091 | C25: Concession for Renovated Unit
A26: 4 | B26: 41095 | C26: Bad Debt Expense
... A28: 4 | B28: 41097 | C28: COVID-19 Bad Debt Expense
B29: Total Vacancy , Losses and Concessions
B31: Total Rental Income
B33: Other Income
A34: 7 | B34: 42000 | C34: Carport Income
A35: 7 | B35: 42010 | C35: Carport/Valet Concession
A36: 7 | B36: 42100 | C36: Garage/Reserved Income
A37: 7 | B37: 42150 | C37: Parking Permit Income
A38: 7 | B38: 42200 | C38: Valet Parking Income
A39: 7 | B39: 42500 | C39: Non-Refundable Pet Fees
A40: 7 | B40: 42505 | C40: Pet Monthly Rent
