Workbook
Name xx: #REF!
Name DELME2: #REF!
Name DATA_01: #REF!
Name aq: #REF!
Name _Key2: #REF!
Name wrn.PropertyInformation.: #REF!
Name RentableFeet: #REF!
Name XXX: #REF!
Name wrn.CCC._.OPEX.: #REF!
Name wrn.CF_HISTORY.: #REF!
Name _Key1: #REF!
Name wrn.Historys.: #REF!
Name wrn.Submittal._.Reconciliation._.Schedule.: #REF!
Name wrn.AnnualRentRoll: #REF!
Name wrn.Rent._.Rolls.: #REF!
Name sadddddddd: #REF!
Name hope: #REF!
Name wrn.AnnualRentRoll: #REF!
Name wrn.CF_HISTORY.: #REF!
Name wrn.Rent._.Rolls.: #REF!
Name wrn.PK._.Variance.: #REF!
Name wrn.CCC.: #REF!
Name DELME4: #REF!
Name wrn.TANASBOURNE._.ONLY.: #REF!
Name wrn.Presentation.: #REF!
Name wrn.ExitAndSalesAssumptions.: #REF!
Name wrn.Presentation.: #REF!
Name xx: #REF!
Name wrn.PropertyInformation.: #REF!
Name sadddddddddd: #REF!
Name wrn.Month._.to._.Month.: #REF!
Name wrn.CF_HIS_Rent_Roll.: #REF!
Name saddddd: #REF!
Name wrn.FULL._.COMPARISON.: #REF!
Name wrn.Variance.: #REF!
Name saddddddddddddd: #REF!
Name DELME7: #REF!
Name wrn.Expense._.Detail.: #REF!
Name wrn.Expense._.Detail.: #REF!
Name sadddddddddd: #REF!
Name saddddddddddddd: #REF!
Name wrn.EXPENSE.: #REF!
Name DELME3: #REF!
Name hope: #REF!
Name XXX: #REF!
Name wrn.OperatingAssumtions.: #REF!
Name wrn.AnnualRentRoll: #REF!
Name wrn.OFFICE._.BUDGET.: #REF!
Name DELME7: #REF!
Name wrn.Rent._.Rolls.: #REF!
Name saddd: #REF!
Name wrn.Summary.: #REF!
Name hope: #REF!
Name saddddd: #REF!
Name _Sort: #REF!
Name DELM: #REF!
Name wrn.PRINT._.ALL.: #REF!
Name wrn.AnnualRentRoll: #REF!
Name wrn.AnnualRentRoll.: #REF!
Name DELME4: #REF!

Sheet DO NOT DELETE
A1: CATEGORY | B1: LINE ITEMS | C1: ELIGIBILITY FOR DEPOSITS/DOWN PAYMENTS/PAID INVOICES | D1: LIEN WAIVER FOR CONTRACTS > $10K | E1: NEED PROOF OF PAYMENT IN THE NEXT DRAW?
A2: Interior Renovations | B2: =+'CapEx Borrower Budget'!B16 -> Unit upgrades | C2: 1) 50% of the contract amount for Downpayment/Deposits | D2: Conditional Lien Waiver Submitted | E2: POP
A3: Exterior Renovations | B3: =+'CapEx Borrower Budget'!B17 -> Appliances | C3: 2) Advance for Unpaid Work | D3: Conditional Lien Waiver NOT Submitted | E3: n/a
A4: Deferred Maintenance | B4: =+'CapEx Borrower Budget'!B18 -> Flooring | C4: 3) Paid Invoice/Purchase Order
A5: Immediate Reparis | B5: =+'CapEx Borrower Budget'!B19 -> Fixtures
A6: Construction Management Fees | B6: =+'CapEx Borrower Budget'!B20 -> Cabinets
A7: Contingency | B7: =+'CapEx Borrower Budget'!B21 -> washer/dryer machines
B8: =+'CapEx Borrower Budget'!B22 -> New Units
B9: =+'CapEx Borrower Budget'!B23 -> Down Unit
B10: =+'CapEx Borrower Budget'!B44 -> Landscaping
B11: =+'CapEx Borrower Budget'!B45 -> Leasing office
B12: =+'CapEx Borrower Budget'!B46 -> Fitness center
B13: =+'CapEx Borrower Budget'!B47 -> Monument sign
B14: =+'CapEx Borrower Budget'!B48 -> Pool area
B15: =+'CapEx Borrower Budget'!B49 -> Grilling stations
B16: =+'CapEx Borrower Budget'!B50 -> Dog park
B17: =+'CapEx Borrower Budget'!B51 -> EV chargers
B18: =+'CapEx Borrower Budget'!B52 -> Playground
B19: =+'CapEx Borrower Budget'!B62 -> Roofs (seller credit)
B20: =+'CapEx Borrower Budget'!B63 -> Plumbing
B21: =+'CapEx Borrower Budget'!B64 -> Electrical
B22: =+'CapEx Borrower Budget'!B65 -> HVAC
B23: =+'CapEx Borrower Budget'!B75 -> Install and /or repair fencing and gates to comply with security plan.
B24: =+'CapEx Borrower Budget'!B76 -> Repair damaged pavement consisting of linear cracking, alligator cracking, potholes, and surface raveling throughout the Property.
B25: =+'CapEx Borrower Budget'!B77 -> Install security cameras to comply with security plan.
B26: =+'CapEx Borrower Budget'!B78 -> Repair and replace cracked and broken concrete stair treads.
B27: =+'CapEx Borrower Budget'!B79 -> Repair all trip hazards.
B28: =+'CapEx Borrower Budget'!B80 -> Reconfigure the ramp and access walk to provide a level landing at the leasing office entry door
B29: =+'CapEx Borrower Budget'!B81 -> Reconfigure the ADA accessible parking space to provide unobstructed access to aisle.
B30: =+'CapEx Borrower Budget'!B88 -> Interior Contingency
B31: =+'CapEx Borrower Budget'!B90 -> Def. Maintenance Contingency

Sheet CapEx Summary
B2: BLUE - Manual Input
B3: BLACK - Formula
B5: Capital Improvement Budget Summary
B6: Category | C6: Total Amount | D6: Per Unit
B7: Interior Renovations | C7: =SUM('CapEx Borrower Budget'!E41) -> 751200 | D7: =C7/'CapEx Borrower Budget'!$C$10 -> 5868.75
B8: Exterior Renovations | C8: ='CapEx Borrower Budget'!E59 -> 65000 | D8: =C8/'CapEx Borrower Budget'!$C$10 -> 507.8125
B9: Deferred Maintenance | C9: =+'CapEx Borrower Budget'!E72 -> 551270 | D9: =C9/'CapEx Borrower Budget'!$C$10 -> 4306.7969
B10: Immediate Repairs | C10: ='CapEx Borrower Budget'!E85 -> 87700 | D10: =C10/'CapEx Borrower Budget'!$C$10 -> 685.15625
B11: Construction Management Fees | C11: =+'CapEx Borrower Budget'!E91 -> 0 | D11: =C11/'CapEx Borrower Budget'!$C$10 -> 0
B12: Contingency | C12: =+SUM('CapEx Borrower Budget'!E88:E90) -> 36830 | D12: =C12/'CapEx Borrower Budget'!$C$10 -> 287.73438
B13: Total Capital Improvement Budget | C13: =SUM(C7:C12) -> 1492000 | D13: =C13/'CapEx Borrower Budget'!$C$10 -> 11656.25

Sheet Capex Detail
A1: What? | B1: Type | C1: How much | D1: Transfer | F1: Total spent so far: | G1: =SUM(C2:C1000) -> 214901.18
A2: Office Buildout | B2: Capex | C2: 8570.41 | D2: 45518 | F2: =MONTH(D2) -> 8
A3: Appliances | B3: Unit Renovations | C3: 10306 | D3: 45518 | F3: =MONTH(D3) -> 8
A4: HVAC A102 | B4: HVAC | C4: 3500 | D4: 45517 | F4: =MONTH(D4) -> 8 | H4: =SUMIF($F$2:$F$25,7,C2:C25) -> 28874
A5: HVAC I258 | B5: HVAC | C5: 3400 | D5: 45517 | F5: =MONTH(D5) -> 8
A6: HVAC G238 | B6: HVAC | C6: 1610 | D6: 45517 | F6: =MONTH(D6) -> 8
A7: HVAC G140 | B7: HVAC | C7: 3550 | D7: 45517 | F7: =MONTH(D7) -> 8
A8: HVAC G240 | B8: HVAC | C8: 3550 | D8: 45517 | F8: =MONTH(D8) -> 8
A9: HVAC A109 | B9: HVAC | C9: 3550 | D9: 45517 | F9: =MONTH(D9) -> 8
A10: HVAC C131 | B10: HVAC | C10: 3900 | D10: 45517 | F10: =MONTH(D10) -> 8
A11: Flooring A102, A207, A105 | B11: Unit Renovations | C11: 1050 | D11: 45517 | F11: =MONTH(D11) -> 8
A12: Optivo Ph 1 & 2 initial payment | B12: Unit Renovations | C12: 29542 | D12: 45517 | F12: =MONTH(D12) -> 8
A13: Fire Extinguishers | B13: Capex | C13: 5092.28 | D13: 45506 | F13: =MONTH(D13) -> 8
A14: Coastal Luxury | B14: Immediate Repairs | C14: 5724 | D14: 45503 | F14: =MONTH(D14) -> 7
A15: Cecilios Painting | B15: Capex | C15: 180 | D15: 45503 | F15: =MONTH(D15) -> 7
A16: Joel Flooring | B16: Capex | C16: 350 | D16: 45503 | F16: =MONTH(D16) -> 7
... A18: Coastal Luxury | B18: Immediate Repairs | C18: 16190 | D18: 45495 | F18: =MONTH(D18) -> 7
A19: Roofing???? | B19: Roofing | F19: =MONTH(D19) -> 12
A20: Jyrka for stair repair (Final payment | B20: Immediate Repairs | C20: 6430 | D20: 45533 | F20: =MONTH(D20) -> 8
A21: Joel Flooring | B21: Unit Renovations | C21: 1771 | D21: 45533 | F21: =MONTH(D21) -> 8
A22: Optivo Ph 1 & 2 final payment | B22: Unit Renovations | C22: 29542 | D22: 45533 | E22: Paid in full | F22: =MONTH(D22) -> 8
A23: ARJ Optivo Ph 4 initial payment | B23: Unit Renovations | C23: 28062.5 | D23: 45534 | E23: =C23*3 -> 84187.5 | F23: =MONTH(D23) -> 8
A24: Optivo Ph 3 | B24: unit Renovations | C24: 41562 | D24: 45601 | F24: =MONTH(D24) -> 11
A25: "ABSTRACT PAW" DOG PARK BUNDLE with BENCH | B25: unit Renovations | C25: 1038.99 | D25: 45558 | F25: =MONTH(D25) -> 9

Sheet CapEx Borrower Budget
B2: BLUE - Manual Input
B3: BLACK - Formula
B5: Borrowing Entity Name: | C5: Red Raider 45 LLC
B6: Property Name: | C6: The Park at Pottsburg Creek
B7: Property Address: | C7: 4800 Atlantic Blvd, Jacksonville, FL 32207
B8: Budget Created By: | C8: Edward Sittler, Vinnie Patel
B9: Date: | C9: 45212
B10: Total # Units: | C10: 128
B11: # Full Upgrades: | C11: 128
B12: # Partial Upgrades: | C12: 0
B14: Item/Description of Work | C14: # Units | D14: Unit Cost | E14: Total
B15: Interior Budget
B16: Unit upgrades | C16: 0 | D16: 0 | E16: =C16*D16 -> 0
B17: Appliances | C17: 128 | D17: 1500 | E17: =C17*D17 -> 192000
B18: Flooring | C18: 128 | D18: 1500 | E18: =C18*D18 -> 192000
B19: Fixtures | C19: 128 | D19: 1000 | E19: =C19*D19 -> 128000
B20: Cabinets | C20: 128 | D20: 900 | E20: =C20*D20 -> 115200
B21: washer/dryer machines | C21: 128 | D21: 500 | E21: =C21*D21 -> 64000
B22: New Units | C22: 2 | D22: 20000 | E22: =C22*D22 -> 40000
B23: Down Unit | C23: 1 | D23: 20000 | E23: =C23*D23 -> 20000
B24: [Enter] | C24: 0 | D24: 0 | E24: =C24*D24 -> 0
B25: [Enter] | C25: 0 | D25: 0 | E25: =C25*D25 -> 0
B26: [Enter] | C26: 0 | D26: 0 | E26: =C26*D26 -> 0
B27: [Enter] | C27: 0 | D27: 0 | E27: =C27*D27 -> 0
... B40: [Enter] | C40: 0 | D40: 0 | E40: =C40*D40 -> 0
B41: Interiors Subtotal | E41: =SUM(E16:E40) -> 751200
B43: Exterior Budget
B44: Landscaping | C44: 1 | D44: 20000 | E44: =C44*D44 -> 20000
B45: Leasing office | C45: 1 | D45: 10000 | E45: =C45*D45 -> 10000
B46: Fitness center | C46: 1 | D46: 5000 | E46: =C46*D46 -> 5000
B47: Monument sign | C47: 1 | D47: 10000 | E47: =C47*D47 -> 10000
B48: Pool area | C48: 1 | D48: 3000 | E48: =C48*D48 -> 3000
B49: Grilling stations | C49: 2 | D49: 2500 | E49: =C49*D49 -> 5000
B50: Dog park | C50: 1 | D50: 5000 | E50: =C50*D50 -> 5000
B51: EV chargers | C51: 2 | D51: 2500 | E51: =C51*D51 -> 5000
B52: Playground | C52: 1 | D52: 2000 | E52: =C52*D52 -> 2000
B53: [Enter] | C53: 0 | D53: 0 | E53: =C53*D53 -> 0
B54: [Enter] | C54: 0 | D54: 0 | E54: =C54*D54 -> 0
B55: [Enter] | C55: 0 | D55: 0 | E55: =C55*D55 -> 0
... B58: [Enter] | C58: 0 | D58: 0 | E58: =C58*D58 -> 0
...

Sheet New Capex Borrower Budget
A1: Borrowing Entity Name: | B1: Red Raider 45 LLC
A2: Property Name: | B2: The Park at Pottsburg Creek
A3: Property Address: | B3: 4800 Atlantic Blvd, Jacksonville, FL 32207
A4: Budget Created By: | B4: Edward Sittler, Vinnie Patel
A5: Date: | B5: 45212
A6: Total # Units: | B6: 128
A7: # Full Upgrades: | B7: 128
A8: # Partial Upgrades: | B8: 0
D9: =D80 -> 1492000 | E9: =E80 -> 1492000 | F9: =E9-D9 -> 0
A10: Item/Description of Work | B10: # Units | C10: Unit Cost | D10: Total | F10: Vendor | G10: Actual Amount | H10: Actual Cost | I10: Versus Budget | J10: Comments
A11: Interior Budget
A12: Unit upgrades | B12: 60 | C12: 5700 | D12: =B12*C12 -> 342000 | F12: Optivo & ARJ | G12: 0 | H12: =B12*G12 -> 0 | I12: =SUM(D12:D16)-H12 -> 636000 | J12: $10.6K per unit.
A13: Appliances | B13: 60 | C13: 1500 | D13: =B13*C13 -> 90000 | F13: Incl. in unit upgrades | G13: 0 | H13: 0
A14: Flooring | B14: 60 | C14: 1500 | D14: =B14*C14 -> 90000 | F14: Incl. in unit upgrades | G14: 0 | H14: 0
A15: Fixtures | B15: 60 | C15: 1000 | D15: =B15*C15 -> 60000 | F15: Incl. in unit upgrades | G15: 0 | H15: 0
A16: Cabinets | B16: 60 | C16: 900 | D16: =B16*C16 -> 54000 | F16: Incl. in unit upgrades | G16: 0 | H16: 0
A17: washer/dryer machines | B17: 0 | C17: 0 | D17: =B17*C17 -> 0 | G17: 0 | H17: 0
A18: New Units | B18: 0 | C18: 0 | D18: =B18*C18 -> 0 | G18: 0 | H18: 0
A19: Down Unit | B19: 1 | C19: 40000 | D19: =B19*C19 -> 40000 | E19: Fire damaged unit | G19: 40000 | H19: =B19*G19 -> 40000 | I19: =D19-H19 -> 0
A20: Laundry Room Improvements | B20: 1 | C20: =20000-4800 -> 15200 | D20: =B20*C20 -> 15200 | F20: OEM Laundry/Orexis | G20: 4000 | H20: =B20*G20 -> 4000 | I20: =C20-H20 -> 11200 | J20: Includes $3,000 investment from OEM. The extra can be re-assigned to another category
A21: [Enter] | B21: 0 | C21: 0 | D21: =B21*C21 -> 0
A22: [Enter] | B22: 0 | C22: 0 | D22: =B22*C22 -> 0
A23: Interiors Subtotal | D23: =SUM(D12:D22) -> 691200 | H23: =SUM(H12:H22) -> 44000 | I23: =SUM(I12:I22) -> 647200
E24: 751200
A25: Exterior Budget
A26: Landscaping | B26: 1 | C26: 50000 | D26: =B26*C26 -> 50000 | F26: TBD | G26: 50000 | H26: =B26*G26 -> 50000 | I26: =D26-H26 -> 0
A27: Leasing office | B27: 1 | C27: 10000 | D27: =B27*C27 -> 10000 | F27: ? | G27: 8570.41 | H27: =B27*G27 -> 8570.41 | I27: =D27-H27 -> 1429.59 | J27: Re-assign the left over to another category
A28: Fitness center | B28: 1 | C28: 0 | D28: =B28*C28 -> 0 | F28: N/A | G28: 0 | H28: =B28*G28 -> 0 | I28: =D28-H28 -> 0
A29: Monument sign | B29: 1 | C29: 10000 | D29: =B29*C29 -> 10000 | F29: TBD | G29: 10000 | H29: =B29*G29 -> 10000 | I29: =D29-H29 -> 0
A30: Pool area | B30: 1 | C30: 10000 | D30: =B30*C30 -> 10000 | F30: TBD | G30: 50000 | H30: =B30*G30 -> 50000 | I30: =D30-H30 -> -40000
A31: Grilling stations | B31: 2 | C31: 2500 | D31: =B31*C31 -> 5000 | F31: N/A | G31: 0 | H31: =B31*G31 -> 0 | I31: =D31-H31 -> 5000 | J31: Included in Pool Area
A32: Dog park | B32: 1 | C32: 5000 | D32: =B32*C32 -> 5000 | F32: TBD | G32: 2000 | H32: =B32*G32 -> 2000 | I32: =D32-H32 -> 3000
A33: EV chargers | B33: 2 | C33: 2500 | D33: =B33*C33 -> 5000 | F33: N/A | G33: 0 | H33: =B33*G33 -> 0 | I33: =D33-H33 -> 5000
A34: Playground | B34: 1 | C34: 2000 | D34: =B34*C34 -> 2000 | F34: N/A | G34: 1000 | H34: =B34*G34 -> 1000 | I34: =D34-H34 -> 1000 | J34: Wash the playground
A35: Shed | B35: 1 | C35: 0 | D35: =B35*C35 -> 0 | F35: TBD | G35: 10000 | H35: =B35*G35 -> 10000 | I35: =D35-H35 -> -10000
A36: Remaining signs | B36: 1 | C36: 0 | D36: =B36*C36 -> 0 | F36: TBD | G36: 20000 | H36: =B36*G36 -> 20000 | I36: =D36-H36 -> -20000
A37: [Enter] | B37: 0 | C37: 0 | D37: =B37*C37 -> 0
A38: [Enter] | B38: 0 | C38: 0 | D38: =B38*C38 -> 0
A39: [Enter] | B39: 0 | C39: 0 | D39: =B39*C39 -> 0
A40: [Enter] | B40: 0 | C40: 0 | D40: =B40*C40 -> 0
...

Sheet CapEx Tracker
B2: BLUE - Manual Input | G2: BLUE - Manual Input
B3: BLACK - Formula | G3: BLACK - Formula
B5: ='CapEx Borrower Budget'!B5 -> Borrowing Entity Name: | C5: ='CapEx Borrower Budget'!C5 -> Red Raider 45 LLC
B6: ='CapEx Borrower Budget'!B6 -> Property Name: | C6: ='CapEx Borrower Budget'!C6 -> The Park at Pottsburg Creek
B7: ='CapEx Borrower Budget'!B7 -> Property Address: | C7: ='CapEx Borrower Budget'!C7 -> 4800 Atlantic Blvd, Jacksonville, FL 32207 | G7: Property Address: | H7: =C7 -> 4800 Atlantic Blvd, Jacksonville, FL 32207
B8: ='CapEx Borrower Budget'!B8 -> Budget Created By: | C8: ='CapEx Borrower Budget'!C8 -> Edward Sittler, Vinnie Patel | G8: Budget Created By: | H8: =C8 -> Edward Sittler, Vinnie Patel
B9: ='CapEx Borrower Budget'!B9 -> Date: | C9: ='CapEx Borrower Budget'!C9 -> 45212 | G9: Date: | H9: =C9 -> 45212
B10: ='CapEx Borrower Budget'!B10 -> Total # Units: | C10: ='CapEx Borrower Budget'!C10 -> 128 | G10: Total # Units: | H10: =C10 -> 128
B11: ='CapEx Borrower Budget'!B11 -> # Full Upgrades: | C11: ='CapEx Borrower Budget'!C11 -> 128 | G11: # Full Upgrades: | H11: =C11 -> 128
B12: ='CapEx Borrower Budget'!B12 -> # Partial Upgrades: | C12: ='CapEx Borrower Budget'!C12 -> 0 | G12: # Partial Upgrades: | H12: =C12 -> 0
B14: ='CapEx Borrower Budget'!B14 -> Item/Description of Work | C14: ='CapEx Borrower Budget'!C14 -> # Units | D14: ='CapEx Borrower Budget'!D14 -> Unit Cost | E14: ='CapEx Borrower Budget'!E14 -> Total | G14: Item/Description of Work | H14: Original Budget | I14: Budget Reallocations | J14: Adjusted Current Budget | K14: 1 | L14: 2 | M14: 3 | N14: 4 | O14: 5 | P14: 6 | Q14: 7 | R14: 8 | S14: 9 | T14: 10 | U14: 11 | V14: 12 | W14: Total Completed and Stored to date | X14: % Complete | Y14: Balance To Finish the Project | Z14: Notes
B15: ='CapEx Borrower Budget'!B15 -> Interior Budget | G15: Interiors | H15: (A) | I15: (B) | J15: (A + B) | K15: (D) | L15: (D) | M15: (D) | N15: (D) | O15: (D) | P15: (D) | Q15: (D) | R15: (D) | S15: (D) | T15: (D) | U15: (D) | V15: (D) | W15: (D+D) | X15: (D+D) / (A+B) | Y15: (A+B)-(D+D)
B16: ='CapEx Borrower Budget'!B16 -> Unit upgrades | C16: ='CapEx Borrower Budget'!C16 -> 0 | D16: ='CapEx Borrower Budget'!D16 -> 0 | E16: ='CapEx Borrower Budget'!E16 -> 0 | G16: =+B16 -> Unit upgrades | H16: =+E16 -> 0 | I16: 627200 | J16: =H16+I16 -> 627200 | K16: 0 | L16: 0 | M16: 0 | N16: 0 | O16: 0 | P16: 0 | Q16: 0 | R16: 0 | S16: 0 | T16: 0 | U16: 0 | V16: 0 | W16: =SUM(K16:V16) -> 0 | X16: =IFERROR((W16)/J16,"0%") -> 0 | Y16: =J16-W16 -> 627200
B17: ='CapEx Borrower Budget'!B17 -> Appliances | C17: ='CapEx Borrower Budget'!C17 -> 128 | D17: ='CapEx Borrower Budget'!D17 -> 1500 | E17: ='CapEx Borrower Budget'!E17 -> 192000 | G17: =+B17 -> Appliances | H17: =+E17 -> 192000 | I17: -192000 | J17: =H17+I17 -> 0 | K17: 0 | L17: 0 | M17: 0 | N17: 0 | O17: 0 | P17: 0 | Q17: 0 | R17: 0 | S17: 0 | T17: 0 | U17: 0 | V17: 0 | W17: =SUM(K17:V17) -> 0 | X17: =IFERROR((W17)/J17,"0%") -> 0% | Y17: =J17-W17 -> 0
B18: ='CapEx Borrower Budget'!B18 -> Flooring | C18: ='CapEx Borrower Budget'!C18 -> 128 | D18: ='CapEx Borrower Budget'!D18 -> 1500 | E18: ='CapEx Borrower Budget'!E18 -> 192000 | G18: =+B18 -> Flooring | H18: =+E18 -> 192000 | I18: -192000 | J18: =H18+I18 -> 0 | K18: 0 | L18: 0 | M18: 0 | N18: 0 | O18: 0 | P18: 0 | Q18: 0 | R18: 0 | S18: 0 | T18: 0 | U18: 0 | V18: 0 | W18: =SUM(K18:V18) -> 0 | X18: =IFERROR((W18)/J18,"0%") -> 0% | Y18: =J18-W18 -> 0
B19: ='CapEx Borrower Budget'!B19 -> Fixtures | C19: ='CapEx Borrower Budget'!C19 -> 128 | D19: ='CapEx Borrower Budget'!D19 -> 1000 | E19: ='CapEx Borrower Budget'!E19 -> 128000 | G19: =+B19 -> Fixtures | H19: =+E19 -> 128000 | I19: =-H19 -> -128000 | J19: =H19+I19 -> 0 | K19: 0 | L19: 0 | M19: 0 | N19: 0 | O19: 0 | P19: 0 | Q19: 0 | R19: 0 | S19: 0 | T19: 0 | U19: 0 | V19: 0 | W19: =SUM(K19:V19) -> 0 | X19: =IFERROR((W19)/J19,"0%") -> 0% | Y19: =J19-W19 -> 0
B20: ='CapEx Borrower Budget'!B20 -> Cabinets | C20: ='CapEx Borrower Budget'!C20 -> 128 | D20: ='CapEx Borrower Budget'!D20 -> 900 | E20: ='CapEx Borrower Budget'!E20 -> 115200 | G20: =+B20 -> Cabinets | H20: =+E20 -> 115200 | I20: =-H20 -> -115200 | J20: =H20+I20 -> 0 | K20: 0 | L20: 0 | M20: 0 | N20: 0 | O20: 0 | P20: 0 | Q20: 0 | R20: 0 | S20: 0 | T20: 0 | U20: 0 | V20: 0 | W20: =SUM(K20:V20) -> 0 | X20: =IFERROR((W20)/J20,"0%") -> 0% | Y20: =J20-W20 -> 0
B21: ='CapEx Borrower Budget'!B21 -> washer/dryer machines | C21: ='CapEx Borrower Budget'!C21 -> 128 | D21: ='CapEx Borrower Budget'!D21 -> 500 | E21: ='CapEx Borrower Budget'!E21 -> 64000 | G21: =+B21 -> washer/dryer machines | H21: =+E21 -> 64000 | I21: 0 | J21: =H21+I21 -> 64000 | K21: 0 | L21: 0 | M21: 0 | N21: 0 | O21: 0 | P21: 0 | Q21: 0 | R21: 0 | S21: 0 | T21: 0 | U21: 0 | V21: 0 | W21: =SUM(K21:V21) -> 0 | X21: =IFERROR((W21)/J21,"0%") -> 0 | Y21: =J21-W21 -> 64000
B22: ='CapEx Borrower Budget'!B22 -> New Units | C22: ='CapEx Borrower Budget'!C22 -> 2 | D22: ='CapEx Borrower Budget'!D22 -> 20000 | E22: ='CapEx Borrower Budget'!E22 -> 40000 | G22: =+B22 -> New Units | H22: =+E22 -> 40000 | I22: 0 | J22: =H22+I22 -> 40000 | K22: 0 | L22: 0 | M22: 0 | N22: 0 | O22: 0 | P22: 0 | Q22: 0 | R22: 0 | S22: 0 | T22: 0 | U22: 0 | V22: 0 | W22: =SUM(K22:V22) -> 0 | X22: =IFERROR((W22)/J22,"0%") -> 0 | Y22: =J22-W22 -> 40000
B23: ='CapEx Borrower Budget'!B23 -> Down Unit | C23: ='CapEx Borrower Budget'!C23 -> 1 | D23: ='CapEx Borrower Budget'!D23 -> 20000 | E23: ='CapEx Borrower Budget'!E23 -> 20000 | G23: =+B23 -> Down Unit | H23: =+E23 -> 20000 | I23: 0 | J23: =H23+I23 -> 20000 | K23: 0 | L23: 0 | M23: 0 | N23: 0 | O23: 0 | P23: 0 | Q23: 0 | R23: 0 | S23: 0 | T23: 0 | U23: 0 | V23: 0 | W23: =SUM(K23:V23) -> 0 | X23: =IFERROR((W23)/J23,"0%") -> 0 | Y23: =J23-W23 -> 20000
B24: ='CapEx Borrower Budget'!B24 -> [Enter] | C24: ='CapEx Borrower Budget'!C24 -> 0 | D24: ='CapEx Borrower Budget'!D24 -> 0 | E24: ='CapEx Borrower Budget'!E24 -> 0 | G24: =+B24 -> [Enter] | H24: =+E24 -> 0 | I24: 0 | J24: =H24+I24 -> 0 | K24: 0 | L24: 0 | M24: 0 | N24: 0 | O24: 0 | P24: 0 | Q24: 0 | R24: 0 | S24: 0 | T24: 0 | U24: 0 | V24: 0 | W24: =SUM(K24:V24) -> 0 | X24: =IFERROR((W24)/J24,"0%") -> 0% | Y24: =J24-W24 -> 0
B25: ='CapEx Borrower Budget'!B25 -> [Enter] | C25: ='CapEx Borrower Budget'!C25 -> 0 | D25: ='CapEx Borrower Budget'!D25 -> 0 | E25: ='CapEx Borrower Budget'!E25 -> 0 | G25: =+B25 -> [Enter] | H25: =+E25 -> 0 | I25: 0 | J25: =H25+I25 -> 0 | K25: 0 | L25: 0 | M25: 0 | N25: 0 | O25: 0 | P25: 0 | Q25: 0 | R25: 0 | S25: 0 | T25: 0 | U25: 0 | V25: 0 | W25: =SUM(K25:V25) -> 0 | X25: =IFERROR((W25)/J25,"0%") -> 0% | Y25: =J25-W25 -> 0
B26: ='CapEx Borrower Budget'!B26 -> [Enter] | C26: ='CapEx Borrower Budget'!C26 -> 0 | D26: ='CapEx Borrower Budget'!D26 -> 0 | E26: ='CapEx Borrower Budget'!E26 -> 0 | G26: =+B26 -> [Enter] | H26: =+E26 -> 0 | I26: 0 | J26: =H26+I26 -> 0 | K26: 0 | L26: 0 | M26: 0 | N26: 0 | O26: 0 | P26: 0 | Q26: 0 | R26: 0 | S26: 0 | T26: 0 | U26: 0 | V26: 0 | W26: =SUM(K26:V26) -> 0 | X26: =IFERROR((W26)/J26,"0%") -> 0% | Y26: =J26-W26 -> 0
B27: ='CapEx Borrower Budget'!B27 -> [Enter] | C27: ='CapEx Borrower Budget'!C27 -> 0 | D27: ='CapEx Borrower Budget'!D27 -> 0 | E27: ='CapEx Borrower Budget'!E27 -> 0 | G27: =+B27 -> [Enter] | H27: =+E27 -> 0 | I27: 0 | J27: =H27+I27 -> 0 | K27: 0 | L27: 0 | M27: 0 | N27: 0 | O27: 0 | P27: 0 | Q27: 0 | R27: 0 | S27: 0 | T27: 0 | U27: 0 | V27: 0 | W27: =SUM(K27:V27) -> 0 | X27: =IFERROR((W27)/J27,"0%") -> 0% | Y27: =J27-W27 -> 0
B28: ='CapEx Borrower Budget'!B28 -> [Enter] | C28: ='CapEx Borrower Budget'!C28 -> 0 | D28: ='CapEx Borrower Budget'!D28 -> 0 | E28: ='CapEx Borrower Budget'!E28 -> 0 | G28: =+B28 -> [Enter] | H28: =+E28 -> 0 | I28: 0 | J28: =H28+I28 -> 0 | K28: 0 | L28: 0 | M28: 0 | N28: 0 | O28: 0 | P28: 0 | Q28: 0 | R28: 0 | S28: 0 | T28: 0 | U28: 0 | V28: 0 | W28: =SUM(K28:V28) -> 0 | X28: =IFERROR((W28)/J28,"0%") -> 0% | Y28: =J28-W28 -> 0
B29: ='CapEx Borrower Budget'!B29 -> [Enter] | C29: ='CapEx Borrower Budget'!C29 -> 0 | D29: ='CapEx Borrower Budget'!D29 -> 0 | E29: ='CapEx Borrower Budget'!E29 -> 0 | G29: =+B29 -> [Enter] | H29: =+E29 -> 0 | I29: 0 | J29: =H29+I29 -> 0 | K29: 0 | L29: 0 | M29: 0 | N29: 0 | O29: 0 | P29: 0 | Q29: 0 | R29: 0 | S29: 0 | T29: 0 | U29: 0 | V29: 0 | W29: =SUM(K29:V29) -> 0 | X29: =IFERROR((W29)/J29,"0%") -> 0% | Y29: =J29-W29 -> 0
B30: ='CapEx Borrower Budget'!B30 -> [Enter] | C30: ='CapEx Borrower Budget'!C30 -> 0 | D30: ='CapEx Borrower Budget'!D30 -> 0 | E30: ='CapEx Borrower Budget'!E30 -> 0 | G30: =+B30 -> [Enter] | H30: =+E30 -> 0 | I30: 0 | J30: =H30+I30 -> 0 | K30: 0 | L30: 0 | M30: 0 | N30: 0 | O30: 0 | P30: 0 | Q30: 0 | R30: 0 | S30: 0 | T30: 0 | U30: 0 | V30: 0 | W30: =SUM(K30:V30) -> 0 | X30: =IFERROR((W30)/J30,"0%") -> 0% | Y30: =J30-W30 -> 0
B31: ='CapEx Borrower Budget'!B31 -> [Enter] | C31: ='CapEx Borrower Budget'!C31 -> 0 | D31: ='CapEx Borrower Budget'!D31 -> 0 | E31: ='CapEx Borrower Budget'!E31 -> 0 | G31: =+B31 -> [Enter] | H31: =+E31 -> 0 | I31: 0 | J31: =H31+I31 -> 0 | K31: 0 | L31: 0 | M31: 0 | N31: 0 | O31: 0 | P31: 0 | Q31: 0 | R31: 0 | S31: 0 | T31: 0 | U31: 0 | V31: 0 | W31: =SUM(K31:V31) -> 0 | X31: =IFERROR((W31)/J31,"0%") -> 0% | Y31: =J31-W31 -> 0
B32: ='CapEx Borrower Budget'!B32 -> [Enter] | C32: ='CapEx Borrower Budget'!C32 -> 0 | D32: ='CapEx Borrower Budget'!D32 -> 0 | E32: ='CapEx Borrower Budget'!E32 -> 0 | G32: =+B32 -> [Enter] | H32: =+E32 -> 0 | I32: 0 | J32: =H32+I32 -> 0 | K32: 0 | L32: 0 | M32: 0 | N32: 0 | O32: 0 | P32: 0 | Q32: 0 | R32: 0 | S32: 0 | T32: 0 | U32: 0 | V32: 0 | W32: =SUM(K32:V32) -> 0 | X32: =IFERROR((W32)/J32,"0%") -> 0% | Y32: =J32-W32 -> 0
... B40: ='CapEx Borrower Budget'!B40 -> [Enter] | C40: ='CapEx Borrower Budget'!C40 -> 0 | D40: ='CapEx Borrower Budget'!D40 -> 0 | E40: ='CapEx Borrower Budget'!E40 -> 0 | G40: =+B40 -> [Enter] | H40: =+E40 -> 0 | I40: 0 | J40: =H40+I40 -> 0 | K40: 0 | L40: 0 | M40: 0 | N40: 0 | O40: 0 | P40: 0 | Q40: 0 | R40: 0 | S40: 0 | T40: 0 | U40: 0 | V40: 0 | W40: =SUM(K40:V40) -> 0 | X40: =IFERROR((W40)/J40,"0%") -> 0% | Y40: =J40-W40 -> 0
B41: ='CapEx Borrower Budget'!B41 -> Interiors Subtotal | E41: ='CapEx Borrower Budget'!E41 -> 751200 | G41: =B41 -> Interiors Subtotal | H41: =SUM(H16:H40) -> 751200 | I41: =SUM(I16:I40) -> 0 | J41: =SUM(J16:J40) -> 751200 | K41: =SUM(K16:K40) -> 0 | L41: =SUM(L16:L40) -> 0 | M41: =SUM(M16:M40) -> 0 | N41: =SUM(N16:N40) -> 0 | O41: =SUM(O16:O40) -> 0 | ... V41: =SUM(V16:V40) -> 0 | W41: =SUM(K41:V41) -> 0 | X41: =IFERROR((W41)/J41,"0%") -> 0 | Y41: =J41-W41 -> 751200
B43: ='CapEx Borrower Budget'!B43 -> Exterior Budget | G43: Exteriors
B44: ='CapEx Borrower Budget'!B44 -> Landscaping | C44: ='CapEx Borrower Budget'!C44 -> 1 | D44: ='CapEx Borrower Budget'!D44 -> 20000 | E44: ='CapEx Borrower Budget'!E44 -> 20000 | G44: =+B44 -> Landscaping | H44: =+E44 -> 20000 | I44: 0 | J44: =H44+I44 -> 20000 | K44: 0 | L44: 0 | M44: 0 | N44: 0 | O44: 0 | P44: 0 | Q44: 0 | R44: 0 | S44: 0 | T44: 0 | U44: 0 | V44: 0 | W44: =SUM(K44:V44) -> 0 | X44: =IFERROR((W44)/J44,"0%") -> 0 | Y44: =J44-W44 -> 20000
B45: ='CapEx Borrower Budget'!B45 -> Leasing office | C45: ='CapEx Borrower Budget'!C45 -> 1 | D45: ='CapEx Borrower Budget'!D45 -> 10000 | E45: ='CapEx Borrower Budget'!E45 -> 10000 | G45: =+B45 -> Leasing office | H45: =+E45 -> 10000 | I45: -1429.59 | J45: =H45+I45 -> 8570.41 | K45: 0 | L45: 0 | M45: 0 | N45: 0 | O45: 0 | P45: 0 | Q45: 0 | R45: 0 | S45: 0 | T45: 0 | U45: 0 | V45: 0 | W45: =SUM(K45:V45) -> 0 | X45: =IFERROR((W45)/J45,"0%") -> 0 | Y45: =J45-W45 -> 8570.41
B46: ='CapEx Borrower Budget'!B46 -> Fitness center | C46: ='CapEx Borrower Budget'!C46 -> 1 | D46: ='CapEx Borrower Budget'!D46 -> 5000 | E46: ='CapEx Borrower Budget'!E46 -> 5000 | G46: =+B46 -> Fitness center | H46: =+E46 -> 5000 | I46: -5000 | J46: =H46+I46 -> 0 | K46: 0 | L46: 0 | M46: 0 | N46: 0 | O46: 0 | P46: 0 | Q46: 0 | R46: 0 | S46: 0 | T46: 0 | U46: 0 | V46: 0 | W46: =SUM(K46:V46) -> 0 | X46: =IFERROR((W46)/J46,"0%") -> 0% | Y46: =J46-W46 -> 0
B47: ='CapEx Borrower Budget'!B47 -> Monument sign | C47: ='CapEx Borrower Budget'!C47 -> 1 | D47: ='CapEx Borrower Budget'!D47 -> 10000 | E47: ='CapEx Borrower Budget'!E47 -> 10000 | G47: =+B47 -> Monument sign | H47: =+E47 -> 10000 | I47: 0 | J47: =H47+I47 -> 10000 | K47: 0 | L47: 0 | M47: 0 | N47: 0 | O47: 0 | P47: 0 | Q47: 0 | R47: 0 | S47: 0 | T47: 0 | U47: 0 | V47: 0 | W47: =SUM(K47:V47) -> 0 | X47: =IFERROR((W47)/J47,"0%") -> 0 | Y47: =J47-W47 -> 10000
B48: ='CapEx Borrower Budget'!B48 -> Pool area | C48: ='CapEx Borrower Budget'!C48 -> 1 | D48: ='CapEx Borrower Budget'!D48 -> 3000 | E48: ='CapEx Borrower Budget'!E48 -> 3000 | G48: =+B48 -> Pool area | H48: =+E48 -> 3000 | I48: 8929.59 | J48: =H48+I48 -> 11929.59 | K48: 0 | L48: 0 | M48: 0 | N48: 0 | O48: 0 | P48: 0 | Q48: 0 | R48: 0 | S48: 0 | T48: 0 | U48: 0 | V48: 0 | W48: =SUM(K48:V48) -> 0 | X48: =IFERROR((W48)/J48,"0%") -> 0 | Y48: =J48-W48 -> 11929.59
B49: ='CapEx Borrower Budget'!B49 -> Grilling stations | C49: ='CapEx Borrower Budget'!C49 -> 2 | D49: ='CapEx Borrower Budget'!D49 -> 2500 | E49: ='CapEx Borrower Budget'!E49 -> 5000 | G49: =+B49 -> Grilling stations | H49: =+E49 -> 5000 | I49: -2500 | J49: =H49+I49 -> 2500 | K49: 0 | L49: 0 | M49: 0 | N49: 0 | O49: 0 | P49: 0 | Q49: 0 | R49: 0 | S49: 0 | T49: 0 | U49: 0 | V49: 0 | W49: =SUM(K49:V49) -> 0 | X49: =IFERROR((W49)/J49,"0%") -> 0 | Y49: =J49-W49 -> 2500
B50: ='CapEx Borrower Budget'!B50 -> Dog park | C50: ='CapEx Borrower Budget'!C50 -> 1 | D50: ='CapEx Borrower Budget'!D50 -> 5000 | E50: ='CapEx Borrower Budget'!E50 -> 5000 | G50: =+B50 -> Dog park | H50: =+E50 -> 5000 | I50: 0 | J50: =H50+I50 -> 5000 | K50: 0 | L50: 0 | M50: 0 | N50: 0 | O50: 0 | P50: 0 | Q50: 0 | R50: 0 | S50: 0 | T50: 0 | U50: 0 | V50: 0 | W50: =SUM(K50:V50) -> 0 | X50: =IFERROR((W50)/J50,"0%") -> 0 | Y50: =J50-W50 -> 5000
B51: ='CapEx Borrower Budget'!B52 -> Playground | C51: ='CapEx Borrower Budget'!C52 -> 1 | D51: ='CapEx Borrower Budget'!D52 -> 2000 | E51: ='CapEx Borrower Budget'!E52 -> 2000 | G51: =+B51 -> Playground | H51: =+E51 -> 2000 | I51: 0 | J51: =H51+I51 -> 2000 | K51: 0 | L51: 0 | M51: 0 | N51: 0 | O51: 0 | P51: 0 | Q51: 0 | R51: 0 | S51: 0 | T51: 0 | U51: 0 | V51: 0 | W51: =SUM(K51:V51) -> 0 | X51: =IFERROR((W51)/J51,"0%") -> 0 | Y51: =J51-W51 -> 2000
...

Sheet Unit Interior Tracker
A1: Borrowing Entity Name
A2: Property Name
A3: Property Address
A4: Date
A5: PLEASE FILL OUT ALL CELLS FOR EACH RENOVATED UNIT AND SUBMIT RENT ROLL
B6: Ex. 1 bd / 1 bd | D6: INCLUDE "X" IF THE UNIT IS RENOVATED AND AVAILABLE FOR LEASING | E6: INCLUDE "X" IF THE UNIT IS NOT FULLY RENOVATED, BUT UNDERGOING RENOVATION | F6: PLEASE FILL OUT DATE THE RENOVATION WAS COMPLETED | H6: PLEASE FILL OUT RENT FOR UNIT PRIOR TO RENOVATION | I6: PLEASE FILL OUT RENT UNIT IS LEASE AT. NOT THE MARKET UNIT FOR THE UNIT. LEASE MUST BE SUPPORTED BY RENT ROLL
A7: Unit # | B7: Unit Type | C7: SF | D7: Fully Renovated | E7: Undergoing Renovation | F7: Completion Date of Renovation | G7: Unit Leased? | H7: Prior Leased Rent | I7: New Leased Rent

Sheet Immediate Repairs
Q5: Immediate Repairs | T5: Status
Q6: Install and /or repair fencing and gates to comply with security plan. | R6: 1 | S6: 30000
Q7: Repair damaged pavement consisting of linear cracking, alligator cracking, potholes, and surface raveling throughout the Property. | R7: 1 | S7: 28000
Q8: Install security cameras to comply with security plan. | R8: 1 | S8: 20000
Q9: Repair and replace cracked and broken concrete stair treads. | R9: 1 | S9: 5000
Q10: Repair all trip hazards. | R10: 1 | S10: 3000
Q11: Reconfigure the ramp and access walk to provide a level landing at the leasing office entry door | R11: 1 | S11: 1200
Q12: Reconfigure the ADA accessible parking space to provide unobstructed access to aisle. | R12: 1 | S12: 500
Q13: [Enter] | R13: 0 | S13: 0
Q14: [Enter] | R14: 0 | S14: 0
Q15: [Enter] | R15: 0 | S15: 0
Q16: Immediate Repairs Subtotal

Sheet Closed& Approved Budget 

Sheet Appliance Details
A1: Appliances | C1: Rich Feller - LinkedIn | D1: Diamond Appl Group | E1: Diamond Appl Group | F1: Summit Appliance From Peak | G1: Amazon | H1: HD Supply | I1: Home Depot
C2: Single | D2: Single | E2: 10 Units | G2: Single
A3: FCFE3083AS | B3: Range | C3: 799
A4: F4000 Hood | B4: Hood | C4: 110
A5: FFTR1835VS | B5: Fridge | C5: 653 | D5: 670 | E5: 625 | G5: 680 | H5: 858.84 | I5: 598 | K5: FCFE3062AS | N5: FCFE3083AS | Q5: FFTR1835VS
A6: FCFE3062AS | B6: Range | D6: 785 | E6: 735 | G6: 780 | H6: 1220.84 | I6: 798
A7: Broan F403004 | B7: Hood | D7: 110 | E7: 99 | G7: 110 | I7: 60
A10: Total | C10: =SUM(C3:C9) -> 1562 | D10: =SUM(D3:D9) -> 1565 | E10: =SUM(E3:E9) -> 1459 | F10: =SUM(F3:F9) -> 0 | G10: =SUM(G3:G9) -> 1570 | H10: =SUM(H3:H9) -> 2079.68 | I10: =SUM(I3:I9) -> 1456
D16: appliances total | E16: 1403 | F16: 60 | G16: =F16*E16 -> 84180
D17: budget | E17: 1500 | F17: 128 | G17: =F17*E17 -> 192000
D18: budget reallocation | G18: =G17-G16 -> 107820
