Workbook

Sheet Worst Case
A1: Account Number | B1: Account Name | C1: Apr 2025 | D1: May 2025 | E1: Jun 2025 | F1: Total | I1: 45931 | J1: 45962 | K1: 45992 | L1: 46023 | M1: 46054 | N1: 46082 | O1: 46113 | P1: 46143 | Q1: 46174 | R1: 46204 | S1: 46235 | T1: 46235
H2: Avg units | I2: 17 | J2: 20 | K2: 20 | L2: 20 | M2: 30 | N2: 40 | O2: 60 | P2: 70 | Q2: 88 | R2: 88 | S2: 88 | T2: 88
H3: Avg Rent | I3: 1450 | J3: 1450 | K3: 1450 | L3: 1450 | M3: 1450 | N3: 1450 | O3: 1450 | P3: 1450 | Q3: 1450 | R3: 1450 | S3: 1450 | T3: 1450
A4: 3110 | B4: Rent | C4: 16436.71 | D4: 0 | E4: 505.72 | F4: 16942.43 | I4: =I2*I3 -> 24650 | J4: =J2*J3 -> 29000 | K4: =K2*K3 -> 29000 | L4: =L2*L3 -> 29000 | M4: =M2*M3 -> 43500 | N4: =N2*N3 -> 58000 | O4: =O2*O3 -> 87000 | P4: =P2*P3 -> 101500 | ... T4: =T2*T3 -> 127600 | U4: =SUM(I4:S4) -> 784450
A5: 3115 | B5: Late fee | C5: 0 | D5: 0 | E5: 280 | F5: 280
A6: 3124 | B6: Bad Debt Offset | C6: -17136.36 | D6: 0 | E6: 0 | F6: -17136.36
A7: 3130 | B7: Application Process | C7: 180 | D7: 210 | E7: 180 | F7: 570
A8: 3443 | B8: Pest Control | C8: 27 | D8: 0 | E8: 15 | F8: 42 | I8: =5*I2 -> 85 | J8: =5*J2 -> 100 | K8: =5*K2 -> 100 | L8: =5*L2 -> 100 | M8: =5*M2 -> 150 | N8: =5*N2 -> 200 | O8: =5*O2 -> 300 | P8: =5*P2 -> 350 | ... T8: =5*T2 -> 440
A9: 3712 | B9: Utility pass thru | C9: 609.65 | D9: 0 | E9: 284.28 | F9: 893.93 | I9: =85*I2 -> 1445 | J9: =85*J2 -> 1700 | K9: =85*K2 -> 1700 | L9: =85*L2 -> 1700 | M9: =85*M2 -> 2550 | N9: =85*N2 -> 3400 | O9: =85*O2 -> 5100 | P9: =85*P2 -> 5950 | ... T9: =85*T2 -> 7480
A10: 3719 | B10: Utility pass thru Trash | C10: 63 | D10: 0 | E10: 35 | F10: 98 | I10: =9*I2 -> 153 | J10: =9*J2 -> 180 | K10: =9*K2 -> 180 | L10: =9*L2 -> 180 | M10: =9*M2 -> 270 | N10: =9*N2 -> 360 | O10: =9*O2 -> 540 | P10: =9*P2 -> 630 | ... T10: =9*T2 -> 792
B11: Total Operating Income | C11: 180 | D11: 210 | E11: 1300 | F11: 1690 | I11: 18000 | J11: 20000 | K11: =SUM(K4:K10) -> 30980 | L11: =SUM(L4:L10) -> 30980 | M11: =SUM(M4:M10) -> 46470 | N11: =SUM(N4:N10) -> 61960 | O11: =SUM(O4:O10) -> 92940 | P11: =SUM(P4:P10) -> 108430 | Q11: =SUM(Q4:Q10) -> 136312 | R11: =SUM(R4:R10) -> 136312 | ... T11: =SUM(T4:T10) -> 136312 | U11: =SUM(I11:S11) -> 818696
B12: Expense | U12: =SUM(I12:S12) -> 0
B13: Maintenance Subtotal | U13: =SUM(I13:S13) -> 0
A14: 4416 | B14: Cleaning Supplies | C14: 28.5 | D14: 0 | E14: 0 | F14: 28.5 | U14: =SUM(I14:S14) -> 0
A15: 4433 | B15: Pest Control | C15: 958 | D15: 0 | E15: 0 | F15: 958 | U15: =SUM(I15:S15) -> 0
A16: 4455 | B16: Equipment Rep & Maint. | C16: 0 | D16: 729.14 | E16: 0 | F16: 729.14 | U16: =SUM(I16:S16) -> 0
A17: 4541 | B17: Turnover - Paint Labor | C17: 250 | D17: 0 | E17: 0 | F17: 250 | U17: =SUM(I17:S17) -> 0
B18: Total Maintenance Subtotal | C18: 1236.5 | D18: 729.14 | E18: 0 | F18: 1965.64 | I18: 1310.4267 | J18: 1310.4267 | K18: 1310.4267 | L18: 2000 | M18: 2000 | N18: 2000 | O18: 2000 | P18: 2000 | Q18: 2000 | R18: 2000 | S18: 2000 | T18: 2000 | U18: =SUM(I18:S18) -> 19931.28
B19: Utilities Subtotal | U19: =SUM(I19:S19) -> 0
A20: 4549 | B20: Turnover - Utility | C20: 624.34 | D20: 301.98 | E20: 402.87 | F20: 1329.19 | I20: 500 | J20: 500 | K20: 500 | L20: 500 | M20: 500 | N20: 500 | O20: 500 | P20: 500 | Q20: 500 | R20: 500 | S20: 500 | T20: 500 | U20: =SUM(I20:S20) -> 5500
A21: 4580 | B21: Electricity | C21: 2180.16 | D21: 1648.95 | E21: 1795.91 | F21: 5625.02 | I21: 2000 | J21: 2000 | K21: 2000 | L21: 2000 | M21: 2000 | N21: 2000 | O21: 2000 | P21: 2000 | Q21: 2000 | R21: 2000 | S21: 2000 | T21: 2000 | U21: =SUM(I21:S21) -> 22000
A22: 4606 | B22: Exp Reim - Cellphone | C22: 45.68 | D22: 45.68 | E22: 45.68 | F22: 137.04 | I22: 45.68 | J22: 45.68 | K22: 45.68 | L22: 45.68 | M22: 45.68 | N22: 45.68 | O22: 45.68 | P22: 45.68 | Q22: 45.68 | R22: 45.68 | S22: 45.68 | T22: 45.68 | U22: =SUM(I22:S22) -> 502.48
A23: 4610 | B23: Water & Sewer | C23: 0 | D23: 1985.53 | E23: 3848.66 | F23: 5834.19 | I23: 3500 | J23: 4500 | K23: 6000 | L23: 6000 | M23: 6000 | N23: 6000 | O23: 6000 | P23: 6000 | Q23: 6000 | R23: 6000 | S23: 6000 | T23: 6000 | U23: =SUM(I23:S23) -> 62000
A24: 4620 | B24: Trash | C24: 0 | D24: 0 | E24: 407.21 | F24: 407.21 | I24: 1000 | J24: 1000 | K24: 1000 | L24: 1000 | M24: 1000 | N24: 1000 | O24: 1000 | P24: 1000 | Q24: 1000 | R24: 1000 | S24: 1000 | T24: 1000 | U24: =SUM(I24:S24) -> 11000
A25: 4691 | B25: High Speed Internet Service | C25: 110 | D25: 110 | E25: 110 | F25: 330 | I25: 110 | J25: 110 | K25: 110 | L25: 110 | M25: 110 | N25: 110 | O25: 110 | P25: 110 | Q25: 110 | R25: 110 | S25: 110 | T25: 110 | U25: =SUM(I25:S25) -> 1210
A26: 4692 | B26: Telephone, Regular Service | C26: 85 | D26: 85 | E26: 85 | F26: 255 | I26: 85 | J26: 85 | K26: 85 | L26: 85 | M26: 85 | N26: 85 | O26: 85 | P26: 85 | Q26: 85 | R26: 85 | S26: 85 | T26: 85 | U26: =SUM(I26:S26) -> 935
B28: Utilities | C28: 3045.18 | D28: 4177.14 | E28: 6695.33 | F28: 13917.65 | I28: =SUM(I20:I26) -> 7240.68 | J28: =SUM(J20:J26) -> 8240.68 | K28: =SUM(K20:K26) -> 9740.68 | L28: =SUM(L20:L26) -> 9740.68 | M28: =SUM(M20:M26) -> 9740.68 | N28: =SUM(N20:N26) -> 9740.68 | O28: =SUM(O20:O26) -> 9740.68 | P28: =SUM(P20:P26) -> 9740.68 | ... T28: =SUM(T20:T26) -> 9740.68 | U28: =SUM(I28:S28) -> 103147.48
B29: Asset Management Subtotal | U29: =SUM(I29:S29) -> 0
A30: 4632 | B30: Offsite Services Fee | C30: 5000 | D30: 5000 | E30: 5000 | F30: 15000 | U30: =SUM(I30:S30) -> 0
B31: Total Property Management Subtotal | C31: 5000 | D31: 5000 | E31: 5000 | F31: 15000 | I31: 5000 | J31: 5000 | K31: 5000 | L31: 5000 | M31: 5000 | N31: 5000 | O31: 5000 | P31: 5000 | Q31: 5000 | R31: 5000 | S31: 5000 | T31: 5000 | U31: =SUM(I31:S31) -> 55000
B32: Advertising Subtotal | U32: =SUM(I32:S32) -> 0
A33: 4604 | B33: Exp Reim - Online Advertising | C33: 70.49 | D33: 69.5 | E33: 67.29 | F33: 207.28 | U33: =SUM(I33:S33) -> 0
A34: 4647 | B34: Print Advertising | C34: 204.83 | D34: 0 | E34: 0 | F34: 204.83 | U34: =SUM(I34:S34) -> 0
A35: 4649 | B35: Advertising Signs/Banners | C35: 0 | D35: 342.07 | E35: 0 | F35: 342.07 | U35: =SUM(I35:S35) -> 0
B36: Total Advertising Subtotal | C36: 275.32 | D36: 411.57 | E36: 67.29 | F36: 754.18 | I36: 4000 | J36: 4000 | K36: 4000 | L36: 4000 | M36: 2000 | N36: 2000 | O36: 2000 | P36: 2000 | Q36: 2000 | R36: 2000 | S36: 2000 | T36: 2000 | U36: =SUM(I36:S36) -> 30000
B37: Taxes & Licensing Subtotal | U37: =SUM(I37:S37) -> 0
A38: 4638 | B38: Annual Inspection - Fire | C38: 2008.18 | D38: 0 | E38: 0 | F38: 2008.18 | U38: =SUM(I38:S38) -> 0
A39: 4640 | B39: Taxes & Licenses | C39: 0 | D39: 0 | E39: 7293.74 | F39: 7293.74 | I39: 2431.2467 | J39: 2431.2467 | K39: 2431.2467 | L39: 2431.2467 | M39: 2431.2467 | N39: 2431.2467 | O39: 2431.2467 | P39: 2431.2467 | Q39: 2431.2467 | R39: 2431.2467 | S39: 2431.2467 | T39: 2431.2467 | U39: =SUM(I39:S39) -> 26743.713
A40: 4670 | B40: Property Tax | C40: 6004 | D40: 6004 | E40: 6004 | F40: 18012 | I40: 6004 | J40: 6004 | K40: 6004 | L40: 6004 | M40: 6004 | N40: 6004 | O40: 6004 | P40: 6004 | Q40: 6004 | R40: 6004 | S40: 6004 | T40: 6004 | U40: =SUM(I40:S40) -> 66044
B41: Total Taxes & Licensing Subtotal | C41: 8012.18 | D41: 6004 | E41: 13297.74 | F41: 27313.92 | I41: =SUM(I39:I40) -> 8435.2467 | J41: =SUM(J39:J40) -> 8435.2467 | K41: =SUM(K39:K40) -> 8435.2467 | L41: =SUM(L39:L40) -> 8435.2467 | M41: =SUM(M39:M40) -> 8435.2467 | N41: =SUM(N39:N40) -> 8435.2467 | O41: =SUM(O39:O40) -> 8435.2467 | P41: =SUM(P39:P40) -> 8435.2467 | ... T41: =SUM(T39:T40) -> 8435.2467 | U41: =SUM(I41:S41) -> 92787.713
...

Sheet Calculator
A1: Month | B1: 45986
A3: Oasis at San Marco
A4: 4800 Atlantic Blvd, Jacksonville, FL 32207
A5: 127 Unit Multifamily
C6: Now | D6: Per unit | E6: PSF
A7: INCOME | D7: 127 | E7: =#REF! -> #REF!
A8: Gross Potential Rent | C8: =#REF! -> #REF! | D8: =C8/$D$7 -> #REF! | E8: =C8/$E$7 -> #REF!
A9: Utility Reimbursements | C9: 83600 | D9: =C9/$D$7 -> 658.26772 | E9: =C9/$E$7 -> #REF!
A10: Trash Fee | C10: 13600 | D10: =C10/$D$7 -> 107.08661 | E10: =C10/$E$7 -> #REF!
A11: Pet Monthly Fee | C11: 4000 | D11: =C11/$D$7 -> 31.496063 | E11: =C11/$E$7 -> #REF!
A12: Pest Control Fee | C12: 8000 | D12: =C12/$D$7 -> 62.992126 | E12: =C12/$E$7 -> #REF!
A13: Laundry Income | C13: 5000 | D13: =C13/$D$7 -> 39.370079 | E13: =C13/$E$7 -> #REF!
A14: App/Late/Admin Fee | C14: 57000 | D14: =C14/$D$7 -> 448.8189 | E14: =C14/$E$7 -> #REF!
A15: Less Market Vacancy @ | B15: 0.08 | C15: =-SUM(C8)*B15 -> #REF! | D15: =C15/$D$7 -> #REF! | E15: =C15/$E$7 -> #REF!
A16: Effective Gross Inc. | C16: =SUM(C8:C15) -> #REF! | D16: =C16/$D$7 -> #REF! | E16: =C16/$E$7 -> #REF! | G16: =C16/12 -> #REF!
A18: EXPENSES
A19: Insurance
A20: R&M + Contract Services
A21: Water & Sewer | C21: 40000 | D21: =C21/$D$7 -> 314.96063 | E21: =C21/$E$7 -> #REF!
A22: Electric
A23: Electric - Common | C23: 14000 | D23: =C23/$D$7 -> 110.23622 | E23: =C23/$E$7 -> #REF!
A24: Garbage & Recycling
A25: Gas | C25: 2000 | D25: =C25/$D$7 -> 15.748031 | E25: =C25/$E$7 -> #REF!
A26: Admin + Advertising
A28: Management | B28: 0.03 | C28: =C16*B28 -> #REF! | D28: =C28/$D$7 -> #REF! | E28: =C28/$E$7 -> #REF! | G28: RE Assessment
A30: TOTAL OPERATING EXP. | C30: =SUM(C19:C28) -> #REF! | D30: =C30/$D$7 -> #REF! | E30: =C30/$E$7 -> #REF! | I30: RE Tax
G31: Assessment | H31: 0.75 | I31: 11518443
A32: RE TAXES (In-Place 160,038) | C32: 165000 | D32: =C32/$D$7 -> 1299.2126 | E32: =C32/$E$7 -> #REF! | G32: Mill rate @ | H32: 0.017865 | I32: 205777
A33: Replacement Reserves
A34: Payroll | C34: =D34*D7 -> 127000 | D34: 1000 | E34: =C34/$E$7 -> #REF!
A36: TOTAL EXPENSES
A38: NET OPERATING INCOME
A40: Value
A41: Cap Rate
A42: Max Perm Debt
A43: Loan to Value
A45: Debt Service Coverage Ratio
A46: Amount
A47: Rate
A48: Amortization
...

Sheet Budget Summary 2026
A1: Account Name | B1: 46023 | C1: =EDATE(B1, 1) -> 46054 | D1: =EDATE(C1, 1) -> 46082 | E1: =EDATE(D1, 1) -> 46113 | F1: =EDATE(E1, 1) -> 46143 | G1: =EDATE(F1, 1) -> 46174 | H1: =EDATE(G1, 1) -> 46204 | I1: =EDATE(H1, 1) -> 46235 | J1: =EDATE(I1, 1) -> 46266 | ... M1: =EDATE(L1, 1) -> 46357 | N1: Total
A2: Gross Potential Rent | B2: ='Worksheet - DO NOT DELETE'!B12 -> 159666 | C2: ='Worksheet - DO NOT DELETE'!C12 -> 159666 | D2: ='Worksheet - DO NOT DELETE'!D12 -> 159666 | E2: ='Worksheet - DO NOT DELETE'!E12 -> 159666 | F2: ='Worksheet - DO NOT DELETE'!F12 -> 159666 | G2: ='Worksheet - DO NOT DELETE'!G12 -> 159666 | H2: ='Worksheet - DO NOT DELETE'!H12 -> 159666 | I2: ='Worksheet - DO NOT DELETE'!I12 -> 159666 | ... M2: ='Worksheet - DO NOT DELETE'!M12 -> 159666 | N2: =SUM(B2:M2) -> 1915992
A3: Loss/Gain to Market | B3: ='Worksheet - DO NOT DELETE'!B16 -> -9750.12 | C3: ='Worksheet - DO NOT DELETE'!C16 -> -9750.12 | D3: ='Worksheet - DO NOT DELETE'!D16 -> -9375.3303 | E3: ='Worksheet - DO NOT DELETE'!E16 -> -9179.9524 | F3: ='Worksheet - DO NOT DELETE'!F16 -> -8984.3206 | G3: ='Worksheet - DO NOT DELETE'!G16 -> -8788.4344 | H3: ='Worksheet - DO NOT DELETE'!H16 -> -8516.8548 | I3: ='Worksheet - DO NOT DELETE'!I16 -> -8244.7863 | ... M3: ='Worksheet - DO NOT DELETE'!M16 -> -7699.0155 | N3: =SUM(B3:M3) -> -103932.52
A4: Concessions | B4: ='Worksheet - DO NOT DELETE'!B15-(B5+B6) -> 0 | C4: ='Worksheet - DO NOT DELETE'!C15-(C5+C6) -> -3541.32 | D4: ='Worksheet - DO NOT DELETE'!D15-(D5+D6) -> -9762.9766 | E4: ='Worksheet - DO NOT DELETE'!E15-(E5+E6) -> -1777.3943 | F4: ='Worksheet - DO NOT DELETE'!F15-(F5+F6) -> -2669.5573 | G4: ='Worksheet - DO NOT DELETE'!G15-(G5+G6) -> -2673.0277 | H4: ='Worksheet - DO NOT DELETE'!H15-(H5+H6) -> -1785.2261 | I4: ='Worksheet - DO NOT DELETE'!I15-(I5+I6) -> -1788.4395 | ... M4: ='Worksheet - DO NOT DELETE'!M15-(M5+M6) -> -897.44282 | N4: =SUM(B4:M4) -> -28480.315
A5: Concessions - Recurring | B5: -100 | C5: -100 | D5: -100 | E5: -100 | F5: -100 | G5: -100 | H5: -100 | I5: -100 | J5: -100 | K5: -100 | L5: -100 | M5: -100 | N5: =SUM(B5:M5) -> -1200
A6: Concessions - Employee Unit | B6: -210 | C6: -210 | D6: -210 | E6: -210 | F6: -210 | G6: -210 | H6: -210 | I6: -210 | J6: -210 | K6: -210 | L6: -210 | M6: -210 | N6: =SUM(B6:M6) -> -2520
A7: Vacancy | B7: ='Worksheet - DO NOT DELETE'!B13 -> -14165.28 | C7: ='Worksheet - DO NOT DELETE'!C13 -> -9443.52 | D7: ='Worksheet - DO NOT DELETE'!D13 -> -4733.5644 | E7: ='Worksheet - DO NOT DELETE'!E13 -> -4739.718 | F7: ='Worksheet - DO NOT DELETE'!F13 -> -4745.8797 | G7: ='Worksheet - DO NOT DELETE'!G13 -> -4752.0493 | H7: ='Worksheet - DO NOT DELETE'!H13 -> -4760.603 | I7: ='Worksheet - DO NOT DELETE'!I13 -> -4769.1721 | ... M7: ='Worksheet - DO NOT DELETE'!M13 -> -3589.7713 | N7: =SUM(B7:M7) -> -66455.961
A8: Bad Debt - Contra | B8: ='Worksheet - DO NOT DELETE'!B17 -> -11804.4 | C8: ='Worksheet - DO NOT DELETE'!C17 -> -11804.4 | D8: ='Worksheet - DO NOT DELETE'!D17 -> -15384.084 | E8: ='Worksheet - DO NOT DELETE'!E17 -> -1184.9295 | F8: ='Worksheet - DO NOT DELETE'!F17 -> -1186.4699 | G8: ='Worksheet - DO NOT DELETE'!G17 -> -1188.0123 | H8: ='Worksheet - DO NOT DELETE'!H17 -> -1190.1507 | I8: ='Worksheet - DO NOT DELETE'!I17 -> -1192.293 | ... M8: ='Worksheet - DO NOT DELETE'!M17 -> 0 | N8: =SUM(B8:M8) -> -48520.208
A9: Total Rental Income | B9: =SUM(B2:B8) -> 123636.2 | C9: =SUM(C2:C8) -> 124816.64 | D9: =SUM(D2:D8) -> 120100.04 | E9: =SUM(E2:E8) -> 142474.01 | F9: =SUM(F2:F8) -> 141769.77 | G9: =SUM(G2:G8) -> 141954.48 | H9: =SUM(H2:H8) -> 143103.17 | I9: =SUM(I2:I8) -> 143361.31 | ... M9: =SUM(M2:M8) -> 147169.77 | N9: =SUM(B9:M9) -> 1664883
A10: Other Income
A11: Lease Lock
A12: NSF Fees Collected | B12: 50 | C12: 50 | D12: 50 | E12: 50 | F12: 50 | G12: 50 | H12: 50 | I12: 50 | J12: 50 | K12: 50 | L12: 50 | M12: 50 | N12: =SUM(B12:M12) -> 600
A13: Late Fee | B13: 2100 | C13: 2100 | D13: 2100 | E13: 2100 | F13: 2100 | G13: 2100 | H13: 2100 | I13: 2100 | J13: 2100 | K13: 2100 | L13: 2100 | M13: 2100 | N13: =SUM(B13:M13) -> 25200
A14: Utility Income | N14: =SUM(B14:M14) -> 0
A15: Electricity Income | N15: =SUM(B15:M15) -> 0
A16: Utility Reimbursements | B16: 7360 | C16: 7360 | D16: 7360 | E16: 7360 | F16: 7360 | G16: 7360 | H16: 7360 | I16: 7360 | J16: 7360 | K16: 7360 | L16: 7360 | M16: 7360 | N16: =SUM(B16:M16) -> 88320
A17: Resident Liability & Contents Coverage | B17: 725 | C17: 725 | D17: 725 | E17: 725 | F17: 725 | G17: 725 | H17: 725 | I17: 725 | J17: 725 | K17: 725 | L17: 725 | M17: 725 | N17: =SUM(B17:M17) -> 8700
A18: 1st month - Resident Liability & Contents Coverage | N18: =SUM(B18:M18) -> 0
A19: AppFolio Insurance Admin Fee | B19: 185 | C19: 185 | D19: 185 | E19: 185 | F19: 185 | G19: 185 | H19: 185 | I19: 185 | J19: 185 | K19: 185 | L19: 185 | M19: 185 | N19: =SUM(B19:M19) -> 2220
A20: Pet Fee - Non Refundable | N20: =SUM(B20:M20) -> 0
A21: Bad Debt Recovery | N21: =SUM(B21:M21) -> 0
A22: Pet Application Fee | N22: =SUM(B22:M22) -> 0
A23: Monthly Pet Rent | B23: 480 | C23: 480 | D23: 480 | E23: 480 | F23: 480 | G23: 480 | H23: 480 | I23: 480 | J23: 480 | K23: 480 | L23: 480 | M23: 480 | N23: =SUM(B23:M23) -> 5760
A24: Admin Fee | B24: 150 | C24: 150 | D24: 150 | E24: 150 | F24: 150 | G24: 150 | H24: 150 | I24: 150 | J24: 150 | K24: 150 | L24: 150 | M24: 150 | N24: =SUM(B24:M24) -> 1800
A25: Early Lease Termination Fee | N25: =SUM(B25:M25) -> 0
A26: Application Fee Income | B26: 215 | C26: 215 | D26: 215 | E26: 215 | F26: 215 | G26: 215 | H26: 215 | I26: 215 | J26: 215 | K26: 215 | L26: 215 | M26: 215 | N26: =SUM(B26:M26) -> 2580
A27: Extended Month to Month Fee | B27: 200 | C27: 200 | D27: 200 | E27: 200 | F27: 200 | G27: 200 | H27: 200 | I27: 200 | J27: 200 | K27: 200 | L27: 200 | M27: 200 | N27: =SUM(B27:M27) -> 2400
A28: Move Out Charges | B28: 500 | C28: 500 | D28: 500 | E28: 500 | F28: 500 | G28: 500 | H28: 500 | I28: 500 | J28: 500 | K28: 500 | L28: 500 | M28: 500 | N28: =SUM(B28:M28) -> 6000
A29: Move In Charges - Misc | N29: =SUM(B29:M29) -> 0
A30: Resident Transfer fee | N30: =SUM(B30:M30) -> 0
A31: Laundry Income | B31: 500 | C31: 500 | D31: 500 | E31: 500 | F31: 500 | G31: 500 | H31: 500 | I31: 500 | J31: 500 | K31: 500 | L31: 500 | M31: 500 | N31: =SUM(B31:M31) -> 6000
A32: Miscellaneous Income | N32: =SUM(B32:M32) -> 0
A33: Misc Reimbursements | N33: =SUM(B33:M33) -> 0
A34: Damages | B34: 406 | C34: 406 | D34: 406 | E34: 406 | F34: 406 | G34: 406 | H34: 406 | I34: 406 | J34: 406 | K34: 406 | L34: 406 | M34: 406 | N34: =SUM(B34:M34) -> 4872
A35: Amenity Fee | B35: ='Worksheet - DO NOT DELETE'!B$5*15 -> 1575 | C35: ='Worksheet - DO NOT DELETE'!C$5*15 -> 1635 | D35: ='Worksheet - DO NOT DELETE'!D$5*15 -> 1650 | E35: ='Worksheet - DO NOT DELETE'!E$5*15 -> 1830 | F35: ='Worksheet - DO NOT DELETE'!F$5*15 -> 1830 | G35: ='Worksheet - DO NOT DELETE'!G$5*15 -> 1830 | H35: ='Worksheet - DO NOT DELETE'!H$5*15 -> 1830 | I35: ='Worksheet - DO NOT DELETE'!I$5*15 -> 1830 | ... M35: ='Worksheet - DO NOT DELETE'!M$5*15 -> 1860 | N35: =SUM(B35:M35) -> 21405
A36: Trash Fee | B36: ='Worksheet - DO NOT DELETE'!B$5*10 -> 1050 | C36: ='Worksheet - DO NOT DELETE'!C$5*10 -> 1090 | D36: ='Worksheet - DO NOT DELETE'!D$5*10 -> 1100 | E36: ='Worksheet - DO NOT DELETE'!E$5*10 -> 1220 | F36: ='Worksheet - DO NOT DELETE'!F$5*10 -> 1220 | G36: ='Worksheet - DO NOT DELETE'!G$5*10 -> 1220 | H36: ='Worksheet - DO NOT DELETE'!H$5*10 -> 1220 | I36: ='Worksheet - DO NOT DELETE'!I$5*10 -> 1220 | ... M36: ='Worksheet - DO NOT DELETE'!M$5*10 -> 1240 | N36: =SUM(B36:M36) -> 14270
A37: Pest Control Fee | B37: ='Worksheet - DO NOT DELETE'!B$5*5 -> 525 | C37: ='Worksheet - DO NOT DELETE'!C$5*5 -> 545 | D37: ='Worksheet - DO NOT DELETE'!D$5*5 -> 550 | E37: ='Worksheet - DO NOT DELETE'!E$5*5 -> 610 | F37: ='Worksheet - DO NOT DELETE'!F$5*5 -> 610 | G37: ='Worksheet - DO NOT DELETE'!G$5*5 -> 610 | H37: ='Worksheet - DO NOT DELETE'!H$5*5 -> 610 | I37: ='Worksheet - DO NOT DELETE'!I$5*5 -> 610 | ... M37: ='Worksheet - DO NOT DELETE'!M$5*5 -> 620 | N37: =SUM(B37:M37) -> 7135
A38: Maintenance Fee | N38: =SUM(B38:M38) -> 0
A39: Waiver Deposit Fee | B39: ='Worksheet - DO NOT DELETE'!B$5*28*0.35 -> 1029 | C39: ='Worksheet - DO NOT DELETE'!C$5*28*0.35 -> 1068.2 | D39: ='Worksheet - DO NOT DELETE'!D$5*28*0.35 -> 1078 | E39: ='Worksheet - DO NOT DELETE'!E$5*28*0.35 -> 1195.6 | F39: ='Worksheet - DO NOT DELETE'!F$5*28*0.35 -> 1195.6 | G39: ='Worksheet - DO NOT DELETE'!G$5*28*0.35 -> 1195.6 | H39: ='Worksheet - DO NOT DELETE'!H$5*28*0.35 -> 1195.6 | I39: ='Worksheet - DO NOT DELETE'!I$5*28*0.35 -> 1195.6 | ... M39: ='Worksheet - DO NOT DELETE'!M$5*28*0.35 -> 1215.2 | N39: =SUM(B39:M39) -> 13984.6
A40: PM Service Fee | B40: ='Worksheet - DO NOT DELETE'!B$5*3 -> 315 | C40: ='Worksheet - DO NOT DELETE'!C$5*3 -> 327 | D40: ='Worksheet - DO NOT DELETE'!D$5*3 -> 330 | E40: ='Worksheet - DO NOT DELETE'!E$5*3 -> 366 | F40: ='Worksheet - DO NOT DELETE'!F$5*3 -> 366 | G40: ='Worksheet - DO NOT DELETE'!G$5*3 -> 366 | H40: ='Worksheet - DO NOT DELETE'!H$5*3 -> 366 | I40: ='Worksheet - DO NOT DELETE'!I$5*3 -> 366 | ... M40: ='Worksheet - DO NOT DELETE'!M$5*3 -> 372 | N40: =SUM(B40:M40) -> 4281
...

Sheet Budget 2026
A1: Account Name | B1: 46023 | C1: =EDATE(B1, 1) -> 46054 | D1: =EDATE(C1, 1) -> 46082 | E1: =EDATE(D1, 1) -> 46113 | F1: =EDATE(E1, 1) -> 46143 | G1: =EDATE(F1, 1) -> 46174 | H1: =EDATE(G1, 1) -> 46204 | I1: =EDATE(H1, 1) -> 46235 | J1: =EDATE(I1, 1) -> 46266 | ... M1: =EDATE(L1, 1) -> 46357 | N1: Total
A2: Gross Potential Rent | B2: ='Worksheet - DO NOT DELETE'!B12 -> 159666 | C2: ='Worksheet - DO NOT DELETE'!C12 -> 159666 | D2: ='Worksheet - DO NOT DELETE'!D12 -> 159666 | E2: ='Worksheet - DO NOT DELETE'!E12 -> 159666 | F2: ='Worksheet - DO NOT DELETE'!F12 -> 159666 | G2: ='Worksheet - DO NOT DELETE'!G12 -> 159666 | H2: ='Worksheet - DO NOT DELETE'!H12 -> 159666 | I2: ='Worksheet - DO NOT DELETE'!I12 -> 159666 | ... M2: ='Worksheet - DO NOT DELETE'!M12 -> 159666 | N2: =SUM(B2:M2) -> 1915992
A3: Loss/Gain to Market | B3: ='Worksheet - DO NOT DELETE'!B16 -> -9750.12 | C3: ='Worksheet - DO NOT DELETE'!C16 -> -9750.12 | D3: ='Worksheet - DO NOT DELETE'!D16 -> -9375.3303 | E3: ='Worksheet - DO NOT DELETE'!E16 -> -9179.9524 | F3: ='Worksheet - DO NOT DELETE'!F16 -> -8984.3206 | G3: ='Worksheet - DO NOT DELETE'!G16 -> -8788.4344 | H3: ='Worksheet - DO NOT DELETE'!H16 -> -8516.8548 | I3: ='Worksheet - DO NOT DELETE'!I16 -> -8244.7863 | ... M3: ='Worksheet - DO NOT DELETE'!M16 -> -7699.0155 | N3: =SUM(B3:M3) -> -103932.52
A4: Concessions | B4: ='Worksheet - DO NOT DELETE'!B15-(B5+B6) -> 0 | C4: ='Worksheet - DO NOT DELETE'!C15-(C5+C6) -> -3541.32 | D4: ='Worksheet - DO NOT DELETE'!D15-(D5+D6) -> -9762.9766 | E4: ='Worksheet - DO NOT DELETE'!E15-(E5+E6) -> -1777.3943 | F4: ='Worksheet - DO NOT DELETE'!F15-(F5+F6) -> -2669.5573 | G4: ='Worksheet - DO NOT DELETE'!G15-(G5+G6) -> -2673.0277 | H4: ='Worksheet - DO NOT DELETE'!H15-(H5+H6) -> -1785.2261 | I4: ='Worksheet - DO NOT DELETE'!I15-(I5+I6) -> -1788.4395 | ... M4: ='Worksheet - DO NOT DELETE'!M15-(M5+M6) -> -897.44282 | N4: =SUM(B4:M4) -> -28480.315
A5: Concessions - Recurring | B5: -100 | C5: -100 | D5: -100 | E5: -100 | F5: -100 | G5: -100 | H5: -100 | I5: -100 | J5: -100 | K5: -100 | L5: -100 | M5: -100 | N5: =SUM(B5:M5) -> -1200
A6: Concessions - Employee Unit | B6: -210 | C6: -210 | D6: -210 | E6: -210 | F6: -210 | G6: -210 | H6: -210 | I6: -210 | J6: -210 | K6: -210 | L6: -210 | M6: -210 | N6: =SUM(B6:M6) -> -2520
A7: Vacancy | B7: ='Worksheet - DO NOT DELETE'!B13 -> -14165.28 | C7: ='Worksheet - DO NOT DELETE'!C13 -> -9443.52 | D7: ='Worksheet - DO NOT DELETE'!D13 -> -4733.5644 | E7: ='Worksheet - DO NOT DELETE'!E13 -> -4739.718 | F7: ='Worksheet - DO NOT DELETE'!F13 -> -4745.8797 | G7: ='Worksheet - DO NOT DELETE'!G13 -> -4752.0493 | H7: ='Worksheet - DO NOT DELETE'!H13 -> -4760.603 | I7: ='Worksheet - DO NOT DELETE'!I13 -> -4769.1721 | ... M7: ='Worksheet - DO NOT DELETE'!M13 -> -3589.7713 | N7: =SUM(B7:M7) -> -66455.961
A8: Bad Debt - Contra | B8: ='Worksheet - DO NOT DELETE'!B17 -> -11804.4 | C8: ='Worksheet - DO NOT DELETE'!C17 -> -11804.4 | D8: ='Worksheet - DO NOT DELETE'!D17 -> -15384.084 | E8: ='Worksheet - DO NOT DELETE'!E17 -> -1184.9295 | F8: ='Worksheet - DO NOT DELETE'!F17 -> -1186.4699 | G8: ='Worksheet - DO NOT DELETE'!G17 -> -1188.0123 | H8: ='Worksheet - DO NOT DELETE'!H17 -> -1190.1507 | I8: ='Worksheet - DO NOT DELETE'!I17 -> -1192.293 | ... M8: ='Worksheet - DO NOT DELETE'!M17 -> 0 | N8: =SUM(B8:M8) -> -48520.208
A9: Total Rental Income | B9: =SUM(B2:B8) -> 123636.2 | C9: =SUM(C2:C8) -> 124816.64 | D9: =SUM(D2:D8) -> 120100.04 | E9: =SUM(E2:E8) -> 142474.01 | F9: =SUM(F2:F8) -> 141769.77 | G9: =SUM(G2:G8) -> 141954.48 | H9: =SUM(H2:H8) -> 143103.17 | I9: =SUM(I2:I8) -> 143361.31 | ... M9: =SUM(M2:M8) -> 147169.77 | N9: =SUM(B9:M9) -> 1664883
A10: Other Income
A11: Lease Lock
A12: NSF Fees Collected | B12: 50 | C12: 50 | D12: 50 | E12: 50 | F12: 50 | G12: 50 | H12: 50 | I12: 50 | J12: 50 | K12: 50 | L12: 50 | M12: 50 | N12: =SUM(B12:M12) -> 600
A13: Late Fee | B13: 2100 | C13: 2100 | D13: 2100 | E13: 2100 | F13: 2100 | G13: 2100 | H13: 2100 | I13: 2100 | J13: 2100 | K13: 2100 | L13: 2100 | M13: 2100 | N13: =SUM(B13:M13) -> 25200
A14: Utility Income | N14: =SUM(B14:M14) -> 0
A15: Electricity Income | N15: =SUM(B15:M15) -> 0
A16: Utility Reimbursements | B16: 7360 | C16: 7360 | D16: 7360 | E16: 7360 | F16: 7360 | G16: 7360 | H16: 7360 | I16: 7360 | J16: 7360 | K16: 7360 | L16: 7360 | M16: 7360 | N16: =SUM(B16:M16) -> 88320
A17: Resident Liability & Contents Coverage | B17: 725 | C17: 725 | D17: 725 | E17: 725 | F17: 725 | G17: 725 | H17: 725 | I17: 725 | J17: 725 | K17: 725 | L17: 725 | M17: 725 | N17: =SUM(B17:M17) -> 8700
A18: 1st month - Resident Liability & Contents Coverage | N18: =SUM(B18:M18) -> 0
A19: AppFolio Insurance Admin Fee | B19: 185 | C19: 185 | D19: 185 | E19: 185 | F19: 185 | G19: 185 | H19: 185 | I19: 185 | J19: 185 | K19: 185 | L19: 185 | M19: 185 | N19: =SUM(B19:M19) -> 2220
A20: Pet Fee - Non Refundable | N20: =SUM(B20:M20) -> 0
A21: Bad Debt Recovery | N21: =SUM(B21:M21) -> 0
A22: Pet Application Fee | N22: =SUM(B22:M22) -> 0
A23: Monthly Pet Rent | B23: 480 | C23: 480 | D23: 480 | E23: 480 | F23: 480 | G23: 480 | H23: 480 | I23: 480 | J23: 480 | K23: 480 | L23: 480 | M23: 480 | N23: =SUM(B23:M23) -> 5760
A24: Admin Fee | B24: 150 | C24: 150 | D24: 150 | E24: 150 | F24: 150 | G24: 150 | H24: 150 | I24: 150 | J24: 150 | K24: 150 | L24: 150 | M24: 150 | N24: =SUM(B24:M24) -> 1800
A25: Early Lease Termination Fee | N25: =SUM(B25:M25) -> 0
A26: Application Fee Income | B26: 215 | C26: 215 | D26: 215 | E26: 215 | F26: 215 | G26: 215 | H26: 215 | I26: 215 | J26: 215 | K26: 215 | L26: 215 | M26: 215 | N26: =SUM(B26:M26) -> 2580
A27: Extended Month to Month Fee | B27: 200 | C27: 200 | D27: 200 | E27: 200 | F27: 200 | G27: 200 | H27: 200 | I27: 200 | J27: 200 | K27: 200 | L27: 200 | M27: 200 | N27: =SUM(B27:M27) -> 2400
A28: Move Out Charges | B28: 500 | C28: 500 | D28: 500 | E28: 500 | F28: 500 | G28: 500 | H28: 500 | I28: 500 | J28: 500 | K28: 500 | L28: 500 | M28: 500 | N28: =SUM(B28:M28) -> 6000
A29: Move In Charges - Misc | N29: =SUM(B29:M29) -> 0
A30: Resident Transfer fee | N30: =SUM(B30:M30) -> 0
A31: Laundry Income | B31: 500 | C31: 500 | D31: 500 | E31: 500 | F31: 500 | G31: 500 | H31: 500 | I31: 500 | J31: 500 | K31: 500 | L31: 500 | M31: 500 | N31: =SUM(B31:M31) -> 6000
A32: Miscellaneous Income | N32: =SUM(B32:M32) -> 0
A33: Misc Reimbursements | N33: =SUM(B33:M33) -> 0
A34: Damages | B34: 406 | C34: 406 | D34: 406 | E34: 406 | F34: 406 | G34: 406 | H34: 406 | I34: 406 | J34: 406 | K34: 406 | L34: 406 | M34: 406 | N34: =SUM(B34:M34) -> 4872
A35: Amenity Fee | B35: ='Worksheet - DO NOT DELETE'!B$5*15 -> 1575 | C35: ='Worksheet - DO NOT DELETE'!C$5*15 -> 1635 | D35: ='Worksheet - DO NOT DELETE'!D$5*15 -> 1650 | E35: ='Worksheet - DO NOT DELETE'!E$5*15 -> 1830 | F35: ='Worksheet - DO NOT DELETE'!F$5*15 -> 1830 | G35: ='Worksheet - DO NOT DELETE'!G$5*15 -> 1830 | H35: ='Worksheet - DO NOT DELETE'!H$5*15 -> 1830 | I35: ='Worksheet - DO NOT DELETE'!I$5*15 -> 1830 | ... M35: ='Worksheet - DO NOT DELETE'!M$5*15 -> 1860 | N35: =SUM(B35:M35) -> 21405
A36: Trash Fee | B36: ='Worksheet - DO NOT DELETE'!B$5*10 -> 1050 | C36: ='Worksheet - DO NOT DELETE'!C$5*10 -> 1090 | D36: ='Worksheet - DO NOT DELETE'!D$5*10 -> 1100 | E36: ='Worksheet - DO NOT DELETE'!E$5*10 -> 1220 | F36: ='Worksheet - DO NOT DELETE'!F$5*10 -> 1220 | G36: ='Worksheet - DO NOT DELETE'!G$5*10 -> 1220 | H36: ='Worksheet - DO NOT DELETE'!H$5*10 -> 1220 | I36: ='Worksheet - DO NOT DELETE'!I$5*10 -> 1220 | ... M36: ='Worksheet - DO NOT DELETE'!M$5*10 -> 1240 | N36: =SUM(B36:M36) -> 14270
A37: Pest Control Fee | B37: ='Worksheet - DO NOT DELETE'!B$5*5 -> 525 | C37: ='Worksheet - DO NOT DELETE'!C$5*5 -> 545 | D37: ='Worksheet - DO NOT DELETE'!D$5*5 -> 550 | E37: ='Worksheet - DO NOT DELETE'!E$5*5 -> 610 | F37: ='Worksheet - DO NOT DELETE'!F$5*5 -> 610 | G37: ='Worksheet - DO NOT DELETE'!G$5*5 -> 610 | H37: ='Worksheet - DO NOT DELETE'!H$5*5 -> 610 | I37: ='Worksheet - DO NOT DELETE'!I$5*5 -> 610 | ... M37: ='Worksheet - DO NOT DELETE'!M$5*5 -> 620 | N37: =SUM(B37:M37) -> 7135
A38: Maintenance Fee | N38: =SUM(B38:M38) -> 0
A39: Waiver Deposit Fee | B39: ='Worksheet - DO NOT DELETE'!B$5*28*0.35 -> 1029 | C39: ='Worksheet - DO NOT DELETE'!C$5*28*0.35 -> 1068.2 | D39: ='Worksheet - DO NOT DELETE'!D$5*28*0.35 -> 1078 | E39: ='Worksheet - DO NOT DELETE'!E$5*28*0.35 -> 1195.6 | F39: ='Worksheet - DO NOT DELETE'!F$5*28*0.35 -> 1195.6 | G39: ='Worksheet - DO NOT DELETE'!G$5*28*0.35 -> 1195.6 | H39: ='Worksheet - DO NOT DELETE'!H$5*28*0.35 -> 1195.6 | I39: ='Worksheet - DO NOT DELETE'!I$5*28*0.35 -> 1195.6 | ... M39: ='Worksheet - DO NOT DELETE'!M$5*28*0.35 -> 1215.2 | N39: =SUM(B39:M39) -> 13984.6
A40: PM Service Fee | B40: ='Worksheet - DO NOT DELETE'!B$5*3 -> 315 | C40: ='Worksheet - DO NOT DELETE'!C$5*3 -> 327 | D40: ='Worksheet - DO NOT DELETE'!D$5*3 -> 330 | E40: ='Worksheet - DO NOT DELETE'!E$5*3 -> 366 | F40: ='Worksheet - DO NOT DELETE'!F$5*3 -> 366 | G40: ='Worksheet - DO NOT DELETE'!G$5*3 -> 366 | H40: ='Worksheet - DO NOT DELETE'!H$5*3 -> 366 | I40: ='Worksheet - DO NOT DELETE'!I$5*3 -> 366 | ... M40: ='Worksheet - DO NOT DELETE'!M$5*3 -> 372 | N40: =SUM(B40:M40) -> 4281
...

Sheet 2026 Budget Analysis
A13: Income analysis and projection for 2026 Budget
F14: ATRIUM vs Ownership version of the budget
B15: 2026 Atrium Budget | C15: 2026 T-1 Expenses Baseline | D15: 2026 Ownership budget | E15: Reviewed and Final | F15: Diff ($) | G15: Diff (%) | H15: Rationale
A16: Rent | B16: 1488447 | C16: 38500 | D16: ='Budget Summary 2026'!N9 -> 1664883 | E16: Yes, by Claudio Sanchez | F16: =B16-D16 -> -176436 | G16: =F16/B16 -> -0.11853697 | H16: Atrium's income projections are equivalent to the asset being in the mid 80% ecc. Occupancy.
A17: Other Income | B17: 225656 | C17: 58248 | D17: ='Budget Summary 2026'!N44 -> 214206.6 | E17: Yes, by Claudio Sanchez | F17: =B17-D17 -> 11449.4 | G17: =F17/B17 -> 0.050738292 | H17: Atrium other income has a larger portion of Late fee, early termination fees
B18: =SUM(B16:B17) -> 1714103 | C18: 797178 | D18: =SUM(D16:D17) -> 1879089.6 | F18: =B18-D18 -> -164986.6 | G18: =F18/B18 -> -0.096252443
A25: Expense analysis and projection for 2026 Budget
F26: ATRIUM vs Ownership version of the budget
B27: 2026 Atrium Budget | C27: 2026 T-1 Expenses Baseline | D27: 2026 Ownership budget | E27: Reviewed and Final | F27: Diff ($) | G27: Diff (%) | H27: Rationale
A28: Advertising | B28: 16000 | C28: 38500 | D28: ='Budget 2026'!N96 -> 38311.95 | E28: Yes, by Claudio Sanchez | F28: =B28-D28 -> -22311.95 | G28: =F28/B28 -> -1.3944969 | H28: Elimited one-time expenses in T-12, left with only Apts.com and Zillow.com
A29: Contract Services | B29: 58248 | C29: 58248 | D29: ='Budget 2026'!N122 -> 63554.09 | E29: Yes, by Claudio Sanchez | F29: =B29-D29 -> -5306.09 | G29: =F29/B29 -> -0.091094802 | H29: More in-line with last 6 mo pattern
A30: Repair and Maintenance | B30: 52620 | C30: 52620 | D30: ='Budget 2026'!N110 -> 39924 | E30: Yes, by Claudio Sanchez | F30: =B30-D30 -> 12696 | G30: =F30/B30 -> 0.24127708 | H30: More in-line with last 6 mo pattern
A31: Turn Over | B31: 34528 | C31: 34528 | D31: ='Budget 2026'!N86 -> 31870 | E31: Yes, by Claudio Sanchez | F31: =B31-D31 -> 2658 | G31: =F31/B31 -> 0.076981001 | H31: Less turn over as we are estabilized
A32: Utilities | B32: 78420 | C32: 78420 | D32: ='Budget 2026'!N131 -> 60346.56 | E32: Yes, by Claudio Sanchez | F32: =B32-D32 -> 18073.44 | G32: =F32/B32 -> 0.23046978 | H32: Optivo's T-12 includes lots of irregular payments. They were always late paying bills
A33: General/Admin | B33: 29342 | C33: 29342 | D33: ='Budget 2026'!N77 -> 37771.77 | E33: Yes, by Claudio Sanchez | F33: =B33-D33 -> -8429.77 | G33: =F33/B33 -> -0.28729364
A34: Insurance | B34: 95000 | C34: 94100 | D34: ='Budget 2026'!N133 -> 102000 | E34: Yes, by Claudio Sanchez | F34: =B34-D34 -> -7000 | G34: =F34/B34 -> -0.073684211
A35: RE Taxes | B35: 165000 | C35: 165500 | D35: ='Budget 2026'!N134 -> 151680 | E35: Yes, by Claudio Sanchez | F35: =B35-D35 -> 13320 | G35: =F35/B35 -> 0.080727273
A36: Legal | B36: 3960 | C36: 3960 | D36: 0 | E36: Yes, by Claudio Sanchez | F36: =B36-D36 -> 3960 | G36: =F36/B36 -> 1 | H36: Legal is covered inside of Admin Expenses Already.
A37: Payroll | B37: 153837 | C37: 151960 | D37: ='Budget 2026'!N151 -> 152400.4 | E37: Yes, by Claudio Sanchez | F37: =B37-D37 -> 1436.6 | G37: =F37/B37 -> 0.0093384556 | H37: We need review this ENTIRE CATEGORY W/ ATRIUM
A38: PM Fees | B38: 54000 | C38: 54000 | D38: ='Budget 2026'!N51 -> 57337.816 | E38: Yes, by Claudio Sanchez | F38: =B38-D38 -> -3337.8155 | G38: =F38/B38 -> -0.061811398
A39: Deposit to Replacement Reserves | B39: 0 | E39: Yes, by Claudio Sanchez | F39: =B39-D39 -> 0
B40: =SUM(B28:B39) -> 740955 | C40: 797178 | D40: =SUM(D28:D39) -> 735196.59 | F40: =B40-D40 -> 5758.4145 | G40: =F40/B40 -> 0.0077716116
A41: Expense to Income | B41: =B40/B18 -> 0.43226982 | D41: =D40/D18 -> 0.39125148
A42: NOI | B42: =B18-B40 -> 973148 | C42: =C18-C40 -> 0 | D42: =D18-D40 -> 1143893
A43: Valuation at 6.5% Cap rate | B43: =B42/6.5% -> 14971508 | D43: =D42/6.5% -> 17598354
A44: Impact to Valuation | B44: =B43-D43 -> -2626846.4
A50: Average EGI per Unit (Annual) | B50: =(B16/127)/12 -> 976.67126 | D50: =(D16/127)/12 -> 1092.4429
A51: Other Income Per Unit (Annual) | B51: =B17/127 -> 1776.8189 | C51: =C17/127 -> 458.64567 | D51: =D17/127 -> 1686.6661
A52: Other Income Per Unit (in relation to EGI) | B52: =B17/B16 -> 0.151605 | D52: =D17/D16 -> 0.12866165
A53: Vacancy (Annualized)

Sheet Agency vs HUD
A2: Agency Debt Modeling | D2: HUD 223(f) | AB2: SALE
D3: HUD Note Rate | E3: 0.0625 | H3: 2026 | V3: 2027 | X3: 2028 | Z3: 2029 | AB3: 2030
D4: Amortization (Years) | E4: 35 | H4: ='Budget 2026'!B1 -> 46023 | I4: ='Budget 2026'!C1 -> 46054 | J4: ='Budget 2026'!D1 -> 46082 | K4: ='Budget 2026'!E1 -> 46113 | L4: ='Budget 2026'!F1 -> 46143 | M4: ='Budget 2026'!G1 -> 46174 | N4: ='Budget 2026'!H1 -> 46204 | O4: ='Budget 2026'!I1 -> 46235 | ... S4: ='Budget 2026'!M1 -> 46357 | T4: Year 3 | V4: Year 4 | X4: Year 5 | Z4: Year 6 | AB4: Year 7 | AE4: EXIT at Year 7
A5: T-5 Treasury | B5: 0.0372 | D5: HUD Min DSCR | E5: 1.176 | G5: Financial Assumptions | O5: REFINANCE | AT5: Source | AU5: Source | AV5: Source | AW5: Source | AX5: Source | AY5: Source | AZ5: Source | BA5: Source | BB5: Source
A6: Spread | B6: 0.0155 | D6: HUD Max LTV | E6: 0.85 | G6: Annual Rent Escalator | V6: 0.04 | X6: 0.03 | Z6: 0.03 | AB6: 0.03 | AE6: Sale | AT6: T-12 | AU6: T-12 | AV6: T-12 | AW6: T-12
A7: Interest Rate | B7: =SUM(B5:B6) -> 0.0527 | D7: RR $/Unit/Yr (PCA placeholder) | E7: 350 | G7: Annual Expense Escalator | V7: 0.02 | X7: 0.02 | Z7: 0.02 | AB7: 0.02 | AE7: Net Operating Income | AF7: =Z34 -> 1525849.7 | AH7: Capital Invested | AL7: =AG37 -> 6047500 | AT7: Sept-25 | AU7: 46320 | AV7: 46351 | AW7: DEC | AX7: JAN | AY7: FEB | AZ7: MAR | BA7: APR | BB7: MAY
D8: Initial RR Deposit (Months) | E8: 12 | AE8: Exit Cap Rate | AF8: 0.07 | AH8: Limited Partner Returns | AS8: Gross Potential Rent (GPR) | AT8: 136185.3 | AU8: 139780.78 | AV8: 143362 | AW8: =AV8 -> 143362 | AX8: =AW8 -> 143362 | AY8: =AX8 -> 143362 | AZ8: =AY8 -> 143362 | BA8: =AZ8 -> 143362 | BB8: =BA8 -> 143362
A9: Refinance - Agency | D9: HUD Financing Costs % (all-in) | E9: 0.04 | G9: INCOME | T9: In-Place Rent | V9: In-Place Rent | X9: In-Place Rent | Z9: In-Place Rent | AB9: In-Place Rent | AE9: Insurance/Tax/Lender Escrows | AF9: 0 | AH9: Return of Capital | AL9: =AG37 -> 6047500 | AS9: - Vacancy | AT9: -17406.1 | AU9: -5336.53 | AV9: -8718.07 | AW9: -6599.14 | AX9: -3377 | AY9: -3377 | AZ9: -3377 | BA9: -3377 | BB9: -3377
A10: Units | B10: 127 | G10: Average In-Place Rent | T10: =(T17/$B$10)/12 -> 1092.4429 | V10: =(V17/$B$10)/12 -> 1242.126 | X10: =(X17/$B$10)/12 -> 1279.3898 | Z10: =(Z17/$B$10)/12 -> 1317.7715 | AB10: =(AB17/$B$10)/12 -> 1357.3047 | AE10: Total Equity Outstanding | AF10: =-AF30-AG32 -> 3568460.5 | AH10: Preferred returns | AL10: =AH37 -> 0 | AS10: - Concessions, Loss to Lease, Bad Debt | AT10: =SUM(AT11:AT13) -> -33231 | AU10: =SUM(AU11:AU13) -> -31462.9 | AV10: =SUM(AV11:AV13) -> -13600 | AW10: =SUM(AW11:AW13) -> -20106.11 | AX10: =SUM(AX11:AX13) -> -13412 | AY10: =SUM(AY11:AY13) -> -13412 | AZ10: =SUM(AZ11:AZ13) -> -11412 | BA10: =SUM(BA11:BA13) -> -8412 | BB10: =SUM(BB11:BB13) -> -6412
A11: Min DSCR | B11: 1.25 | D11: Amourt Months | E11: =E4*12 -> 420 | G11: Gross Potential Rent (GPR) | H11: ='Budget 2026'!B2 -> 159666 | I11: ='Budget 2026'!C2 -> 159666 | J11: ='Budget 2026'!D2 -> 159666 | K11: ='Budget 2026'!E2 -> 159666 | L11: ='Budget 2026'!F2 -> 159666 | M11: ='Budget 2026'!G2 -> 159666 | N11: ='Budget 2026'!H2 -> 159666 | O11: ='Budget 2026'!I2 -> 159666 | ... S11: ='Budget 2026'!M2 -> 159666 | T11: =SUM(H11:S11) -> 1915992 | V11: =T11*(1+V6) -> 1992631.7 | X11: =V11*(1+X6) -> 2052410.6 | Z11: =X11*(1+Z6) -> 2113982.9 | AB11: =Z11*(1+AB6) -> 2177402.4 | AH11: From Cash Flow | AL11: =AI37 -> 1621350.2 | AS11: Consessions | AT11: -17426 | AU11: =-(19220+410) -> -19630 | AV11: =-(11590+310) -> -11900 | AW11: -919 | AX11: -1712 | AY11: -1712 | AZ11: -1712 | BA11: -1712 | BB11: -1712
A12: Max LTV | B12: 0.75 | G12: - Vacancy | H12: ='Budget 2026'!B7 -> -14165.28 | I12: ='Budget 2026'!C7 -> -9443.52 | J12: ='Budget 2026'!D7 -> -4733.5644 | K12: ='Budget 2026'!E7 -> -4739.718 | L12: ='Budget 2026'!F7 -> -4745.8797 | M12: ='Budget 2026'!G7 -> -4752.0493 | N12: ='Budget 2026'!H7 -> -4760.603 | O12: ='Budget 2026'!I7 -> -4769.1721 | ... S12: ='Budget 2026'!M7 -> -3589.7713 | T12: =SUM(H12:S12) -> -66455.961 | U12: =ABS(T12/$T$11) -> 0.034684885 | V12: =-V11*W12 -> -19926.317 | W12: 0.01 | X12: =-X11*Y12 -> -41048.213 | Y12: 0.02 | Z12: =-Z11*AA12 -> -42279.659 | AA12: 0.02 | AB12: =-AB11*AC12 -> -43548.049 | AC12: 0.02 | AE12: Sales Price | AF12: =AF7/AF8 -> 21797854 | AG12: =AF12/B10 -> 171636.64 | AH12: From Sales Proceeds | AL12: =AK36 -> 2136890.7 | AS12: Loss To Lease | AT12: =856 -> 856 | AU12: -158.9 | AV12: -1700 | AW12: -4847.11 | AX12: -1700 | AY12: -1700 | AZ12: -1700 | BA12: -1700 | BB12: -1700
A13: Interest rate | B13: =B7 -> 0.0527 | G13: - Concessions, Loss to Lease, Bad Debt | T13: =SUM(H13:S13) -> 0 | V13: =-V11*W13 -> -79705.267 | W13: 0.04 | X13: =-X11*Y13 -> -61572.319 | Y13: 0.03 | Z13: =-Z11*AA13 -> -63419.488 | AA13: 0.03 | AB13: =-AB11*AC13 -> -65322.073 | AC13: 0.03 | AE13: Operating Reserves Remaining | AF13: =SUM(T45:AB45) -> 180000 | AG13: =AF13/B10 -> 1417.3228 | AH13: Total Distributions | AL13: =SUM(AL9:AL12) -> 9805740.9 | AS13: Bad Debt | AT13: -16661 | AU13: -11674 | AV13: 0 | AW13: -14340 | AX13: -10000 | AY13: -10000 | AZ13: -8000 | BA13: -5000 | BB13: -3000
A14: Cap rate | B14: 0.065 | G14: Consessions | H14: =SUM('Budget 2026'!B4:B6) -> -310 | I14: =SUM('Budget 2026'!C4:C6) -> -3851.32 | J14: =SUM('Budget 2026'!D4:D6) -> -10072.977 | K14: =SUM('Budget 2026'!E4:E6) -> -2087.3943 | L14: =SUM('Budget 2026'!F4:F6) -> -2979.5573 | M14: =SUM('Budget 2026'!G4:G6) -> -2983.0277 | N14: =SUM('Budget 2026'!H4:H6) -> -2095.2261 | O14: =SUM('Budget 2026'!I4:I6) -> -2098.4395 | ... S14: =SUM('Budget 2026'!M4:M6) -> -1207.4428 | T14: =SUM(H14:S14) -> -32200.315 | U14: =ABS(T14/$T$11) -> 0.01680608 | AE14: Pref/Mezz Principal Payoff | AF14: =-B62 -> 0 | AS14: Gross Potential Income (GPI) | AT14: =SUM(AT8:AT10) -> 85548.2 | AU14: =SUM(AU8:AU10) -> 102981.35 | AV14: =SUM(AV8:AV10) -> 121043.93 | AW14: =SUM(AW8:AW10) -> 116656.75 | AX14: =SUM(AX8:AX10) -> 126573 | AY14: =SUM(AY8:AY10) -> 126573 | AZ14: =SUM(AZ8:AZ10) -> 128573 | BA14: =SUM(BA8:BA10) -> 131573 | BB14: =SUM(BB8:BB10) -> 133573
A15: Income (MAY-JUL '26) | B15: =SUM(L19:N19)*4 -> 1926748.9 | D15: Income (MAY-JUL '26) | E15: =T19 -> 1879089.6 | G15: Loss To Lease | H15: ='Budget 2026'!B3 -> -9750.12 | I15: ='Budget 2026'!C3 -> -9750.12 | J15: ='Budget 2026'!D3 -> -9375.3303 | K15: ='Budget 2026'!E3 -> -9179.9524 | L15: ='Budget 2026'!F3 -> -8984.3206 | M15: ='Budget 2026'!G3 -> -8788.4344 | N15: ='Budget 2026'!H3 -> -8516.8548 | O15: ='Budget 2026'!I3 -> -8244.7863 | ... S15: ='Budget 2026'!M3 -> -7699.0155 | T15: =SUM(H15:S15) -> -103932.52 | U15: =ABS(T15/$T$11) -> 0.054244754 | AE15: Defferred Interest Pref/Mezz Payoff | AF15: =-B68*3 -> 0 | AH15: LP Metrics | AS15: Other Income | AT15: 13112.8 | AU15: 13988.72 | AV15: 17456.19 | AW15: 13773.1 | AX15: 14839 | AY15: 14839 | AZ15: 14839 | BA15: 14839 | BB15: 14839
A16: Expenses (MAY-JUL '26) | B16: =SUM(L32:N32)*4 -> 709184.39 | D16: Expenses (MAY-JUL '26) | E16: =T32 -> 734656.41 | G16: Bad Debt | H16: ='Budget 2026'!B8 -> -11804.4 | I16: ='Budget 2026'!C8 -> -11804.4 | J16: ='Budget 2026'!D8 -> -15384.084 | K16: ='Budget 2026'!E8 -> -1184.9295 | L16: ='Budget 2026'!F8 -> -1186.4699 | M16: ='Budget 2026'!G8 -> -1188.0123 | N16: ='Budget 2026'!H8 -> -1190.1507 | O16: ='Budget 2026'!I8 -> -1192.293 | ... S16: ='Budget 2026'!M8 -> 0 | T16: =SUM(H16:S16) -> -48520.208 | U16: =ABS(T16/$T$11) -> 0.025323805 | AE16: Sales Cost at 4% | AF16: =-AF12*4% -> -871914.14 | AG16: =AF16/B10 -> -6865.4657 | AH16: Equity Multiple | AL16: =(AL13/AL7) -> 1.6214536 | AS16: Effective Gross Income | AT16: =SUM(AT14:AT15) -> 98661 | AU16: =SUM(AU14:AU15) -> 116970.07 | AV16: =SUM(AV14:AV15) -> 138500.12 | AW16: =SUM(AW14:AW15) -> 130429.85 | AX16: =SUM(AX14:AX15) -> 141412 | AY16: =SUM(AY14:AY15) -> 141412 | AZ16: =SUM(AZ14:AZ15) -> 143412 | BA16: =SUM(BA14:BA15) -> 146412 | BB16: =SUM(BB14:BB15) -> 148412
A17: NOI | B17: =B15-B16 -> 1217564.5 | D17: NOI | E17: =E15-E16 -> 1144433.2 | G17: Gross Potential Income (GPI) | H17: =SUM(H11:H16) -> 123636.2 | I17: =SUM(I11:I16) -> 124816.64 | J17: =SUM(J11:J16) -> 120100.04 | K17: =SUM(K11:K16) -> 142474.01 | L17: =SUM(L11:L16) -> 141769.77 | M17: =SUM(M11:M16) -> 141954.48 | N17: =SUM(N11:N16) -> 143103.17 | O17: =SUM(O11:O16) -> 143361.31 | ... S17: =SUM(S11:S16) -> 147169.77 | T17: =SUM(H17:S17) -> 1664883 | U17: =ABS(T17/$T$11) -> 0.86894048 | V17: =SUM(V11:V13) -> 1893000.1 | W17: =V17/V11 -> 0.95 | X17: =SUM(X11:X13) -> 1949790.1 | Y17: =X17/X11 -> 0.95 | Z17: =SUM(Z11:Z13) -> 2008283.8 | AA17: =Z17/Z11 -> 0.95 | AB17: =SUM(AB11:AB13) -> 2068532.3 | AC17: =AB17/AB11 -> 0.95 | AE17: Outstanding Loan Balance | AF17: =-B20 -> -14048821 | AG17: =AF17/B10 -> -110620.64 | AH17: Cash On Cash | AL17: =AJ37 -> 0.038300364 | AT17: Source
A18: Income to Expense Ratio | B18: =B16/B15 -> 0.36807308 | G18: Other Income | H18: ='Budget 2026'!B44 -> 16410 | I18: ='Budget 2026'!C44 -> 16593.2 | J18: ='Budget 2026'!D44 -> 16273 | K18: ='Budget 2026'!E44 -> 18286.6 | L18: ='Budget 2026'!F44 -> 18286.6 | M18: ='Budget 2026'!G44 -> 18286.6 | N18: ='Budget 2026'!H44 -> 18286.6 | O18: ='Budget 2026'!I44 -> 18286.6 | ... S18: ='Budget 2026'!M44 -> 18500.2 | T18: =SUM(H18:S18) -> 214206.6 | U18: =ABS(T18/$T$11) -> 0.11179932 | V18: =T18*(1+V6) -> 222774.86 | W18: =V18/V11 -> 0.11179932 | X18: =V18*(1+X6) -> 229458.11 | Y18: =X18/X11 -> 0.11179932 | Z18: =X18*(1+Z6) -> 236341.85 | AA18: =Z18/Z11 -> 0.11179932 | AB18: =Z18*(1+AB6) -> 243432.11 | AC18: =AB18/AB11 -> 0.11179932 | AE18: Return of Member Capital | AF18: =-AF10 -> -3568460.5 | AH18: ARR | AL18: =(AL13/AL7)/7 -> 0.23163623 | AT18: T-12
A19: Appraised Value | B19: =B17/B14 -> 18731761 | G19: Effective Gross Income | H19: =SUM(H17:H18) -> 140046.2 | I19: =SUM(I17:I18) -> 141409.84 | J19: =SUM(J17:J18) -> 136373.04 | K19: =SUM(K17:K18) -> 160760.61 | L19: =SUM(L17:L18) -> 160056.37 | M19: =SUM(M17:M18) -> 160241.08 | N19: =SUM(N17:N18) -> 161389.77 | O19: =SUM(O17:O18) -> 161647.91 | ... S19: =SUM(S17:S18) -> 165669.97 | T19: =SUM(H19:S19) -> 1879089.6 | V19: =SUM(V17:V18) -> 2115775 | X19: =SUM(X17:X18) -> 2179248.2 | Z19: =SUM(Z17:Z18) -> 2244625.7 | AB19: =SUM(AB17:AB18) -> 2311964.4 | AE19: Members Preferred Return Deficiency | AF19: =-X51 -> 0 | AH19: IRR | AL19: =AL38 -> 0.11192712 | AS19: EXPENSES | AT19: T-12 Expenses
A20: Refi proceeds | B20: =MIN( B19*B12, PV(B13/12,30*12,-(B17/B11)/12) ) -> 14048821 | D20: HUD Refi Proceeds | E20: =MIN( PV($E$3/12,$E$11,-($B$17/$E$5)/12), $B$19*$E$6 ) -> 14696324 | AE20: Residual Cash After LP Capital + Pref | AF20: =SUM(AF12:AF19) -> 3488658.1 | AS20: Advertising | AT20: 31392.72
A21: Closing Charges | G21: EXPENSES | AE21: Exit Fee @ 2%of Sales price | AF21: =-AF12*2% -> -435957.07 | AS21: Contract Services | AT21: 66947.02
A22: Existing loan payoff | B22: -10899999 | D22: =A22 -> Existing loan payoff | E22: =$B$22 -> -10899999 | G22: PM Fees | H22: ='Budget 2026'!B51 -> 4500 | I22: ='Budget 2026'!C51 -> 4500 | J22: ='Budget 2026'!D51 -> 4500 | K22: ='Budget 2026'!E51 -> 4822.8182 | L22: ='Budget 2026'!F51 -> 4801.6912 | M22: ='Budget 2026'!G51 -> 4807.2323 | N22: ='Budget 2026'!H51 -> 4841.693 | O22: ='Budget 2026'!I51 -> 4849.4373 | ... T22: ='Budget 2026'!N51 -> 57337.816 | U22: =T22/$T$19 -> 0.030513614 | V22: =V19*3% -> 63473.249 | W22: =V22/V$17 -> 0.033530505 | X22: =V22*(1+$X$7) -> 64742.714 | Y22: =X22/X$17 -> 0.033204966 | Z22: =X22*(1+$X$7) -> 66037.568 | AA22: =Z22/Z$17 -> 0.032882588 | AB22: =Z22*(1+$X$7) -> 67358.319 | AC22: =AB22/AB$17 -> 0.032563339 | AE22: Net Proceeds to be distributed | AF22: =SUM(AF20:AF21) -> 3052701 | AS22: Repair and Maintenance | AT22: 66031.47
A23: Closing costs @ 1.5% | B23: =-B20*1.5% -> -210732.31 | D23: Hud Financing Costs | E23: =-$E$20*$E$9 -> -587852.96 | G23: Advertising | H23: ='Budget 2026'!B96 -> 3562 | I23: ='Budget 2026'!C77 -> 3093.77 | J23: ='Budget 2026'!D77 -> 2297.05 | K23: ='Budget 2026'!E77 -> 7597.05 | L23: ='Budget 2026'!F77 -> 2997.4 | M23: ='Budget 2026'!G77 -> 2297.05 | N23: ='Budget 2026'!H77 -> 2297.05 | O23: ='Budget 2026'!I77 -> 4497.05 | P23: ='Budget 2026'!J77 -> 2597.05 | ... T23: ='Budget 2026'!N77 -> 37771.77 | U23: =T23/$T$19 -> 0.020101101 | V23: =T23*(1+V$7) -> 38527.205 | W23: =V23/V$17 -> 0.020352458 | X23: =V23*(1+$X$7) -> 39297.75 | Y23: =X23/X$17 -> 0.020154862 | Z23: =X23*(1+$X$7) -> 40083.704 | AA23: =Z23/Z$17 -> 0.019959183 | AB23: =Z23*(1+$X$7) -> 40885.379 | AC23: =AB23/AB$17 -> 0.019765405 | AE23: Net Proceeds paid to Members (70%) | AF23: =SUM(AF20:AF21)*70% -> 2136890.7 | AS23: Turn Over | AT23: 40300.19
A24: Initial Replacement Reserves | B24: =-(B10*300)/2 -> -19050 | D24: initial replacement reserves deposit | E24: =-( $B$10 * $E$7 * $E$8 / 12 ) -> -44450 | G24: Contract Services | H24: ='Budget 2026'!B122 -> 5573.66 | I24: ='Budget 2026'!C122 -> 4898.04 | J24: ='Budget 2026'!D122 -> 4898.04 | K24: ='Budget 2026'!E122 -> 5573.66 | L24: ='Budget 2026'!F122 -> 4898.04 | M24: ='Budget 2026'!G122 -> 4898.04 | N24: ='Budget 2026'!H122 -> 5573.66 | O24: ='Budget 2026'!I122 -> 4898.04 | ... S24: ='Budget 2026'!M122 -> 4898.04 | T24: =SUM(H24:S24) -> 63554.09 | U24: =T24/$T$19 -> 0.033821745 | V24: =T24*(1+V$7) -> 64825.172 | W24: =V24/V$17 -> 0.034244674 | X24: =V24*(1+$X$7) -> 66121.675 | Y24: =X24/X$17 -> 0.033912202 | Z24: =X24*(1+$X$7) -> 67444.109 | AA24: =Z24/Z$17 -> 0.033582957 | AB24: =Z24*(1+$X$7) -> 68792.991 | AC24: =AB24/AB$17 -> 0.033256909 | AE24: Net Proceeds paid to Manager (30%) | AF24: =SUM(AF20:AF21)*30% -> 915810.31 | AS24: Utilities
G25: Repair and Maintenance | H25: ='Budget 2026'!B110 -> 3327 | I25: ='Budget 2026'!C110 -> 3327 | J25: ='Budget 2026'!D110 -> 3327 | K25: ='Budget 2026'!E110 -> 3327 | L25: ='Budget 2026'!F110 -> 3327 | M25: ='Budget 2026'!G110 -> 3327 | N25: ='Budget 2026'!H110 -> 3327 | O25: ='Budget 2026'!I110 -> 3327 | ... S25: ='Budget 2026'!M110 -> 3327 | T25: =SUM(H25:S25) -> 39924 | U25: =T25/$T$19 -> 0.021246459 | V25: =T25*(1+V$7) -> 40722.48 | W25: =V25/V$17 -> 0.021512138 | X25: =V25*(1+$X$7) -> 41536.93 | Y25: =X25/X$17 -> 0.021303283 | Z25: =X25*(1+$X$7) -> 42367.668 | AA25: =Z25/Z$17 -> 0.021096455 | AB25: =Z25*(1+$X$7) -> 43215.022 | AC25: =AB25/AB$17 -> 0.020891635 | AS25: Gas & Electric | AT25: 34323.46
G26: Turn Over | H26: ='Budget 2026'!B86 -> 2210 | I26: ='Budget 2026'!C86 -> 2210 | J26: ='Budget 2026'!D86 -> 1610 | K26: ='Budget 2026'!E86 -> 3110 | L26: ='Budget 2026'!F86 -> 1910 | M26: ='Budget 2026'!G86 -> 1910 | N26: ='Budget 2026'!H86 -> 2510 | O26: ='Budget 2026'!I86 -> 5210 | ... S26: ='Budget 2026'!M86 -> 3110 | T26: =SUM(H26:S26) -> 31870 | U26: =T26/$T$19 -> 0.016960341 | V26: =T26*(1+V$7) -> 32507.4 | W26: =V26/V$17 -> 0.017172424 | X26: =V26*(1+$X$7) -> 33157.548 | Y26: =X26/X$17 -> 0.017005701 | Z26: =X26*(1+$X$7) -> 33820.699 | AA26: =Z26/Z$17 -> 0.016840597 | AB26: =Z26*(1+$X$7) -> 34497.113 | AC26: =AB26/AB$17 -> 0.016677096 | AS26: Trash Removal
G27: Utilities | H27: ='Budget 2026'!B131 -> 5028.88 | I27: ='Budget 2026'!C131 -> 5028.88 | J27: ='Budget 2026'!D131 -> 5028.88 | K27: ='Budget 2026'!E131 -> 5028.88 | L27: ='Budget 2026'!F131 -> 5028.88 | M27: ='Budget 2026'!G131 -> 5028.88 | N27: ='Budget 2026'!H131 -> 5028.88 | O27: ='Budget 2026'!I131 -> 5028.88 | ... S27: ='Budget 2026'!M131 -> 5028.88 | T27: =SUM(H27:S27) -> 60346.56 | U27: =T27/$T$19 -> 0.032114786 | V27: =T27*(1+V$7) -> 61553.491 | W27: =V27/V$17 -> 0.03251637 | X27: =V27*(1+$X$7) -> 62784.561 | Y27: =X27/X$17 -> 0.032200677 | Z27: =X27*(1+$X$7) -> 64040.252 | AA27: =Z27/Z$17 -> 0.031888049 | AB27: =Z27*(1+$X$7) -> 65321.057 | AC27: =AB27/AB$17 -> 0.031578456 | AS27: Water and Sewer | AT27: 41380.97
A28: Total Charges | B28: =SUM(B22:B26) -> -11129781 | D28: Total Charges | E28: =SUM($E$22:$E$24) -> -11532302 | G28: General/Admin | H28: ='Budget 2026'!B77 -> 2781.05 | I28: ='Budget 2026'!C77 -> 3093.77 | J28: ='Budget 2026'!D77 -> 2297.05 | K28: ='Budget 2026'!E77 -> 7597.05 | L28: ='Budget 2026'!F77 -> 2997.4 | M28: ='Budget 2026'!G77 -> 2297.05 | N28: ='Budget 2026'!H77 -> 2297.05 | O28: ='Budget 2026'!I77 -> 4497.05 | ... S28: ='Budget 2026'!M77 -> 2297.05 | T28: =SUM(H28:S28) -> 37771.77 | U28: =T28/$T$19 -> 0.020101101 | V28: =T28*(1+V$7) -> 38527.205 | W28: =V28/V$17 -> 0.020352458 | X28: =V28*(1+$X$7) -> 39297.75 | Y28: =X28/X$17 -> 0.020154862 | Z28: =X28*(1+$X$7) -> 40083.704 | AA28: =Z28/Z$17 -> 0.019959183 | AB28: =Z28*(1+$X$7) -> 40885.379 | AC28: =AB28/AB$17 -> 0.019765405 | AS28: General/Admin | AT28: 52530.16
A29: B. Cash out (in) | B29: =SUM(B20:B26) -> 2919039.5 | D29: Cash Out | E29: =$E$20+$E$28 -> 3164022 | G29: Insurance | H29: ='Budget 2026'!B133 -> 8500 | I29: ='Budget 2026'!C133 -> 8500 | J29: ='Budget 2026'!D133 -> 8500 | K29: ='Budget 2026'!E133 -> 8500 | L29: ='Budget 2026'!F133 -> 8500 | M29: ='Budget 2026'!G133 -> 8500 | N29: ='Budget 2026'!H133 -> 8500 | O29: ='Budget 2026'!I133 -> 8500 | ... S29: ='Budget 2026'!M133 -> 8500 | T29: =SUM(H29:S29) -> 102000 | U29: =T29/$T$19 -> 0.054281605 | V29: =T29*(1+V$7) -> 104040 | W29: =V29/V$17 -> 0.054960378 | X29: =V29*(1+$X$7) -> 106120.8 | Y29: =X29/X$17 -> 0.054426782 | Z29: =X29*(1+$X$7) -> 108243.22 | AA29: =Z29/Z$17 -> 0.053898366 | AB29: =Z29*(1+$X$7) -> 110408.08 | AC29: =AB29/AB$17 -> 0.053375081 | AE29: Year | AF29: Contributions | AG29: Return of Capital | AH29: Pref. Returns | AI29: Cash Flow | AJ29: Cash On Cash | AK29: Sale Proceeds | AL29: Total | AS29: Insurance | AT29: 206902.04
A30: New Debt Service | G30: RE Taxes | H30: ='Budget 2026'!B134 -> 12640 | I30: ='Budget 2026'!C134 -> 12640 | J30: ='Budget 2026'!D134 -> 12640 | K30: ='Budget 2026'!E134 -> 12640 | L30: ='Budget 2026'!F134 -> 12640 | M30: ='Budget 2026'!G134 -> 12640 | N30: ='Budget 2026'!H134 -> 12640 | O30: ='Budget 2026'!I134 -> 12640 | ... S30: ='Budget 2026'!M134 -> 12640 | T30: =SUM(H30:S30) -> 151680 | U30: =T30/$T$19 -> 0.08071994 | V30: =T30*(1+V$7) -> 154713.6 | W30: =V30/V$17 -> 0.081729314 | X30: =V30*(1+$X$7) -> 157807.87 | Y30: =X30/X$17 -> 0.080935826 | Z30: =X30*(1+$X$7) -> 160964.03 | AA30: =Z30/Z$17 -> 0.080150041 | AB30: =Z30*(1+$X$7) -> 164183.31 | AC30: =AB30/AB$17 -> 0.079371885 | AE30: 45292 | AF30: -6047500 | AG30: 0 | AH30: 0 | AI30: 0 | AJ30: 0 | AL30: =AF30 -> -6047500 | AS30: RE Taxes | AT30: 164042.76
A31: Amortized Per Annum | B31: =PMT(B13/12,30*12,B20)*12 -> -933026.77 | D31: Amortized Per Annum | E31: =PMT($E$3/12,$E$11,$E$20)*12 -> -1035343.9 | G31: Payroll | H31: ='Budget 2026'!B151 -> 12241.7 | I31: ='Budget 2026'!C151 -> 12241.7 | J31: ='Budget 2026'!D151 -> 12991.7 | K31: ='Budget 2026'!E151 -> 12241.7 | L31: ='Budget 2026'!F151 -> 12241.7 | M31: ='Budget 2026'!G151 -> 12991.7 | N31: ='Budget 2026'!H151 -> 12241.7 | O31: ='Budget 2026'!I151 -> 12241.7 | ... S31: ='Budget 2026'!M151 -> 15491.7 | T31: =SUM(H31:S31) -> 152400.4 | U31: =T31/$T$19 -> 0.081103317 | V31: =T31*(1+V$7) -> 155448.41 | W31: =V31/V$17 -> 0.082117486 | X31: =V31*(1+$X$7) -> 158557.38 | Y31: =X31/X$17 -> 0.081320228 | Z31: =X31*(1+$X$7) -> 161728.52 | AA31: =Z31/Z$17 -> 0.080530712 | AB31: =Z31*(1+$X$7) -> 164963.09 | AC31: =AB31/AB$17 -> 0.07974886 | AE31: 45658 | AG31: 0 | AH31: 0 | AI31: 0 | AJ31: 0 | AL31: 0 | AS31: Legal | AT31: 3951.5
A32: Monthly Debt Service | B32: =B31/12 -> -77752.231 | D32: =A32 -> Monthly Debt Service | E32: =PMT($E$3/12,$E$11,$E$20) -> -86278.661 | G32: Total Expenses | H32: =SUM(H22:H31) -> 60364.29 | I32: =SUM(I22:I31) -> 59533.16 | J32: =SUM(J22:J31) -> 58089.72 | K32: =SUM(K22:K31) -> 70438.158 | L32: =SUM(L22:L31) -> 59342.111 | M32: =SUM(M22:M31) -> 58696.952 | N32: =SUM(N22:N31) -> 59257.033 | O32: =SUM(O22:O31) -> 65689.157 | ... T32: =SUM(T22:T31) -> 734656.41 | U32: =T32/$T$19 -> 0.39096401 | V32: =SUM(V23:V31) -> 690864.96 | W32: =V32/V19 -> 0.32653046 | X32: =SUM(X23:X31) -> 704682.26 | Y32: =X32/X$17 -> 0.36141442 | Z32: =SUM(Z23:Z31) -> 718775.91 | AA32: =Z32/Z$17 -> 0.35790554 | AB32: =SUM(AB23:AB31) -> 733151.42 | AC32: =AB32/AB$17 -> 0.35443073 | AE32: 46023 | AG32: =B58 -> 2479039.5 | AH32: 0 | AI32: =T57 -> 136219.65 | AJ32: =AI32/$AG$37 -> 0.022524953 | AL32: =SUM(AG32:AI32) -> 2615259.2 | AS32: Payroll | AT32: 96128.71
A33: Effective LTV | B33: =B20/B19 -> 0.75 | D33: =A33 -> Effective LTV | E33: =$E$20/$B$19 -> 0.78456713 | AE33: 46388 | AG33: 0 | AH33: =V52 -> 0 | AI33: =V57 -> 319355.15 | AJ33: =AI33/$AG$37 -> 0.052807797 | AL33: =SUM(AG33:AI33) -> 319355.15 | AS33: PM Fees | AT33: 126907.18
A34: Debt Yield | B34: =B17/B20 -> 0.086666667 | D34: =A34 -> Debt Yield | E34: =$B$17/$E$20 -> 0.082848233 | G34: Net Operating Income | H34: =H19-H32 -> 79681.91 | I34: =I19-I32 -> 81876.68 | J34: =J19-J32 -> 78283.324 | K34: =K19-K32 -> 90322.448 | L34: =L19-L32 -> 100714.26 | M34: =M19-M32 -> 101544.12 | N34: =N19-N32 -> 102132.73 | O34: =O19-O32 -> 95958.752 | ... T34: =T19-T32 -> 1144433.2 | U34: =T34/T19 -> 0.60903599 | V34: =V19-V32 -> 1424910 | W34: =V34/V19 -> 0.67346954 | X34: =X19-X32 -> 1474565.9 | Y34: =X34/X19 -> 0.67663974 | Z34: =Z19-Z32 -> 1525849.7 | AA34: =Z34/Z19 -> 0.67977916 | AB34: =AB19-AB32 -> 1578813 | AC34: =AB34/AB19 -> 0.6828881 | AE34: 46753 | AG34: 0 | AH34: =X52 -> 0 | AI34: =X57 -> 353225.69 | AJ34: =AI34/$AG$37 -> 0.058408547 | AL34: =SUM(AG34:AI34) -> 353225.69 | AS34: Deposit to Replacement Reserves | AT34: 0
A35: DSCR | B35: =B17/ABS(B31) -> 1.304962 | C35: =IF(B35>=B11,"OK","DSCR FAIL") -> OK | D35: =A35 -> DSCR | E35: =$B$17/ABS($E$31) -> 1.176 | AE35: 47119 | AG35: 0 | AH35: 0 | AI35: =Z57 -> 388209.07 | AJ35: =AI35/$AG$37 -> 0.064193314 | AL35: =AG35+AI35+AK35 -> 388209.07
G36: Debt Service | AE36: 47484 | AG36: =AF10 -> 3568460.5 | AH36: 0 | AI36: =AB57 -> 424340.6 | AJ36: =AI36/$AG$37 -> 0.070167937 | AK36: =AF23 -> 2136890.7 | AL36: =AG36+AI36+AK36 -> 6129691.8
A37: Interest Only Period | G37: Senior Loan Principal | AG37: =SUM(AG30:AG36) -> 6047500 | AH37: =SUM(AH30:AH35) -> 0 | AI37: =SUM(AI30:AI36) -> 1621350.2 | AJ37: =AVERAGE(AJ30:AJ36) -> 0.038300364 | AL37: =AG37+AH37+AK37 -> 6047500
A38: Interest Only | B38: =-B20*B13 -> -740372.86 | G38: Senior Loan Interest | H38: 78585 | I38: 78585 | J38: 78585 | K38: 78585 | L38: 78585 | M38: 78585 | N38: 78585 | O38: 78585 | P38: =-$B$39 -> 61697.738 | Q38: =-$B$39 -> 61697.738 | R38: =-$B$39 -> 61697.738 | S38: =-$B$39 -> 61697.738 | T38: =SUM(H38:S38) -> 875470.95 | V38: =-B39*12 -> 740372.86 | X38: =V38 -> 740372.86 | Z38: =X38 -> 740372.86 | AB38: =Z38 -> 740372.86 | AK38: IRR | AL38: =XIRR(AL30:AL36, AE30:AE36) -> 0.11192712 | AS38: Advertising | AT38: 3631 | AU38: 3812 | AV38: 2936.62
A39: Monthly I/O | B39: =B38/12 -> -61697.738 | G39: Short term Mezz Debt Interest | H39: =B67 -> 0 | I39: =D67 -> 0 | J39: =G67 -> 0 | K39: =H67 -> 0 | L39: =I67 -> 0 | M39: =J67 -> 0 | N39: =K67 -> 0 | O39: =L67 -> 0 | P39: =M67 -> 0 | Q39: =N67 -> 0 | ... S39: =P67 -> 0 | T39: =SUM(H39:S39) -> 0 | V39: =-B67 -> 0 | X39: =-B67 -> 0 | Z39: =-G61 -> 0 | AB39: =-I61 -> 0 | AS39: Contract Services | AT39: 0 | AU39: 0 | AV39: 0
AS40: Repair and Maintenance | AT40: 10385.34 | AU40: 9136.84 | AV40: 12365.79
G41: Total Debt Service | H41: =SUM(H37:H40) -> 78585 | I41: =SUM(I37:I40) -> 78585 | J41: =SUM(J37:J40) -> 78585 | K41: =SUM(K37:K40) -> 78585 | L41: =SUM(L37:L40) -> 78585 | M41: =SUM(M37:M40) -> 78585 | N41: =SUM(N37:N40) -> 78585 | O41: =SUM(O37:O40) -> 78585 | ... T41: =SUM(T37:T40) -> 875470.95 | V41: =SUM(V37:V40) -> 740372.86 | X41: =SUM(X37:X40) -> 740372.86 | Z41: =SUM(Z37:Z40) -> 740372.86 | AB41: =SUM(AB37:AB40) -> 740372.86 | AS41: Turn Over | AT41: 0 | AU41: 0 | AV41: 0
...

Sheet Proforma FOR BUDGET 2026
A2: Debt Sizing Tool | Y2: SALE
E3: Year 3 | S3: 2027 | U3: 2028 | W3: 2029 | Y3: 2030
E4: ='Budget 2026'!B1 -> 46023 | F4: ='Budget 2026'!C1 -> 46054 | G4: ='Budget 2026'!D1 -> 46082 | H4: ='Budget 2026'!E1 -> 46113 | I4: ='Budget 2026'!F1 -> 46143 | J4: ='Budget 2026'!G1 -> 46174 | K4: ='Budget 2026'!H1 -> 46204 | L4: ='Budget 2026'!I1 -> 46235 | ... P4: ='Budget 2026'!M1 -> 46357 | Q4: Total | S4: Year 4 | U4: Year 5 | W4: Year 6 | Y4: Year 7 | AB4: EXIT at Year 7
A5: T-5 Treasury | B5: 0.0372 | D5: Financial Assumptions | L5: REFINANCE | AO5: Source | AP5: Source | AQ5: Source | AR5: Source | AS5: Source | AT5: Source | AU5: Source | AV5: Source | AW5: Source
A6: Spread | B6: 0.0155 | D6: Annual Rent Escalator | S6: 0.04 | U6: 0.03 | W6: 0.03 | Y6: 0.03 | AB6: Sale | AO6: T-12 | AP6: T-12 | AQ6: T-12 | AR6: T-12
B7: =SUM(B5:B6) -> 0.0527 | D7: Annual Expense Escalator | S7: 0.02 | U7: 0.02 | W7: 0.02 | Y7: 0.02 | AB7: Net Operating Income | AC7: =W34 -> 1525849.7 | AE7: Capital Invested | AI7: =AD37 -> 6047500 | AO7: Sept-25 | AP7: 46320 | AQ7: 46351 | AR7: DEC | AS7: JAN | AT7: FEB | AU7: MAR | AV7: APR | AW7: MAY
AB8: Exit Cap Rate | AC8: 0.07 | AE8: Limited Partner Returns
A9: Refinance - Agency | D9: INCOME | Q9: In-Place Rent | S9: In-Place Rent | U9: In-Place Rent | W9: In-Place Rent | Y9: In-Place Rent | AB9: Insurance/Tax/Lender Escrows | AC9: 0 | AE9: Return of Capital | AI9: =AD37 -> 6047500
A10: Units | B10: 127 | D10: Average In-Place Rent | Q10: =(Q17/$B$10)/12 -> 1092.4429 | S10: =(S17/$B$10)/12 -> 1242.126 | U10: =(U17/$B$10)/12 -> 1279.3898 | W10: =(W17/$B$10)/12 -> 1317.7715 | Y10: =(Y17/$B$10)/12 -> 1357.3047 | AB10: Total Equity Outstanding | AC10: =-AC30-AD32 -> 5230711 | AE10: Preferred returns | AI10: =AE37 -> 0
A11: Min DSCR | B11: 1.25 | D11: Gross Potential Rent (GPR) | E11: ='Budget 2026'!B2 -> 159666 | F11: ='Budget 2026'!C2 -> 159666 | G11: ='Budget 2026'!D2 -> 159666 | H11: ='Budget 2026'!E2 -> 159666 | I11: ='Budget 2026'!F2 -> 159666 | J11: ='Budget 2026'!G2 -> 159666 | K11: ='Budget 2026'!H2 -> 159666 | L11: ='Budget 2026'!I2 -> 159666 | ... P11: ='Budget 2026'!M2 -> 159666 | Q11: =SUM(E11:P11) -> 1915992 | S11: =Q11*(1+S6) -> 1992631.7 | U11: =S11*(1+U6) -> 2052410.6 | W11: =U11*(1+W6) -> 2113982.9 | Y11: =W11*(1+Y6) -> 2177402.4 | AE11: From Cash Flow | AI11: =AF37 -> 1806307.1
A12: Max LTV | B12: 0.75 | D12: - Vacancy | E12: ='Budget 2026'!B7 -> -14165.28 | F12: ='Budget 2026'!C7 -> -9443.52 | G12: ='Budget 2026'!D7 -> -4733.5644 | H12: ='Budget 2026'!E7 -> -4739.718 | I12: ='Budget 2026'!F7 -> -4745.8797 | J12: ='Budget 2026'!G7 -> -4752.0493 | K12: ='Budget 2026'!H7 -> -4760.603 | L12: ='Budget 2026'!I7 -> -4769.1721 | ... P12: ='Budget 2026'!M7 -> -3589.7713 | Q12: =SUM(E12:P12) -> -66455.961 | R12: =ABS(Q12/$Q$11) -> 0.034684885 | S12: =-S11*T12 -> -19926.317 | T12: 0.01 | U12: =-U11*V12 -> -41048.213 | V12: 0.02 | W12: =-W11*X12 -> -42279.659 | X12: 0.02 | Y12: =-Y11*Z12 -> -43548.049 | Z12: 0.02 | AB12: Sales Price | AC12: =AC7/AC8 -> 21797854 | AD12: =AC12/B10 -> 171636.64 | AE12: From Sales Proceeds | AI12: =AH36 -> 2151056.8 | AO12: Source | AP12: Source | AQ12: Source | AR12: Source | AS12: Source | AT12: Source | AU12: Source | AV12: Source | AW12: Source
A13: Interest rate | B13: =B7 -> 0.0527 | D13: - Concessions, Loss to Lease, Bad Debt | Q13: =SUM(E13:P13) -> 0 | S13: =-S11*T13 -> -79705.267 | T13: 0.04 | U13: =-U11*V13 -> -61572.319 | V13: 0.03 | W13: =-W11*X13 -> -63419.488 | X13: 0.03 | Y13: =-Y11*Z13 -> -65322.073 | Z13: 0.03 | AB13: Operating Reserves Remaining | AC13: =SUM(Q45:Y45) -> 180000 | AD13: =AC13/B10 -> 1417.3228 | AE13: Total Distributions | AI13: =SUM(AI9:AI12) -> 10004864 | AO13: T-12 | AP13: T-12 | AQ13: T-12 | AR13: T-12
